ERROR 2023-08-02 17:29:25,075 log Internal Server Error: /department/projectdetails/
Traceback (most recent call last):
  File "D:\python files\Project tasks\customizeUserModel\venv\lib\site-packages\django\core\handlers\exception.py", line 55, in inner
    response = get_response(request)
  File "D:\python files\Project tasks\customizeUserModel\venv\lib\site-packages\django\core\handlers\base.py", line 197, in _get_response
    response = wrapped_callback(request, *callback_args, **callback_kwargs)
  File "D:\python files\Project tasks\customizeUserModel\venv\lib\site-packages\django\views\decorators\csrf.py", line 56, in wrapper_view
    return view_func(*args, **kwargs)
  File "D:\python files\Project tasks\customizeUserModel\venv\lib\site-packages\django\views\generic\base.py", line 104, in view
    return self.dispatch(request, *args, **kwargs)
  File "D:\python files\Project tasks\customizeUserModel\venv\lib\site-packages\rest_framework\views.py", line 492, in dispatch
    request = self.initialize_request(request, *args, **kwargs)
  File "D:\python files\Project tasks\customizeUserModel\venv\lib\site-packages\rest_framework\views.py", line 394, in initialize_request
    authenticators=self.get_authenticators(),
  File "D:\python files\Project tasks\customizeUserModel\venv\lib\site-packages\rest_framework\views.py", line 272, in get_authenticators
    return [auth() for auth in self.authentication_classes]
  File "D:\python files\Project tasks\customizeUserModel\venv\lib\site-packages\rest_framework\views.py", line 272, in <listcomp>
    return [auth() for auth in self.authentication_classes]
TypeError: 'list' object is not callable
ERROR 2023-08-02 17:29:25,078 basehttp "POST /department/projectdetails/ HTTP/1.1" 500 94691
ERROR 2023-08-02 19:43:27,168 log Internal Server Error: /department/projectdetails/27/
Traceback (most recent call last):
  File "D:\python files\Project tasks\customizeUserModel\venv\lib\site-packages\django\db\backends\utils.py", line 89, in _execute
    return self.cursor.execute(sql, params)
  File "D:\python files\Project tasks\customizeUserModel\venv\lib\site-packages\django\db\backends\sqlite3\base.py", line 328, in execute
    return super().execute(query, params)
sqlite3.IntegrityError: CHECK constraint failed: team_size

The above exception was the direct cause of the following exception:

Traceback (most recent call last):
  File "D:\python files\Project tasks\customizeUserModel\venv\lib\site-packages\django\core\handlers\exception.py", line 55, in inner
    response = get_response(request)
  File "D:\python files\Project tasks\customizeUserModel\venv\lib\site-packages\django\core\handlers\base.py", line 197, in _get_response
    response = wrapped_callback(request, *callback_args, **callback_kwargs)
  File "D:\python files\Project tasks\customizeUserModel\venv\lib\site-packages\django\views\decorators\csrf.py", line 56, in wrapper_view
    return view_func(*args, **kwargs)
  File "D:\python files\Project tasks\customizeUserModel\venv\lib\site-packages\django\views\generic\base.py", line 104, in view
    return self.dispatch(request, *args, **kwargs)
  File "D:\python files\Project tasks\customizeUserModel\venv\lib\site-packages\rest_framework\views.py", line 509, in dispatch
    response = self.handle_exception(exc)
  File "D:\python files\Project tasks\customizeUserModel\venv\lib\site-packages\rest_framework\views.py", line 469, in handle_exception
    self.raise_uncaught_exception(exc)
  File "D:\python files\Project tasks\customizeUserModel\venv\lib\site-packages\rest_framework\views.py", line 480, in raise_uncaught_exception
    raise exc
  File "D:\python files\Project tasks\customizeUserModel\venv\lib\site-packages\rest_framework\views.py", line 506, in dispatch
    response = handler(request, *args, **kwargs)
  File "D:\python files\Project tasks\customizeUserModel\projectDept\project\views.py", line 48, in put
    serializer.save()
  File "D:\python files\Project tasks\customizeUserModel\venv\lib\site-packages\rest_framework\serializers.py", line 207, in save
    self.instance = self.update(self.instance, validated_data)
  File "D:\python files\Project tasks\customizeUserModel\projectDept\project\Serializers.py", line 26, in update
    return super().update(instance, validated_data)
  File "D:\python files\Project tasks\customizeUserModel\venv\lib\site-packages\rest_framework\serializers.py", line 1006, in update
    instance.save()
  File "D:\python files\Project tasks\customizeUserModel\venv\lib\site-packages\django\db\models\base.py", line 814, in save
    self.save_base(
  File "D:\python files\Project tasks\customizeUserModel\venv\lib\site-packages\django\db\models\base.py", line 877, in save_base
    updated = self._save_table(
  File "D:\python files\Project tasks\customizeUserModel\venv\lib\site-packages\django\db\models\base.py", line 990, in _save_table
    updated = self._do_update(
  File "D:\python files\Project tasks\customizeUserModel\venv\lib\site-packages\django\db\models\base.py", line 1054, in _do_update
    return filtered._update(values) > 0
  File "D:\python files\Project tasks\customizeUserModel\venv\lib\site-packages\django\db\models\query.py", line 1231, in _update
    return query.get_compiler(self.db).execute_sql(CURSOR)
  File "D:\python files\Project tasks\customizeUserModel\venv\lib\site-packages\django\db\models\sql\compiler.py", line 1984, in execute_sql
    cursor = super().execute_sql(result_type)
  File "D:\python files\Project tasks\customizeUserModel\venv\lib\site-packages\django\db\models\sql\compiler.py", line 1562, in execute_sql
    cursor.execute(sql, params)
  File "D:\python files\Project tasks\customizeUserModel\venv\lib\site-packages\django\db\backends\utils.py", line 102, in execute
    return super().execute(sql, params)
  File "D:\python files\Project tasks\customizeUserModel\venv\lib\site-packages\django\db\backends\utils.py", line 67, in execute
    return self._execute_with_wrappers(
  File "D:\python files\Project tasks\customizeUserModel\venv\lib\site-packages\django\db\backends\utils.py", line 80, in _execute_with_wrappers
    return executor(sql, params, many, context)
  File "D:\python files\Project tasks\customizeUserModel\venv\lib\site-packages\django\db\backends\utils.py", line 84, in _execute
    with self.db.wrap_database_errors:
  File "D:\python files\Project tasks\customizeUserModel\venv\lib\site-packages\django\db\utils.py", line 91, in __exit__
    raise dj_exc_value.with_traceback(traceback) from exc_value
  File "D:\python files\Project tasks\customizeUserModel\venv\lib\site-packages\django\db\backends\utils.py", line 89, in _execute
    return self.cursor.execute(sql, params)
  File "D:\python files\Project tasks\customizeUserModel\venv\lib\site-packages\django\db\backends\sqlite3\base.py", line 328, in execute
    return super().execute(query, params)
django.db.utils.IntegrityError: CHECK constraint failed: team_size
ERROR 2023-08-02 19:43:27,201 basehttp "PUT /department/projectdetails/27/ HTTP/1.1" 500 207272
ERROR 2023-08-03 22:24:31,155 log Internal Server Error: /accounts/register/
Traceback (most recent call last):
  File "D:\python files\Project tasks\customizeUserModel\venv\lib\site-packages\django\core\handlers\exception.py", line 55, in inner
    response = get_response(request)
  File "D:\python files\Project tasks\customizeUserModel\venv\lib\site-packages\django\core\handlers\base.py", line 197, in _get_response
    response = wrapped_callback(request, *callback_args, **callback_kwargs)
  File "D:\python files\Project tasks\customizeUserModel\venv\lib\site-packages\django\views\decorators\csrf.py", line 56, in wrapper_view
    return view_func(*args, **kwargs)
  File "D:\python files\Project tasks\customizeUserModel\venv\lib\site-packages\django\views\generic\base.py", line 104, in view
    return self.dispatch(request, *args, **kwargs)
  File "D:\python files\Project tasks\customizeUserModel\venv\lib\site-packages\rest_framework\views.py", line 509, in dispatch
    response = self.handle_exception(exc)
  File "D:\python files\Project tasks\customizeUserModel\venv\lib\site-packages\rest_framework\views.py", line 469, in handle_exception
    self.raise_uncaught_exception(exc)
  File "D:\python files\Project tasks\customizeUserModel\venv\lib\site-packages\rest_framework\views.py", line 480, in raise_uncaught_exception
    raise exc
  File "D:\python files\Project tasks\customizeUserModel\venv\lib\site-packages\rest_framework\views.py", line 506, in dispatch
    response = handler(request, *args, **kwargs)
  File "D:\python files\Project tasks\customizeUserModel\projectDept\accounts\views.py", line 21, in post
    serializer.save()
  File "D:\python files\Project tasks\customizeUserModel\venv\lib\site-packages\rest_framework\serializers.py", line 212, in save
    self.instance = self.create(validated_data)
  File "D:\python files\Project tasks\customizeUserModel\projectDept\accounts\Serializers.py", line 34, in create
    domain = get_current_site(self)
  File "D:\python files\Project tasks\customizeUserModel\venv\lib\site-packages\django\contrib\sites\shortcuts.py", line 18, in get_current_site
    return RequestSite(request)
  File "D:\python files\Project tasks\customizeUserModel\venv\lib\site-packages\django\contrib\sites\requests.py", line 11, in __init__
    self.domain = self.name = request.get_host()
AttributeError: 'registerUser' object has no attribute 'get_host'
ERROR 2023-08-03 22:24:31,218 basehttp "POST /accounts/register/ HTTP/1.1" 500 125553
ERROR 2023-08-03 22:44:58,242 log Internal Server Error: /accounts/register/
Traceback (most recent call last):
  File "D:\python files\Project tasks\customizeUserModel\venv\lib\site-packages\django\core\handlers\exception.py", line 55, in inner
    response = get_response(request)
  File "D:\python files\Project tasks\customizeUserModel\venv\lib\site-packages\django\core\handlers\base.py", line 197, in _get_response
    response = wrapped_callback(request, *callback_args, **callback_kwargs)
  File "D:\python files\Project tasks\customizeUserModel\venv\lib\site-packages\django\views\decorators\csrf.py", line 56, in wrapper_view
    return view_func(*args, **kwargs)
  File "D:\python files\Project tasks\customizeUserModel\venv\lib\site-packages\django\views\generic\base.py", line 104, in view
    return self.dispatch(request, *args, **kwargs)
  File "D:\python files\Project tasks\customizeUserModel\venv\lib\site-packages\rest_framework\views.py", line 509, in dispatch
    response = self.handle_exception(exc)
  File "D:\python files\Project tasks\customizeUserModel\venv\lib\site-packages\rest_framework\views.py", line 469, in handle_exception
    self.raise_uncaught_exception(exc)
  File "D:\python files\Project tasks\customizeUserModel\venv\lib\site-packages\rest_framework\views.py", line 480, in raise_uncaught_exception
    raise exc
  File "D:\python files\Project tasks\customizeUserModel\venv\lib\site-packages\rest_framework\views.py", line 506, in dispatch
    response = handler(request, *args, **kwargs)
  File "D:\python files\Project tasks\customizeUserModel\projectDept\accounts\views.py", line 29, in post
    serializer.save()
  File "D:\python files\Project tasks\customizeUserModel\venv\lib\site-packages\rest_framework\serializers.py", line 212, in save
    self.instance = self.create(validated_data)
  File "D:\python files\Project tasks\customizeUserModel\projectDept\accounts\Serializers.py", line 35, in create
    domain = get_current_site(request)
  File "D:\python files\Project tasks\customizeUserModel\venv\lib\site-packages\django\contrib\sites\shortcuts.py", line 18, in get_current_site
    return RequestSite(request)
  File "D:\python files\Project tasks\customizeUserModel\venv\lib\site-packages\django\contrib\sites\requests.py", line 11, in __init__
    self.domain = self.name = request.get_host()
AttributeError: 'NoneType' object has no attribute 'get_host'
ERROR 2023-08-03 22:44:58,249 basehttp "POST /accounts/register/ HTTP/1.1" 500 121948
ERROR 2023-08-03 22:54:40,459 log Internal Server Error: /accounts/register/
Traceback (most recent call last):
  File "D:\python files\Project tasks\customizeUserModel\venv\lib\site-packages\django\core\handlers\exception.py", line 55, in inner
    response = get_response(request)
  File "D:\python files\Project tasks\customizeUserModel\venv\lib\site-packages\django\core\handlers\base.py", line 197, in _get_response
    response = wrapped_callback(request, *callback_args, **callback_kwargs)
  File "D:\python files\Project tasks\customizeUserModel\venv\lib\site-packages\django\views\decorators\csrf.py", line 56, in wrapper_view
    return view_func(*args, **kwargs)
  File "D:\python files\Project tasks\customizeUserModel\venv\lib\site-packages\django\views\generic\base.py", line 104, in view
    return self.dispatch(request, *args, **kwargs)
  File "D:\python files\Project tasks\customizeUserModel\venv\lib\site-packages\rest_framework\views.py", line 509, in dispatch
    response = self.handle_exception(exc)
  File "D:\python files\Project tasks\customizeUserModel\venv\lib\site-packages\rest_framework\views.py", line 469, in handle_exception
    self.raise_uncaught_exception(exc)
  File "D:\python files\Project tasks\customizeUserModel\venv\lib\site-packages\rest_framework\views.py", line 480, in raise_uncaught_exception
    raise exc
  File "D:\python files\Project tasks\customizeUserModel\venv\lib\site-packages\rest_framework\views.py", line 506, in dispatch
    response = handler(request, *args, **kwargs)
  File "D:\python files\Project tasks\customizeUserModel\projectDept\accounts\views.py", line 29, in post
    serializer.save()
  File "D:\python files\Project tasks\customizeUserModel\venv\lib\site-packages\rest_framework\serializers.py", line 212, in save
    self.instance = self.create(validated_data)
  File "D:\python files\Project tasks\customizeUserModel\projectDept\accounts\Serializers.py", line 36, in create
    current_site = validated_data.pop('current_site')
KeyError: 'current_site'
ERROR 2023-08-03 22:54:40,465 basehttp "POST /accounts/register/ HTTP/1.1" 500 115137
ERROR 2023-08-04 11:46:10,642 log Internal Server Error: /accounts/register/
Traceback (most recent call last):
  File "D:\python files\Project tasks\customizeUserModel\venv\lib\site-packages\django\core\handlers\exception.py", line 55, in inner
    response = get_response(request)
  File "D:\python files\Project tasks\customizeUserModel\venv\lib\site-packages\django\core\handlers\base.py", line 197, in _get_response
    response = wrapped_callback(request, *callback_args, **callback_kwargs)
  File "D:\python files\Project tasks\customizeUserModel\venv\lib\site-packages\django\views\decorators\csrf.py", line 56, in wrapper_view
    return view_func(*args, **kwargs)
  File "D:\python files\Project tasks\customizeUserModel\venv\lib\site-packages\django\views\generic\base.py", line 104, in view
    return self.dispatch(request, *args, **kwargs)
  File "D:\python files\Project tasks\customizeUserModel\venv\lib\site-packages\rest_framework\views.py", line 509, in dispatch
    response = self.handle_exception(exc)
  File "D:\python files\Project tasks\customizeUserModel\venv\lib\site-packages\rest_framework\views.py", line 469, in handle_exception
    self.raise_uncaught_exception(exc)
  File "D:\python files\Project tasks\customizeUserModel\venv\lib\site-packages\rest_framework\views.py", line 480, in raise_uncaught_exception
    raise exc
  File "D:\python files\Project tasks\customizeUserModel\venv\lib\site-packages\rest_framework\views.py", line 506, in dispatch
    response = handler(request, *args, **kwargs)
  File "D:\python files\Project tasks\customizeUserModel\projectDept\accounts\views.py", line 29, in post
    serializer.save()
  File "D:\python files\Project tasks\customizeUserModel\venv\lib\site-packages\rest_framework\serializers.py", line 212, in save
    self.instance = self.create(validated_data)
  File "D:\python files\Project tasks\customizeUserModel\projectDept\accounts\Serializers.py", line 47, in create
    send_mail(Subject,message,from_email,to_email)
  File "D:\python files\Project tasks\customizeUserModel\venv\lib\site-packages\django\core\mail\__init__.py", line 87, in send_mail
    return mail.send()
  File "D:\python files\Project tasks\customizeUserModel\venv\lib\site-packages\django\core\mail\message.py", line 298, in send
    return self.get_connection(fail_silently).send_messages([self])
  File "D:\python files\Project tasks\customizeUserModel\venv\lib\site-packages\django\core\mail\backends\smtp.py", line 127, in send_messages
    new_conn_created = self.open()
  File "D:\python files\Project tasks\customizeUserModel\venv\lib\site-packages\django\core\mail\backends\smtp.py", line 92, in open
    self.connection.starttls(context=self.ssl_context)
  File "C:\Users\Admin\AppData\Local\Programs\Python\Python310\lib\smtplib.py", line 790, in starttls
    self.sock = context.wrap_socket(self.sock,
  File "C:\Users\Admin\AppData\Local\Programs\Python\Python310\lib\ssl.py", line 512, in wrap_socket
    return self.sslsocket_class._create(
  File "C:\Users\Admin\AppData\Local\Programs\Python\Python310\lib\ssl.py", line 1070, in _create
    self.do_handshake()
  File "C:\Users\Admin\AppData\Local\Programs\Python\Python310\lib\ssl.py", line 1341, in do_handshake
    self._sslobj.do_handshake()
TimeoutError: [WinError 10060] A connection attempt failed because the connected party did not properly respond after a period of time, or established connection failed because connected host has failed to respond
ERROR 2023-08-04 11:46:10,672 basehttp "POST /accounts/register/ HTTP/1.1" 500 154603
ERROR 2023-08-04 11:50:01,407 log Internal Server Error: /accounts/register/
Traceback (most recent call last):
  File "D:\python files\Project tasks\customizeUserModel\venv\lib\site-packages\django\core\handlers\exception.py", line 55, in inner
    response = get_response(request)
  File "D:\python files\Project tasks\customizeUserModel\venv\lib\site-packages\django\core\handlers\base.py", line 197, in _get_response
    response = wrapped_callback(request, *callback_args, **callback_kwargs)
  File "D:\python files\Project tasks\customizeUserModel\venv\lib\site-packages\django\views\decorators\csrf.py", line 56, in wrapper_view
    return view_func(*args, **kwargs)
  File "D:\python files\Project tasks\customizeUserModel\venv\lib\site-packages\django\views\generic\base.py", line 104, in view
    return self.dispatch(request, *args, **kwargs)
  File "D:\python files\Project tasks\customizeUserModel\venv\lib\site-packages\rest_framework\views.py", line 509, in dispatch
    response = self.handle_exception(exc)
  File "D:\python files\Project tasks\customizeUserModel\venv\lib\site-packages\rest_framework\views.py", line 469, in handle_exception
    self.raise_uncaught_exception(exc)
  File "D:\python files\Project tasks\customizeUserModel\venv\lib\site-packages\rest_framework\views.py", line 480, in raise_uncaught_exception
    raise exc
  File "D:\python files\Project tasks\customizeUserModel\venv\lib\site-packages\rest_framework\views.py", line 506, in dispatch
    response = handler(request, *args, **kwargs)
  File "D:\python files\Project tasks\customizeUserModel\projectDept\accounts\views.py", line 29, in post
    serializer.save()
  File "D:\python files\Project tasks\customizeUserModel\venv\lib\site-packages\rest_framework\serializers.py", line 212, in save
    self.instance = self.create(validated_data)
  File "D:\python files\Project tasks\customizeUserModel\projectDept\accounts\Serializers.py", line 47, in create
    send_mail(Subject,message,from_email,to_email)
  File "D:\python files\Project tasks\customizeUserModel\venv\lib\site-packages\django\core\mail\__init__.py", line 87, in send_mail
    return mail.send()
  File "D:\python files\Project tasks\customizeUserModel\venv\lib\site-packages\django\core\mail\message.py", line 298, in send
    return self.get_connection(fail_silently).send_messages([self])
  File "D:\python files\Project tasks\customizeUserModel\venv\lib\site-packages\django\core\mail\backends\smtp.py", line 127, in send_messages
    new_conn_created = self.open()
  File "D:\python files\Project tasks\customizeUserModel\venv\lib\site-packages\django\core\mail\backends\smtp.py", line 92, in open
    self.connection.starttls(context=self.ssl_context)
  File "C:\Users\Admin\AppData\Local\Programs\Python\Python310\lib\smtplib.py", line 790, in starttls
    self.sock = context.wrap_socket(self.sock,
  File "C:\Users\Admin\AppData\Local\Programs\Python\Python310\lib\ssl.py", line 512, in wrap_socket
    return self.sslsocket_class._create(
  File "C:\Users\Admin\AppData\Local\Programs\Python\Python310\lib\ssl.py", line 1070, in _create
    self.do_handshake()
  File "C:\Users\Admin\AppData\Local\Programs\Python\Python310\lib\ssl.py", line 1341, in do_handshake
    self._sslobj.do_handshake()
FileNotFoundError: [Errno 2] No such file or directory
ERROR 2023-08-04 11:50:01,413 basehttp "POST /accounts/register/ HTTP/1.1" 500 153611
ERROR 2023-08-04 14:40:14,344 log Internal Server Error: /activate/MTk/bsewpm-13ceaae1356fd1a414aea5bebd32e2d8/
Traceback (most recent call last):
  File "D:\python files\Project tasks\customizeUserModel\venv\lib\site-packages\django\core\handlers\exception.py", line 55, in inner
    response = get_response(request)
  File "D:\python files\Project tasks\customizeUserModel\venv\lib\site-packages\django\core\handlers\base.py", line 197, in _get_response
    response = wrapped_callback(request, *callback_args, **callback_kwargs)
  File "D:\python files\Project tasks\customizeUserModel\venv\lib\site-packages\django\views\decorators\csrf.py", line 56, in wrapper_view
    return view_func(*args, **kwargs)
  File "D:\python files\Project tasks\customizeUserModel\venv\lib\site-packages\django\views\generic\base.py", line 104, in view
    return self.dispatch(request, *args, **kwargs)
  File "D:\python files\Project tasks\customizeUserModel\venv\lib\site-packages\rest_framework\views.py", line 509, in dispatch
    response = self.handle_exception(exc)
  File "D:\python files\Project tasks\customizeUserModel\venv\lib\site-packages\rest_framework\views.py", line 469, in handle_exception
    self.raise_uncaught_exception(exc)
  File "D:\python files\Project tasks\customizeUserModel\venv\lib\site-packages\rest_framework\views.py", line 480, in raise_uncaught_exception
    raise exc
  File "D:\python files\Project tasks\customizeUserModel\venv\lib\site-packages\rest_framework\views.py", line 506, in dispatch
    response = handler(request, *args, **kwargs)
  File "D:\python files\Project tasks\customizeUserModel\projectDept\accounts\views.py", line 48, in post
    if default_token_generator.check_token(user, token):
UnboundLocalError: local variable 'user' referenced before assignment
ERROR 2023-08-04 14:40:14,357 basehttp "POST /activate/MTk/bsewpm-13ceaae1356fd1a414aea5bebd32e2d8/ HTTP/1.1" 500 103587
ERROR 2023-08-04 14:44:16,332 log Internal Server Error: /activate/MTk/bsewpm-13ceaae1356fd1a414aea5bebd32e2d8/
Traceback (most recent call last):
  File "D:\python files\Project tasks\customizeUserModel\venv\lib\site-packages\django\core\handlers\exception.py", line 55, in inner
    response = get_response(request)
  File "D:\python files\Project tasks\customizeUserModel\venv\lib\site-packages\django\core\handlers\base.py", line 197, in _get_response
    response = wrapped_callback(request, *callback_args, **callback_kwargs)
  File "D:\python files\Project tasks\customizeUserModel\venv\lib\site-packages\django\views\decorators\csrf.py", line 56, in wrapper_view
    return view_func(*args, **kwargs)
  File "D:\python files\Project tasks\customizeUserModel\venv\lib\site-packages\django\views\generic\base.py", line 104, in view
    return self.dispatch(request, *args, **kwargs)
  File "D:\python files\Project tasks\customizeUserModel\venv\lib\site-packages\rest_framework\views.py", line 509, in dispatch
    response = self.handle_exception(exc)
  File "D:\python files\Project tasks\customizeUserModel\venv\lib\site-packages\rest_framework\views.py", line 469, in handle_exception
    self.raise_uncaught_exception(exc)
  File "D:\python files\Project tasks\customizeUserModel\venv\lib\site-packages\rest_framework\views.py", line 480, in raise_uncaught_exception
    raise exc
  File "D:\python files\Project tasks\customizeUserModel\venv\lib\site-packages\rest_framework\views.py", line 506, in dispatch
    response = handler(request, *args, **kwargs)
  File "D:\python files\Project tasks\customizeUserModel\projectDept\accounts\views.py", line 48, in post
    if user is not None and default_token_generator.check_token(user, token):
UnboundLocalError: local variable 'user' referenced before assignment
ERROR 2023-08-04 14:44:16,335 basehttp "POST /activate/MTk/bsewpm-13ceaae1356fd1a414aea5bebd32e2d8/ HTTP/1.1" 500 103629
ERROR 2023-08-04 15:08:58,480 log Internal Server Error: /activate/MTk/bsewpm-13ceaae1356fd1a414aea5bebd32e2d8/
Traceback (most recent call last):
  File "D:\python files\Project tasks\customizeUserModel\venv\lib\site-packages\django\core\handlers\exception.py", line 55, in inner
    response = get_response(request)
  File "D:\python files\Project tasks\customizeUserModel\venv\lib\site-packages\django\core\handlers\base.py", line 197, in _get_response
    response = wrapped_callback(request, *callback_args, **callback_kwargs)
  File "D:\python files\Project tasks\customizeUserModel\venv\lib\site-packages\django\views\decorators\csrf.py", line 56, in wrapper_view
    return view_func(*args, **kwargs)
  File "D:\python files\Project tasks\customizeUserModel\venv\lib\site-packages\django\views\generic\base.py", line 104, in view
    return self.dispatch(request, *args, **kwargs)
  File "D:\python files\Project tasks\customizeUserModel\venv\lib\site-packages\rest_framework\views.py", line 509, in dispatch
    response = self.handle_exception(exc)
  File "D:\python files\Project tasks\customizeUserModel\venv\lib\site-packages\rest_framework\views.py", line 469, in handle_exception
    self.raise_uncaught_exception(exc)
  File "D:\python files\Project tasks\customizeUserModel\venv\lib\site-packages\rest_framework\views.py", line 480, in raise_uncaught_exception
    raise exc
  File "D:\python files\Project tasks\customizeUserModel\venv\lib\site-packages\rest_framework\views.py", line 506, in dispatch
    response = handler(request, *args, **kwargs)
TypeError: Account_activation_API.post() got an unexpected keyword argument 'uidb64'
ERROR 2023-08-04 15:08:58,483 basehttp "POST /activate/MTk/bsewpm-13ceaae1356fd1a414aea5bebd32e2d8/ HTTP/1.1" 500 99344
ERROR 2023-08-04 15:10:04,838 log Internal Server Error: /activate/MTk/bsewpm-13ceaae1356fd1a414aea5bebd32e2d8/
Traceback (most recent call last):
  File "D:\python files\Project tasks\customizeUserModel\venv\lib\site-packages\django\core\handlers\exception.py", line 55, in inner
    response = get_response(request)
  File "D:\python files\Project tasks\customizeUserModel\venv\lib\site-packages\django\core\handlers\base.py", line 197, in _get_response
    response = wrapped_callback(request, *callback_args, **callback_kwargs)
  File "D:\python files\Project tasks\customizeUserModel\venv\lib\site-packages\django\views\decorators\csrf.py", line 56, in wrapper_view
    return view_func(*args, **kwargs)
  File "D:\python files\Project tasks\customizeUserModel\venv\lib\site-packages\django\views\generic\base.py", line 104, in view
    return self.dispatch(request, *args, **kwargs)
  File "D:\python files\Project tasks\customizeUserModel\venv\lib\site-packages\rest_framework\views.py", line 509, in dispatch
    response = self.handle_exception(exc)
  File "D:\python files\Project tasks\customizeUserModel\venv\lib\site-packages\rest_framework\views.py", line 469, in handle_exception
    self.raise_uncaught_exception(exc)
  File "D:\python files\Project tasks\customizeUserModel\venv\lib\site-packages\rest_framework\views.py", line 480, in raise_uncaught_exception
    raise exc
  File "D:\python files\Project tasks\customizeUserModel\venv\lib\site-packages\rest_framework\views.py", line 506, in dispatch
    response = handler(request, *args, **kwargs)
TypeError: Account_activation_API.post() got an unexpected keyword argument 'uidb64'
ERROR 2023-08-04 15:10:04,841 basehttp "POST /activate/MTk/bsewpm-13ceaae1356fd1a414aea5bebd32e2d8/ HTTP/1.1" 500 99344
ERROR 2023-08-04 15:10:49,387 log Internal Server Error: /activate/MTk/bsewpm-13ceaae1356fd1a414aea5bebd32e2d8/
Traceback (most recent call last):
  File "D:\python files\Project tasks\customizeUserModel\venv\lib\site-packages\django\core\handlers\exception.py", line 55, in inner
    response = get_response(request)
  File "D:\python files\Project tasks\customizeUserModel\venv\lib\site-packages\django\core\handlers\base.py", line 197, in _get_response
    response = wrapped_callback(request, *callback_args, **callback_kwargs)
  File "D:\python files\Project tasks\customizeUserModel\venv\lib\site-packages\django\views\decorators\csrf.py", line 56, in wrapper_view
    return view_func(*args, **kwargs)
  File "D:\python files\Project tasks\customizeUserModel\venv\lib\site-packages\django\views\generic\base.py", line 104, in view
    return self.dispatch(request, *args, **kwargs)
  File "D:\python files\Project tasks\customizeUserModel\venv\lib\site-packages\rest_framework\views.py", line 509, in dispatch
    response = self.handle_exception(exc)
  File "D:\python files\Project tasks\customizeUserModel\venv\lib\site-packages\rest_framework\views.py", line 469, in handle_exception
    self.raise_uncaught_exception(exc)
  File "D:\python files\Project tasks\customizeUserModel\venv\lib\site-packages\rest_framework\views.py", line 480, in raise_uncaught_exception
    raise exc
  File "D:\python files\Project tasks\customizeUserModel\venv\lib\site-packages\rest_framework\views.py", line 506, in dispatch
    response = handler(request, *args, **kwargs)
TypeError: Account_activation_API.post() got an unexpected keyword argument 'uid'
ERROR 2023-08-04 15:10:49,390 basehttp "POST /activate/MTk/bsewpm-13ceaae1356fd1a414aea5bebd32e2d8/ HTTP/1.1" 500 99296
ERROR 2023-08-04 15:13:40,133 log Internal Server Error: /activate/MjA/bsey9r-278f83ab5ec3c87c08fbe866c362817b/
Traceback (most recent call last):
  File "D:\python files\Project tasks\customizeUserModel\venv\lib\site-packages\django\core\handlers\exception.py", line 55, in inner
    response = get_response(request)
  File "D:\python files\Project tasks\customizeUserModel\venv\lib\site-packages\django\core\handlers\base.py", line 197, in _get_response
    response = wrapped_callback(request, *callback_args, **callback_kwargs)
  File "D:\python files\Project tasks\customizeUserModel\venv\lib\site-packages\django\views\decorators\csrf.py", line 56, in wrapper_view
    return view_func(*args, **kwargs)
  File "D:\python files\Project tasks\customizeUserModel\venv\lib\site-packages\django\views\generic\base.py", line 104, in view
    return self.dispatch(request, *args, **kwargs)
  File "D:\python files\Project tasks\customizeUserModel\venv\lib\site-packages\rest_framework\views.py", line 509, in dispatch
    response = self.handle_exception(exc)
  File "D:\python files\Project tasks\customizeUserModel\venv\lib\site-packages\rest_framework\views.py", line 469, in handle_exception
    self.raise_uncaught_exception(exc)
  File "D:\python files\Project tasks\customizeUserModel\venv\lib\site-packages\rest_framework\views.py", line 480, in raise_uncaught_exception
    raise exc
  File "D:\python files\Project tasks\customizeUserModel\venv\lib\site-packages\rest_framework\views.py", line 506, in dispatch
    response = handler(request, *args, **kwargs)
TypeError: Account_activation_API.post() got an unexpected keyword argument 'uid'
ERROR 2023-08-04 15:13:40,136 basehttp "POST /activate/MjA/bsey9r-278f83ab5ec3c87c08fbe866c362817b/ HTTP/1.1" 500 99296
ERROR 2023-08-04 15:17:43,104 log Internal Server Error: /activate/MjA/bsey9r-278f83ab5ec3c87c08fbe866c362817b/
Traceback (most recent call last):
  File "D:\python files\Project tasks\customizeUserModel\venv\lib\site-packages\django\core\handlers\exception.py", line 55, in inner
    response = get_response(request)
  File "D:\python files\Project tasks\customizeUserModel\venv\lib\site-packages\django\core\handlers\base.py", line 197, in _get_response
    response = wrapped_callback(request, *callback_args, **callback_kwargs)
  File "D:\python files\Project tasks\customizeUserModel\venv\lib\site-packages\django\views\decorators\csrf.py", line 56, in wrapper_view
    return view_func(*args, **kwargs)
  File "D:\python files\Project tasks\customizeUserModel\venv\lib\site-packages\django\views\generic\base.py", line 104, in view
    return self.dispatch(request, *args, **kwargs)
  File "D:\python files\Project tasks\customizeUserModel\venv\lib\site-packages\rest_framework\views.py", line 509, in dispatch
    response = self.handle_exception(exc)
  File "D:\python files\Project tasks\customizeUserModel\venv\lib\site-packages\rest_framework\views.py", line 469, in handle_exception
    self.raise_uncaught_exception(exc)
  File "D:\python files\Project tasks\customizeUserModel\venv\lib\site-packages\rest_framework\views.py", line 480, in raise_uncaught_exception
    raise exc
  File "D:\python files\Project tasks\customizeUserModel\venv\lib\site-packages\rest_framework\views.py", line 506, in dispatch
    response = handler(request, *args, **kwargs)
TypeError: Account_activation_API.post() got an unexpected keyword argument 'uid'
ERROR 2023-08-04 15:17:43,107 basehttp "POST /activate/MjA/bsey9r-278f83ab5ec3c87c08fbe866c362817b/ HTTP/1.1" 500 99296
