ERROR 2023-08-02 17:29:25,075 log Internal Server Error: /department/projectdetails/
Traceback (most recent call last):
  File "D:\python files\Project tasks\customizeUserModel\venv\lib\site-packages\django\core\handlers\exception.py", line 55, in inner
    response = get_response(request)
  File "D:\python files\Project tasks\customizeUserModel\venv\lib\site-packages\django\core\handlers\base.py", line 197, in _get_response
    response = wrapped_callback(request, *callback_args, **callback_kwargs)
  File "D:\python files\Project tasks\customizeUserModel\venv\lib\site-packages\django\views\decorators\csrf.py", line 56, in wrapper_view
    return view_func(*args, **kwargs)
  File "D:\python files\Project tasks\customizeUserModel\venv\lib\site-packages\django\views\generic\base.py", line 104, in view
    return self.dispatch(request, *args, **kwargs)
  File "D:\python files\Project tasks\customizeUserModel\venv\lib\site-packages\rest_framework\views.py", line 492, in dispatch
    request = self.initialize_request(request, *args, **kwargs)
  File "D:\python files\Project tasks\customizeUserModel\venv\lib\site-packages\rest_framework\views.py", line 394, in initialize_request
    authenticators=self.get_authenticators(),
  File "D:\python files\Project tasks\customizeUserModel\venv\lib\site-packages\rest_framework\views.py", line 272, in get_authenticators
    return [auth() for auth in self.authentication_classes]
  File "D:\python files\Project tasks\customizeUserModel\venv\lib\site-packages\rest_framework\views.py", line 272, in <listcomp>
    return [auth() for auth in self.authentication_classes]
TypeError: 'list' object is not callable
ERROR 2023-08-02 17:29:25,078 basehttp "POST /department/projectdetails/ HTTP/1.1" 500 94691
ERROR 2023-08-02 19:43:27,168 log Internal Server Error: /department/projectdetails/27/
Traceback (most recent call last):
  File "D:\python files\Project tasks\customizeUserModel\venv\lib\site-packages\django\db\backends\utils.py", line 89, in _execute
    return self.cursor.execute(sql, params)
  File "D:\python files\Project tasks\customizeUserModel\venv\lib\site-packages\django\db\backends\sqlite3\base.py", line 328, in execute
    return super().execute(query, params)
sqlite3.IntegrityError: CHECK constraint failed: team_size

The above exception was the direct cause of the following exception:

Traceback (most recent call last):
  File "D:\python files\Project tasks\customizeUserModel\venv\lib\site-packages\django\core\handlers\exception.py", line 55, in inner
    response = get_response(request)
  File "D:\python files\Project tasks\customizeUserModel\venv\lib\site-packages\django\core\handlers\base.py", line 197, in _get_response
    response = wrapped_callback(request, *callback_args, **callback_kwargs)
  File "D:\python files\Project tasks\customizeUserModel\venv\lib\site-packages\django\views\decorators\csrf.py", line 56, in wrapper_view
    return view_func(*args, **kwargs)
  File "D:\python files\Project tasks\customizeUserModel\venv\lib\site-packages\django\views\generic\base.py", line 104, in view
    return self.dispatch(request, *args, **kwargs)
  File "D:\python files\Project tasks\customizeUserModel\venv\lib\site-packages\rest_framework\views.py", line 509, in dispatch
    response = self.handle_exception(exc)
  File "D:\python files\Project tasks\customizeUserModel\venv\lib\site-packages\rest_framework\views.py", line 469, in handle_exception
    self.raise_uncaught_exception(exc)
  File "D:\python files\Project tasks\customizeUserModel\venv\lib\site-packages\rest_framework\views.py", line 480, in raise_uncaught_exception
    raise exc
  File "D:\python files\Project tasks\customizeUserModel\venv\lib\site-packages\rest_framework\views.py", line 506, in dispatch
    response = handler(request, *args, **kwargs)
  File "D:\python files\Project tasks\customizeUserModel\projectDept\project\views.py", line 48, in put
    serializer.save()
  File "D:\python files\Project tasks\customizeUserModel\venv\lib\site-packages\rest_framework\serializers.py", line 207, in save
    self.instance = self.update(self.instance, validated_data)
  File "D:\python files\Project tasks\customizeUserModel\projectDept\project\Serializers.py", line 26, in update
    return super().update(instance, validated_data)
  File "D:\python files\Project tasks\customizeUserModel\venv\lib\site-packages\rest_framework\serializers.py", line 1006, in update
    instance.save()
  File "D:\python files\Project tasks\customizeUserModel\venv\lib\site-packages\django\db\models\base.py", line 814, in save
    self.save_base(
  File "D:\python files\Project tasks\customizeUserModel\venv\lib\site-packages\django\db\models\base.py", line 877, in save_base
    updated = self._save_table(
  File "D:\python files\Project tasks\customizeUserModel\venv\lib\site-packages\django\db\models\base.py", line 990, in _save_table
    updated = self._do_update(
  File "D:\python files\Project tasks\customizeUserModel\venv\lib\site-packages\django\db\models\base.py", line 1054, in _do_update
    return filtered._update(values) > 0
  File "D:\python files\Project tasks\customizeUserModel\venv\lib\site-packages\django\db\models\query.py", line 1231, in _update
    return query.get_compiler(self.db).execute_sql(CURSOR)
  File "D:\python files\Project tasks\customizeUserModel\venv\lib\site-packages\django\db\models\sql\compiler.py", line 1984, in execute_sql
    cursor = super().execute_sql(result_type)
  File "D:\python files\Project tasks\customizeUserModel\venv\lib\site-packages\django\db\models\sql\compiler.py", line 1562, in execute_sql
    cursor.execute(sql, params)
  File "D:\python files\Project tasks\customizeUserModel\venv\lib\site-packages\django\db\backends\utils.py", line 102, in execute
    return super().execute(sql, params)
  File "D:\python files\Project tasks\customizeUserModel\venv\lib\site-packages\django\db\backends\utils.py", line 67, in execute
    return self._execute_with_wrappers(
  File "D:\python files\Project tasks\customizeUserModel\venv\lib\site-packages\django\db\backends\utils.py", line 80, in _execute_with_wrappers
    return executor(sql, params, many, context)
  File "D:\python files\Project tasks\customizeUserModel\venv\lib\site-packages\django\db\backends\utils.py", line 84, in _execute
    with self.db.wrap_database_errors:
  File "D:\python files\Project tasks\customizeUserModel\venv\lib\site-packages\django\db\utils.py", line 91, in __exit__
    raise dj_exc_value.with_traceback(traceback) from exc_value
  File "D:\python files\Project tasks\customizeUserModel\venv\lib\site-packages\django\db\backends\utils.py", line 89, in _execute
    return self.cursor.execute(sql, params)
  File "D:\python files\Project tasks\customizeUserModel\venv\lib\site-packages\django\db\backends\sqlite3\base.py", line 328, in execute
    return super().execute(query, params)
django.db.utils.IntegrityError: CHECK constraint failed: team_size
ERROR 2023-08-02 19:43:27,201 basehttp "PUT /department/projectdetails/27/ HTTP/1.1" 500 207272
