WARNING 2023-08-02 17:18:53,082 log Bad Request: /department/projectdetails/
WARNING 2023-08-02 17:18:53,083 basehttp "POST /department/projectdetails/ HTTP/1.1" 400 52
WARNING 2023-08-02 17:21:14,582 log Bad Request: /department/projectdetails/
WARNING 2023-08-02 17:21:14,583 basehttp "POST /department/projectdetails/ HTTP/1.1" 400 46
WARNING 2023-08-02 17:22:54,446 log Not Found: /department/projectdetails/12/
WARNING 2023-08-02 17:22:54,448 basehttp "GET /department/projectdetails/12/ HTTP/1.1" 404 23
WARNING 2023-08-02 17:25:16,255 log Method Not Allowed: /department/projectdetails/11/
WARNING 2023-08-02 17:25:16,256 basehttp "POST /department/projectdetails/11/ HTTP/1.1" 405 41
WARNING 2023-08-02 17:25:38,331 log Method Not Allowed: /department/projectdetails/11/
WARNING 2023-08-02 17:25:38,333 basehttp "POST /department/projectdetails/11/ HTTP/1.1" 405 41
ERROR 2023-08-02 17:29:25,075 log Internal Server Error: /department/projectdetails/
Traceback (most recent call last):
  File "D:\python files\Project tasks\customizeUserModel\venv\lib\site-packages\django\core\handlers\exception.py", line 55, in inner
    response = get_response(request)
  File "D:\python files\Project tasks\customizeUserModel\venv\lib\site-packages\django\core\handlers\base.py", line 197, in _get_response
    response = wrapped_callback(request, *callback_args, **callback_kwargs)
  File "D:\python files\Project tasks\customizeUserModel\venv\lib\site-packages\django\views\decorators\csrf.py", line 56, in wrapper_view
    return view_func(*args, **kwargs)
  File "D:\python files\Project tasks\customizeUserModel\venv\lib\site-packages\django\views\generic\base.py", line 104, in view
    return self.dispatch(request, *args, **kwargs)
  File "D:\python files\Project tasks\customizeUserModel\venv\lib\site-packages\rest_framework\views.py", line 492, in dispatch
    request = self.initialize_request(request, *args, **kwargs)
  File "D:\python files\Project tasks\customizeUserModel\venv\lib\site-packages\rest_framework\views.py", line 394, in initialize_request
    authenticators=self.get_authenticators(),
  File "D:\python files\Project tasks\customizeUserModel\venv\lib\site-packages\rest_framework\views.py", line 272, in get_authenticators
    return [auth() for auth in self.authentication_classes]
  File "D:\python files\Project tasks\customizeUserModel\venv\lib\site-packages\rest_framework\views.py", line 272, in <listcomp>
    return [auth() for auth in self.authentication_classes]
TypeError: 'list' object is not callable
ERROR 2023-08-02 17:29:25,078 basehttp "POST /department/projectdetails/ HTTP/1.1" 500 94691
WARNING 2023-08-02 17:29:54,681 log Unauthorized: /department/projectdetails/
WARNING 2023-08-02 17:29:54,683 basehttp "POST /department/projectdetails/ HTTP/1.1" 401 58
WARNING 2023-08-02 17:31:01,205 log Not Found: /department/projectdetails/10/
WARNING 2023-08-02 17:31:01,206 basehttp "DELETE /department/projectdetails/10/ HTTP/1.1" 404 23
WARNING 2023-08-02 18:39:43,716 log Bad Request: /department/projectdetails/
WARNING 2023-08-02 18:39:43,755 basehttp "POST /department/projectdetails/ HTTP/1.1" 400 142
WARNING 2023-08-02 18:40:39,869 log Bad Request: /department/projectdetails/
WARNING 2023-08-02 18:40:39,869 basehttp "POST /department/projectdetails/ HTTP/1.1" 400 48
WARNING 2023-08-02 18:41:22,505 log Bad Request: /department/projectdetails/
WARNING 2023-08-02 18:41:22,506 basehttp "POST /department/projectdetails/ HTTP/1.1" 400 48
WARNING 2023-08-02 18:55:32,087 log Bad Request: /department/projectdetails/
WARNING 2023-08-02 18:55:32,088 basehttp "POST /department/projectdetails/ HTTP/1.1" 400 48
WARNING 2023-08-02 18:57:07,047 log Bad Request: /department/projectdetails/
WARNING 2023-08-02 18:57:07,048 basehttp "POST /department/projectdetails/ HTTP/1.1" 400 52
WARNING 2023-08-02 18:59:17,236 log Bad Request: /department/projectdetails/
WARNING 2023-08-02 18:59:17,238 basehttp "POST /department/projectdetails/ HTTP/1.1" 400 95
WARNING 2023-08-02 19:05:44,005 log Not Found: /
WARNING 2023-08-02 19:05:44,006 basehttp "GET / HTTP/1.1" 404 2499
WARNING 2023-08-02 19:05:44,883 log Not Found: /
WARNING 2023-08-02 19:05:44,884 basehttp "GET / HTTP/1.1" 404 2499
WARNING 2023-08-02 19:42:08,454 log Bad Request: /department/projectdetails/27/
WARNING 2023-08-02 19:42:08,455 basehttp "PUT /department/projectdetails/27/ HTTP/1.1" 400 48
ERROR 2023-08-02 19:43:27,168 log Internal Server Error: /department/projectdetails/27/
Traceback (most recent call last):
  File "D:\python files\Project tasks\customizeUserModel\venv\lib\site-packages\django\db\backends\utils.py", line 89, in _execute
    return self.cursor.execute(sql, params)
  File "D:\python files\Project tasks\customizeUserModel\venv\lib\site-packages\django\db\backends\sqlite3\base.py", line 328, in execute
    return super().execute(query, params)
sqlite3.IntegrityError: CHECK constraint failed: team_size

The above exception was the direct cause of the following exception:

Traceback (most recent call last):
  File "D:\python files\Project tasks\customizeUserModel\venv\lib\site-packages\django\core\handlers\exception.py", line 55, in inner
    response = get_response(request)
  File "D:\python files\Project tasks\customizeUserModel\venv\lib\site-packages\django\core\handlers\base.py", line 197, in _get_response
    response = wrapped_callback(request, *callback_args, **callback_kwargs)
  File "D:\python files\Project tasks\customizeUserModel\venv\lib\site-packages\django\views\decorators\csrf.py", line 56, in wrapper_view
    return view_func(*args, **kwargs)
  File "D:\python files\Project tasks\customizeUserModel\venv\lib\site-packages\django\views\generic\base.py", line 104, in view
    return self.dispatch(request, *args, **kwargs)
  File "D:\python files\Project tasks\customizeUserModel\venv\lib\site-packages\rest_framework\views.py", line 509, in dispatch
    response = self.handle_exception(exc)
  File "D:\python files\Project tasks\customizeUserModel\venv\lib\site-packages\rest_framework\views.py", line 469, in handle_exception
    self.raise_uncaught_exception(exc)
  File "D:\python files\Project tasks\customizeUserModel\venv\lib\site-packages\rest_framework\views.py", line 480, in raise_uncaught_exception
    raise exc
  File "D:\python files\Project tasks\customizeUserModel\venv\lib\site-packages\rest_framework\views.py", line 506, in dispatch
    response = handler(request, *args, **kwargs)
  File "D:\python files\Project tasks\customizeUserModel\projectDept\project\views.py", line 48, in put
    serializer.save()
  File "D:\python files\Project tasks\customizeUserModel\venv\lib\site-packages\rest_framework\serializers.py", line 207, in save
    self.instance = self.update(self.instance, validated_data)
  File "D:\python files\Project tasks\customizeUserModel\projectDept\project\Serializers.py", line 26, in update
    return super().update(instance, validated_data)
  File "D:\python files\Project tasks\customizeUserModel\venv\lib\site-packages\rest_framework\serializers.py", line 1006, in update
    instance.save()
  File "D:\python files\Project tasks\customizeUserModel\venv\lib\site-packages\django\db\models\base.py", line 814, in save
    self.save_base(
  File "D:\python files\Project tasks\customizeUserModel\venv\lib\site-packages\django\db\models\base.py", line 877, in save_base
    updated = self._save_table(
  File "D:\python files\Project tasks\customizeUserModel\venv\lib\site-packages\django\db\models\base.py", line 990, in _save_table
    updated = self._do_update(
  File "D:\python files\Project tasks\customizeUserModel\venv\lib\site-packages\django\db\models\base.py", line 1054, in _do_update
    return filtered._update(values) > 0
  File "D:\python files\Project tasks\customizeUserModel\venv\lib\site-packages\django\db\models\query.py", line 1231, in _update
    return query.get_compiler(self.db).execute_sql(CURSOR)
  File "D:\python files\Project tasks\customizeUserModel\venv\lib\site-packages\django\db\models\sql\compiler.py", line 1984, in execute_sql
    cursor = super().execute_sql(result_type)
  File "D:\python files\Project tasks\customizeUserModel\venv\lib\site-packages\django\db\models\sql\compiler.py", line 1562, in execute_sql
    cursor.execute(sql, params)
  File "D:\python files\Project tasks\customizeUserModel\venv\lib\site-packages\django\db\backends\utils.py", line 102, in execute
    return super().execute(sql, params)
  File "D:\python files\Project tasks\customizeUserModel\venv\lib\site-packages\django\db\backends\utils.py", line 67, in execute
    return self._execute_with_wrappers(
  File "D:\python files\Project tasks\customizeUserModel\venv\lib\site-packages\django\db\backends\utils.py", line 80, in _execute_with_wrappers
    return executor(sql, params, many, context)
  File "D:\python files\Project tasks\customizeUserModel\venv\lib\site-packages\django\db\backends\utils.py", line 84, in _execute
    with self.db.wrap_database_errors:
  File "D:\python files\Project tasks\customizeUserModel\venv\lib\site-packages\django\db\utils.py", line 91, in __exit__
    raise dj_exc_value.with_traceback(traceback) from exc_value
  File "D:\python files\Project tasks\customizeUserModel\venv\lib\site-packages\django\db\backends\utils.py", line 89, in _execute
    return self.cursor.execute(sql, params)
  File "D:\python files\Project tasks\customizeUserModel\venv\lib\site-packages\django\db\backends\sqlite3\base.py", line 328, in execute
    return super().execute(query, params)
django.db.utils.IntegrityError: CHECK constraint failed: team_size
ERROR 2023-08-02 19:43:27,201 basehttp "PUT /department/projectdetails/27/ HTTP/1.1" 500 207272
WARNING 2023-08-02 21:32:05,838 log Bad Request: /accounts/register/
WARNING 2023-08-02 21:32:05,839 basehttp "POST /accounts/register/ HTTP/1.1" 400 58
WARNING 2023-08-02 22:15:14,308 log Unauthorized: /department/projectdetails/26/
WARNING 2023-08-02 22:15:14,309 basehttp "GET /department/projectdetails/26/ HTTP/1.1" 401 183
WARNING 2023-08-02 22:15:14,312 log Unauthorized: /department/projectdetails/26/
WARNING 2023-08-02 22:15:14,313 basehttp "GET /department/projectdetails/26/ HTTP/1.1" 401 183
WARNING 2023-08-03 21:55:50,969 log Not Found: /project/home/
WARNING 2023-08-03 21:55:51,001 basehttp "GET /project/home/ HTTP/1.1" 404 2556
WARNING 2023-08-03 22:00:19,861 log Bad Request: /accounts/register/
WARNING 2023-08-03 22:00:19,863 basehttp "POST /accounts/register/ HTTP/1.1" 400 50
ERROR 2023-08-03 22:24:31,155 log Internal Server Error: /accounts/register/
Traceback (most recent call last):
  File "D:\python files\Project tasks\customizeUserModel\venv\lib\site-packages\django\core\handlers\exception.py", line 55, in inner
    response = get_response(request)
  File "D:\python files\Project tasks\customizeUserModel\venv\lib\site-packages\django\core\handlers\base.py", line 197, in _get_response
    response = wrapped_callback(request, *callback_args, **callback_kwargs)
  File "D:\python files\Project tasks\customizeUserModel\venv\lib\site-packages\django\views\decorators\csrf.py", line 56, in wrapper_view
    return view_func(*args, **kwargs)
  File "D:\python files\Project tasks\customizeUserModel\venv\lib\site-packages\django\views\generic\base.py", line 104, in view
    return self.dispatch(request, *args, **kwargs)
  File "D:\python files\Project tasks\customizeUserModel\venv\lib\site-packages\rest_framework\views.py", line 509, in dispatch
    response = self.handle_exception(exc)
  File "D:\python files\Project tasks\customizeUserModel\venv\lib\site-packages\rest_framework\views.py", line 469, in handle_exception
    self.raise_uncaught_exception(exc)
  File "D:\python files\Project tasks\customizeUserModel\venv\lib\site-packages\rest_framework\views.py", line 480, in raise_uncaught_exception
    raise exc
  File "D:\python files\Project tasks\customizeUserModel\venv\lib\site-packages\rest_framework\views.py", line 506, in dispatch
    response = handler(request, *args, **kwargs)
  File "D:\python files\Project tasks\customizeUserModel\projectDept\accounts\views.py", line 21, in post
    serializer.save()
  File "D:\python files\Project tasks\customizeUserModel\venv\lib\site-packages\rest_framework\serializers.py", line 212, in save
    self.instance = self.create(validated_data)
  File "D:\python files\Project tasks\customizeUserModel\projectDept\accounts\Serializers.py", line 34, in create
    domain = get_current_site(self)
  File "D:\python files\Project tasks\customizeUserModel\venv\lib\site-packages\django\contrib\sites\shortcuts.py", line 18, in get_current_site
    return RequestSite(request)
  File "D:\python files\Project tasks\customizeUserModel\venv\lib\site-packages\django\contrib\sites\requests.py", line 11, in __init__
    self.domain = self.name = request.get_host()
AttributeError: 'registerUser' object has no attribute 'get_host'
ERROR 2023-08-03 22:24:31,218 basehttp "POST /accounts/register/ HTTP/1.1" 500 125553
WARNING 2023-08-03 22:26:32,021 log Bad Request: /accounts/register/
WARNING 2023-08-03 22:26:32,022 basehttp "POST /accounts/register/ HTTP/1.1" 400 107
WARNING 2023-08-03 22:28:55,479 log Not Found: /activate/MTA/bsdnrf-332986871dd0ea858ad19a5a95b471e4/
WARNING 2023-08-03 22:28:55,480 basehttp "GET /activate/MTA/bsdnrf-332986871dd0ea858ad19a5a95b471e4/ HTTP/1.1" 404 2676
ERROR 2023-08-03 22:44:58,242 log Internal Server Error: /accounts/register/
Traceback (most recent call last):
  File "D:\python files\Project tasks\customizeUserModel\venv\lib\site-packages\django\core\handlers\exception.py", line 55, in inner
    response = get_response(request)
  File "D:\python files\Project tasks\customizeUserModel\venv\lib\site-packages\django\core\handlers\base.py", line 197, in _get_response
    response = wrapped_callback(request, *callback_args, **callback_kwargs)
  File "D:\python files\Project tasks\customizeUserModel\venv\lib\site-packages\django\views\decorators\csrf.py", line 56, in wrapper_view
    return view_func(*args, **kwargs)
  File "D:\python files\Project tasks\customizeUserModel\venv\lib\site-packages\django\views\generic\base.py", line 104, in view
    return self.dispatch(request, *args, **kwargs)
  File "D:\python files\Project tasks\customizeUserModel\venv\lib\site-packages\rest_framework\views.py", line 509, in dispatch
    response = self.handle_exception(exc)
  File "D:\python files\Project tasks\customizeUserModel\venv\lib\site-packages\rest_framework\views.py", line 469, in handle_exception
    self.raise_uncaught_exception(exc)
  File "D:\python files\Project tasks\customizeUserModel\venv\lib\site-packages\rest_framework\views.py", line 480, in raise_uncaught_exception
    raise exc
  File "D:\python files\Project tasks\customizeUserModel\venv\lib\site-packages\rest_framework\views.py", line 506, in dispatch
    response = handler(request, *args, **kwargs)
  File "D:\python files\Project tasks\customizeUserModel\projectDept\accounts\views.py", line 29, in post
    serializer.save()
  File "D:\python files\Project tasks\customizeUserModel\venv\lib\site-packages\rest_framework\serializers.py", line 212, in save
    self.instance = self.create(validated_data)
  File "D:\python files\Project tasks\customizeUserModel\projectDept\accounts\Serializers.py", line 35, in create
    domain = get_current_site(request)
  File "D:\python files\Project tasks\customizeUserModel\venv\lib\site-packages\django\contrib\sites\shortcuts.py", line 18, in get_current_site
    return RequestSite(request)
  File "D:\python files\Project tasks\customizeUserModel\venv\lib\site-packages\django\contrib\sites\requests.py", line 11, in __init__
    self.domain = self.name = request.get_host()
AttributeError: 'NoneType' object has no attribute 'get_host'
ERROR 2023-08-03 22:44:58,249 basehttp "POST /accounts/register/ HTTP/1.1" 500 121948
ERROR 2023-08-03 22:54:40,459 log Internal Server Error: /accounts/register/
Traceback (most recent call last):
  File "D:\python files\Project tasks\customizeUserModel\venv\lib\site-packages\django\core\handlers\exception.py", line 55, in inner
    response = get_response(request)
  File "D:\python files\Project tasks\customizeUserModel\venv\lib\site-packages\django\core\handlers\base.py", line 197, in _get_response
    response = wrapped_callback(request, *callback_args, **callback_kwargs)
  File "D:\python files\Project tasks\customizeUserModel\venv\lib\site-packages\django\views\decorators\csrf.py", line 56, in wrapper_view
    return view_func(*args, **kwargs)
  File "D:\python files\Project tasks\customizeUserModel\venv\lib\site-packages\django\views\generic\base.py", line 104, in view
    return self.dispatch(request, *args, **kwargs)
  File "D:\python files\Project tasks\customizeUserModel\venv\lib\site-packages\rest_framework\views.py", line 509, in dispatch
    response = self.handle_exception(exc)
  File "D:\python files\Project tasks\customizeUserModel\venv\lib\site-packages\rest_framework\views.py", line 469, in handle_exception
    self.raise_uncaught_exception(exc)
  File "D:\python files\Project tasks\customizeUserModel\venv\lib\site-packages\rest_framework\views.py", line 480, in raise_uncaught_exception
    raise exc
  File "D:\python files\Project tasks\customizeUserModel\venv\lib\site-packages\rest_framework\views.py", line 506, in dispatch
    response = handler(request, *args, **kwargs)
  File "D:\python files\Project tasks\customizeUserModel\projectDept\accounts\views.py", line 29, in post
    serializer.save()
  File "D:\python files\Project tasks\customizeUserModel\venv\lib\site-packages\rest_framework\serializers.py", line 212, in save
    self.instance = self.create(validated_data)
  File "D:\python files\Project tasks\customizeUserModel\projectDept\accounts\Serializers.py", line 36, in create
    current_site = validated_data.pop('current_site')
KeyError: 'current_site'
ERROR 2023-08-03 22:54:40,465 basehttp "POST /accounts/register/ HTTP/1.1" 500 115137
WARNING 2023-08-03 22:58:31,238 log Not Found: /favicon.ico
WARNING 2023-08-03 22:58:31,239 basehttp "GET /favicon.ico HTTP/1.1" 404 2713
WARNING 2023-08-04 10:36:30,898 log Not Found: /
WARNING 2023-08-04 10:36:30,939 basehttp "GET / HTTP/1.1" 404 2662
WARNING 2023-08-04 10:36:31,061 log Not Found: /favicon.ico
WARNING 2023-08-04 10:36:31,063 basehttp "GET /favicon.ico HTTP/1.1" 404 2713
WARNING 2023-08-04 11:26:33,820 log Not Found: /favicon.ico
WARNING 2023-08-04 11:26:33,822 basehttp "GET /favicon.ico HTTP/1.1" 404 2713
WARNING 2023-08-04 11:44:47,505 log Bad Request: /accounts/register/
WARNING 2023-08-04 11:44:47,506 basehttp "POST /accounts/register/ HTTP/1.1" 400 107
ERROR 2023-08-04 11:46:10,642 log Internal Server Error: /accounts/register/
Traceback (most recent call last):
  File "D:\python files\Project tasks\customizeUserModel\venv\lib\site-packages\django\core\handlers\exception.py", line 55, in inner
    response = get_response(request)
  File "D:\python files\Project tasks\customizeUserModel\venv\lib\site-packages\django\core\handlers\base.py", line 197, in _get_response
    response = wrapped_callback(request, *callback_args, **callback_kwargs)
  File "D:\python files\Project tasks\customizeUserModel\venv\lib\site-packages\django\views\decorators\csrf.py", line 56, in wrapper_view
    return view_func(*args, **kwargs)
  File "D:\python files\Project tasks\customizeUserModel\venv\lib\site-packages\django\views\generic\base.py", line 104, in view
    return self.dispatch(request, *args, **kwargs)
  File "D:\python files\Project tasks\customizeUserModel\venv\lib\site-packages\rest_framework\views.py", line 509, in dispatch
    response = self.handle_exception(exc)
  File "D:\python files\Project tasks\customizeUserModel\venv\lib\site-packages\rest_framework\views.py", line 469, in handle_exception
    self.raise_uncaught_exception(exc)
  File "D:\python files\Project tasks\customizeUserModel\venv\lib\site-packages\rest_framework\views.py", line 480, in raise_uncaught_exception
    raise exc
  File "D:\python files\Project tasks\customizeUserModel\venv\lib\site-packages\rest_framework\views.py", line 506, in dispatch
    response = handler(request, *args, **kwargs)
  File "D:\python files\Project tasks\customizeUserModel\projectDept\accounts\views.py", line 29, in post
    serializer.save()
  File "D:\python files\Project tasks\customizeUserModel\venv\lib\site-packages\rest_framework\serializers.py", line 212, in save
    self.instance = self.create(validated_data)
  File "D:\python files\Project tasks\customizeUserModel\projectDept\accounts\Serializers.py", line 47, in create
    send_mail(Subject,message,from_email,to_email)
  File "D:\python files\Project tasks\customizeUserModel\venv\lib\site-packages\django\core\mail\__init__.py", line 87, in send_mail
    return mail.send()
  File "D:\python files\Project tasks\customizeUserModel\venv\lib\site-packages\django\core\mail\message.py", line 298, in send
    return self.get_connection(fail_silently).send_messages([self])
  File "D:\python files\Project tasks\customizeUserModel\venv\lib\site-packages\django\core\mail\backends\smtp.py", line 127, in send_messages
    new_conn_created = self.open()
  File "D:\python files\Project tasks\customizeUserModel\venv\lib\site-packages\django\core\mail\backends\smtp.py", line 92, in open
    self.connection.starttls(context=self.ssl_context)
  File "C:\Users\Admin\AppData\Local\Programs\Python\Python310\lib\smtplib.py", line 790, in starttls
    self.sock = context.wrap_socket(self.sock,
  File "C:\Users\Admin\AppData\Local\Programs\Python\Python310\lib\ssl.py", line 512, in wrap_socket
    return self.sslsocket_class._create(
  File "C:\Users\Admin\AppData\Local\Programs\Python\Python310\lib\ssl.py", line 1070, in _create
    self.do_handshake()
  File "C:\Users\Admin\AppData\Local\Programs\Python\Python310\lib\ssl.py", line 1341, in do_handshake
    self._sslobj.do_handshake()
TimeoutError: [WinError 10060] A connection attempt failed because the connected party did not properly respond after a period of time, or established connection failed because connected host has failed to respond
ERROR 2023-08-04 11:46:10,672 basehttp "POST /accounts/register/ HTTP/1.1" 500 154603
ERROR 2023-08-04 11:50:01,407 log Internal Server Error: /accounts/register/
Traceback (most recent call last):
  File "D:\python files\Project tasks\customizeUserModel\venv\lib\site-packages\django\core\handlers\exception.py", line 55, in inner
    response = get_response(request)
  File "D:\python files\Project tasks\customizeUserModel\venv\lib\site-packages\django\core\handlers\base.py", line 197, in _get_response
    response = wrapped_callback(request, *callback_args, **callback_kwargs)
  File "D:\python files\Project tasks\customizeUserModel\venv\lib\site-packages\django\views\decorators\csrf.py", line 56, in wrapper_view
    return view_func(*args, **kwargs)
  File "D:\python files\Project tasks\customizeUserModel\venv\lib\site-packages\django\views\generic\base.py", line 104, in view
    return self.dispatch(request, *args, **kwargs)
  File "D:\python files\Project tasks\customizeUserModel\venv\lib\site-packages\rest_framework\views.py", line 509, in dispatch
    response = self.handle_exception(exc)
  File "D:\python files\Project tasks\customizeUserModel\venv\lib\site-packages\rest_framework\views.py", line 469, in handle_exception
    self.raise_uncaught_exception(exc)
  File "D:\python files\Project tasks\customizeUserModel\venv\lib\site-packages\rest_framework\views.py", line 480, in raise_uncaught_exception
    raise exc
  File "D:\python files\Project tasks\customizeUserModel\venv\lib\site-packages\rest_framework\views.py", line 506, in dispatch
    response = handler(request, *args, **kwargs)
  File "D:\python files\Project tasks\customizeUserModel\projectDept\accounts\views.py", line 29, in post
    serializer.save()
  File "D:\python files\Project tasks\customizeUserModel\venv\lib\site-packages\rest_framework\serializers.py", line 212, in save
    self.instance = self.create(validated_data)
  File "D:\python files\Project tasks\customizeUserModel\projectDept\accounts\Serializers.py", line 47, in create
    send_mail(Subject,message,from_email,to_email)
  File "D:\python files\Project tasks\customizeUserModel\venv\lib\site-packages\django\core\mail\__init__.py", line 87, in send_mail
    return mail.send()
  File "D:\python files\Project tasks\customizeUserModel\venv\lib\site-packages\django\core\mail\message.py", line 298, in send
    return self.get_connection(fail_silently).send_messages([self])
  File "D:\python files\Project tasks\customizeUserModel\venv\lib\site-packages\django\core\mail\backends\smtp.py", line 127, in send_messages
    new_conn_created = self.open()
  File "D:\python files\Project tasks\customizeUserModel\venv\lib\site-packages\django\core\mail\backends\smtp.py", line 92, in open
    self.connection.starttls(context=self.ssl_context)
  File "C:\Users\Admin\AppData\Local\Programs\Python\Python310\lib\smtplib.py", line 790, in starttls
    self.sock = context.wrap_socket(self.sock,
  File "C:\Users\Admin\AppData\Local\Programs\Python\Python310\lib\ssl.py", line 512, in wrap_socket
    return self.sslsocket_class._create(
  File "C:\Users\Admin\AppData\Local\Programs\Python\Python310\lib\ssl.py", line 1070, in _create
    self.do_handshake()
  File "C:\Users\Admin\AppData\Local\Programs\Python\Python310\lib\ssl.py", line 1341, in do_handshake
    self._sslobj.do_handshake()
FileNotFoundError: [Errno 2] No such file or directory
ERROR 2023-08-04 11:50:01,413 basehttp "POST /accounts/register/ HTTP/1.1" 500 153611
WARNING 2023-08-04 14:39:46,307 log Method Not Allowed: /activate/MTk/bsewpm-13ceaae1356fd1a414aea5bebd32e2d8/
WARNING 2023-08-04 14:39:46,334 basehttp "GET /activate/MTk/bsewpm-13ceaae1356fd1a414aea5bebd32e2d8/ HTTP/1.1" 405 5830
ERROR 2023-08-04 14:40:14,344 log Internal Server Error: /activate/MTk/bsewpm-13ceaae1356fd1a414aea5bebd32e2d8/
Traceback (most recent call last):
  File "D:\python files\Project tasks\customizeUserModel\venv\lib\site-packages\django\core\handlers\exception.py", line 55, in inner
    response = get_response(request)
  File "D:\python files\Project tasks\customizeUserModel\venv\lib\site-packages\django\core\handlers\base.py", line 197, in _get_response
    response = wrapped_callback(request, *callback_args, **callback_kwargs)
  File "D:\python files\Project tasks\customizeUserModel\venv\lib\site-packages\django\views\decorators\csrf.py", line 56, in wrapper_view
    return view_func(*args, **kwargs)
  File "D:\python files\Project tasks\customizeUserModel\venv\lib\site-packages\django\views\generic\base.py", line 104, in view
    return self.dispatch(request, *args, **kwargs)
  File "D:\python files\Project tasks\customizeUserModel\venv\lib\site-packages\rest_framework\views.py", line 509, in dispatch
    response = self.handle_exception(exc)
  File "D:\python files\Project tasks\customizeUserModel\venv\lib\site-packages\rest_framework\views.py", line 469, in handle_exception
    self.raise_uncaught_exception(exc)
  File "D:\python files\Project tasks\customizeUserModel\venv\lib\site-packages\rest_framework\views.py", line 480, in raise_uncaught_exception
    raise exc
  File "D:\python files\Project tasks\customizeUserModel\venv\lib\site-packages\rest_framework\views.py", line 506, in dispatch
    response = handler(request, *args, **kwargs)
  File "D:\python files\Project tasks\customizeUserModel\projectDept\accounts\views.py", line 48, in post
    if default_token_generator.check_token(user, token):
UnboundLocalError: local variable 'user' referenced before assignment
ERROR 2023-08-04 14:40:14,357 basehttp "POST /activate/MTk/bsewpm-13ceaae1356fd1a414aea5bebd32e2d8/ HTTP/1.1" 500 103587
WARNING 2023-08-04 14:42:10,764 log Method Not Allowed: /activate/MTk/bsewpm-13ceaae1356fd1a414aea5bebd32e2d8/
WARNING 2023-08-04 14:42:10,765 basehttp "GET /activate/MTk/bsewpm-13ceaae1356fd1a414aea5bebd32e2d8/ HTTP/1.1" 405 5830
ERROR 2023-08-04 14:44:16,332 log Internal Server Error: /activate/MTk/bsewpm-13ceaae1356fd1a414aea5bebd32e2d8/
Traceback (most recent call last):
  File "D:\python files\Project tasks\customizeUserModel\venv\lib\site-packages\django\core\handlers\exception.py", line 55, in inner
    response = get_response(request)
  File "D:\python files\Project tasks\customizeUserModel\venv\lib\site-packages\django\core\handlers\base.py", line 197, in _get_response
    response = wrapped_callback(request, *callback_args, **callback_kwargs)
  File "D:\python files\Project tasks\customizeUserModel\venv\lib\site-packages\django\views\decorators\csrf.py", line 56, in wrapper_view
    return view_func(*args, **kwargs)
  File "D:\python files\Project tasks\customizeUserModel\venv\lib\site-packages\django\views\generic\base.py", line 104, in view
    return self.dispatch(request, *args, **kwargs)
  File "D:\python files\Project tasks\customizeUserModel\venv\lib\site-packages\rest_framework\views.py", line 509, in dispatch
    response = self.handle_exception(exc)
  File "D:\python files\Project tasks\customizeUserModel\venv\lib\site-packages\rest_framework\views.py", line 469, in handle_exception
    self.raise_uncaught_exception(exc)
  File "D:\python files\Project tasks\customizeUserModel\venv\lib\site-packages\rest_framework\views.py", line 480, in raise_uncaught_exception
    raise exc
  File "D:\python files\Project tasks\customizeUserModel\venv\lib\site-packages\rest_framework\views.py", line 506, in dispatch
    response = handler(request, *args, **kwargs)
  File "D:\python files\Project tasks\customizeUserModel\projectDept\accounts\views.py", line 48, in post
    if user is not None and default_token_generator.check_token(user, token):
UnboundLocalError: local variable 'user' referenced before assignment
ERROR 2023-08-04 14:44:16,335 basehttp "POST /activate/MTk/bsewpm-13ceaae1356fd1a414aea5bebd32e2d8/ HTTP/1.1" 500 103629
WARNING 2023-08-04 15:08:48,058 log Method Not Allowed: /activate/MTk/bsewpm-13ceaae1356fd1a414aea5bebd32e2d8/
WARNING 2023-08-04 15:08:48,059 basehttp "GET /activate/MTk/bsewpm-13ceaae1356fd1a414aea5bebd32e2d8/ HTTP/1.1" 405 5830
ERROR 2023-08-04 15:08:58,480 log Internal Server Error: /activate/MTk/bsewpm-13ceaae1356fd1a414aea5bebd32e2d8/
Traceback (most recent call last):
  File "D:\python files\Project tasks\customizeUserModel\venv\lib\site-packages\django\core\handlers\exception.py", line 55, in inner
    response = get_response(request)
  File "D:\python files\Project tasks\customizeUserModel\venv\lib\site-packages\django\core\handlers\base.py", line 197, in _get_response
    response = wrapped_callback(request, *callback_args, **callback_kwargs)
  File "D:\python files\Project tasks\customizeUserModel\venv\lib\site-packages\django\views\decorators\csrf.py", line 56, in wrapper_view
    return view_func(*args, **kwargs)
  File "D:\python files\Project tasks\customizeUserModel\venv\lib\site-packages\django\views\generic\base.py", line 104, in view
    return self.dispatch(request, *args, **kwargs)
  File "D:\python files\Project tasks\customizeUserModel\venv\lib\site-packages\rest_framework\views.py", line 509, in dispatch
    response = self.handle_exception(exc)
  File "D:\python files\Project tasks\customizeUserModel\venv\lib\site-packages\rest_framework\views.py", line 469, in handle_exception
    self.raise_uncaught_exception(exc)
  File "D:\python files\Project tasks\customizeUserModel\venv\lib\site-packages\rest_framework\views.py", line 480, in raise_uncaught_exception
    raise exc
  File "D:\python files\Project tasks\customizeUserModel\venv\lib\site-packages\rest_framework\views.py", line 506, in dispatch
    response = handler(request, *args, **kwargs)
TypeError: Account_activation_API.post() got an unexpected keyword argument 'uidb64'
ERROR 2023-08-04 15:08:58,483 basehttp "POST /activate/MTk/bsewpm-13ceaae1356fd1a414aea5bebd32e2d8/ HTTP/1.1" 500 99344
WARNING 2023-08-04 15:10:00,484 log Method Not Allowed: /activate/MTk/bsewpm-13ceaae1356fd1a414aea5bebd32e2d8/
WARNING 2023-08-04 15:10:00,485 basehttp "GET /activate/MTk/bsewpm-13ceaae1356fd1a414aea5bebd32e2d8/ HTTP/1.1" 405 5830
ERROR 2023-08-04 15:10:04,838 log Internal Server Error: /activate/MTk/bsewpm-13ceaae1356fd1a414aea5bebd32e2d8/
Traceback (most recent call last):
  File "D:\python files\Project tasks\customizeUserModel\venv\lib\site-packages\django\core\handlers\exception.py", line 55, in inner
    response = get_response(request)
  File "D:\python files\Project tasks\customizeUserModel\venv\lib\site-packages\django\core\handlers\base.py", line 197, in _get_response
    response = wrapped_callback(request, *callback_args, **callback_kwargs)
  File "D:\python files\Project tasks\customizeUserModel\venv\lib\site-packages\django\views\decorators\csrf.py", line 56, in wrapper_view
    return view_func(*args, **kwargs)
  File "D:\python files\Project tasks\customizeUserModel\venv\lib\site-packages\django\views\generic\base.py", line 104, in view
    return self.dispatch(request, *args, **kwargs)
  File "D:\python files\Project tasks\customizeUserModel\venv\lib\site-packages\rest_framework\views.py", line 509, in dispatch
    response = self.handle_exception(exc)
  File "D:\python files\Project tasks\customizeUserModel\venv\lib\site-packages\rest_framework\views.py", line 469, in handle_exception
    self.raise_uncaught_exception(exc)
  File "D:\python files\Project tasks\customizeUserModel\venv\lib\site-packages\rest_framework\views.py", line 480, in raise_uncaught_exception
    raise exc
  File "D:\python files\Project tasks\customizeUserModel\venv\lib\site-packages\rest_framework\views.py", line 506, in dispatch
    response = handler(request, *args, **kwargs)
TypeError: Account_activation_API.post() got an unexpected keyword argument 'uidb64'
ERROR 2023-08-04 15:10:04,841 basehttp "POST /activate/MTk/bsewpm-13ceaae1356fd1a414aea5bebd32e2d8/ HTTP/1.1" 500 99344
WARNING 2023-08-04 15:10:46,787 log Method Not Allowed: /activate/MTk/bsewpm-13ceaae1356fd1a414aea5bebd32e2d8/
WARNING 2023-08-04 15:10:46,788 basehttp "GET /activate/MTk/bsewpm-13ceaae1356fd1a414aea5bebd32e2d8/ HTTP/1.1" 405 5830
ERROR 2023-08-04 15:10:49,387 log Internal Server Error: /activate/MTk/bsewpm-13ceaae1356fd1a414aea5bebd32e2d8/
Traceback (most recent call last):
  File "D:\python files\Project tasks\customizeUserModel\venv\lib\site-packages\django\core\handlers\exception.py", line 55, in inner
    response = get_response(request)
  File "D:\python files\Project tasks\customizeUserModel\venv\lib\site-packages\django\core\handlers\base.py", line 197, in _get_response
    response = wrapped_callback(request, *callback_args, **callback_kwargs)
  File "D:\python files\Project tasks\customizeUserModel\venv\lib\site-packages\django\views\decorators\csrf.py", line 56, in wrapper_view
    return view_func(*args, **kwargs)
  File "D:\python files\Project tasks\customizeUserModel\venv\lib\site-packages\django\views\generic\base.py", line 104, in view
    return self.dispatch(request, *args, **kwargs)
  File "D:\python files\Project tasks\customizeUserModel\venv\lib\site-packages\rest_framework\views.py", line 509, in dispatch
    response = self.handle_exception(exc)
  File "D:\python files\Project tasks\customizeUserModel\venv\lib\site-packages\rest_framework\views.py", line 469, in handle_exception
    self.raise_uncaught_exception(exc)
  File "D:\python files\Project tasks\customizeUserModel\venv\lib\site-packages\rest_framework\views.py", line 480, in raise_uncaught_exception
    raise exc
  File "D:\python files\Project tasks\customizeUserModel\venv\lib\site-packages\rest_framework\views.py", line 506, in dispatch
    response = handler(request, *args, **kwargs)
TypeError: Account_activation_API.post() got an unexpected keyword argument 'uid'
ERROR 2023-08-04 15:10:49,390 basehttp "POST /activate/MTk/bsewpm-13ceaae1356fd1a414aea5bebd32e2d8/ HTTP/1.1" 500 99296
WARNING 2023-08-04 15:13:31,757 log Method Not Allowed: /activate/MjA/bsey9r-278f83ab5ec3c87c08fbe866c362817b/
WARNING 2023-08-04 15:13:31,759 basehttp "GET /activate/MjA/bsey9r-278f83ab5ec3c87c08fbe866c362817b/ HTTP/1.1" 405 5830
ERROR 2023-08-04 15:13:40,133 log Internal Server Error: /activate/MjA/bsey9r-278f83ab5ec3c87c08fbe866c362817b/
Traceback (most recent call last):
  File "D:\python files\Project tasks\customizeUserModel\venv\lib\site-packages\django\core\handlers\exception.py", line 55, in inner
    response = get_response(request)
  File "D:\python files\Project tasks\customizeUserModel\venv\lib\site-packages\django\core\handlers\base.py", line 197, in _get_response
    response = wrapped_callback(request, *callback_args, **callback_kwargs)
  File "D:\python files\Project tasks\customizeUserModel\venv\lib\site-packages\django\views\decorators\csrf.py", line 56, in wrapper_view
    return view_func(*args, **kwargs)
  File "D:\python files\Project tasks\customizeUserModel\venv\lib\site-packages\django\views\generic\base.py", line 104, in view
    return self.dispatch(request, *args, **kwargs)
  File "D:\python files\Project tasks\customizeUserModel\venv\lib\site-packages\rest_framework\views.py", line 509, in dispatch
    response = self.handle_exception(exc)
  File "D:\python files\Project tasks\customizeUserModel\venv\lib\site-packages\rest_framework\views.py", line 469, in handle_exception
    self.raise_uncaught_exception(exc)
  File "D:\python files\Project tasks\customizeUserModel\venv\lib\site-packages\rest_framework\views.py", line 480, in raise_uncaught_exception
    raise exc
  File "D:\python files\Project tasks\customizeUserModel\venv\lib\site-packages\rest_framework\views.py", line 506, in dispatch
    response = handler(request, *args, **kwargs)
TypeError: Account_activation_API.post() got an unexpected keyword argument 'uid'
ERROR 2023-08-04 15:13:40,136 basehttp "POST /activate/MjA/bsey9r-278f83ab5ec3c87c08fbe866c362817b/ HTTP/1.1" 500 99296
WARNING 2023-08-04 15:17:40,582 log Method Not Allowed: /activate/MjA/bsey9r-278f83ab5ec3c87c08fbe866c362817b/
WARNING 2023-08-04 15:17:40,583 basehttp "GET /activate/MjA/bsey9r-278f83ab5ec3c87c08fbe866c362817b/ HTTP/1.1" 405 5830
ERROR 2023-08-04 15:17:43,104 log Internal Server Error: /activate/MjA/bsey9r-278f83ab5ec3c87c08fbe866c362817b/
Traceback (most recent call last):
  File "D:\python files\Project tasks\customizeUserModel\venv\lib\site-packages\django\core\handlers\exception.py", line 55, in inner
    response = get_response(request)
  File "D:\python files\Project tasks\customizeUserModel\venv\lib\site-packages\django\core\handlers\base.py", line 197, in _get_response
    response = wrapped_callback(request, *callback_args, **callback_kwargs)
  File "D:\python files\Project tasks\customizeUserModel\venv\lib\site-packages\django\views\decorators\csrf.py", line 56, in wrapper_view
    return view_func(*args, **kwargs)
  File "D:\python files\Project tasks\customizeUserModel\venv\lib\site-packages\django\views\generic\base.py", line 104, in view
    return self.dispatch(request, *args, **kwargs)
  File "D:\python files\Project tasks\customizeUserModel\venv\lib\site-packages\rest_framework\views.py", line 509, in dispatch
    response = self.handle_exception(exc)
  File "D:\python files\Project tasks\customizeUserModel\venv\lib\site-packages\rest_framework\views.py", line 469, in handle_exception
    self.raise_uncaught_exception(exc)
  File "D:\python files\Project tasks\customizeUserModel\venv\lib\site-packages\rest_framework\views.py", line 480, in raise_uncaught_exception
    raise exc
  File "D:\python files\Project tasks\customizeUserModel\venv\lib\site-packages\rest_framework\views.py", line 506, in dispatch
    response = handler(request, *args, **kwargs)
TypeError: Account_activation_API.post() got an unexpected keyword argument 'uid'
ERROR 2023-08-04 15:17:43,107 basehttp "POST /activate/MjA/bsey9r-278f83ab5ec3c87c08fbe866c362817b/ HTTP/1.1" 500 99296
WARNING 2023-08-04 15:19:49,398 log Method Not Allowed: /activate/MjA/bsey9r-278f83ab5ec3c87c08fbe866c362817b/
WARNING 2023-08-04 15:19:49,399 basehttp "GET /activate/MjA/bsey9r-278f83ab5ec3c87c08fbe866c362817b/ HTTP/1.1" 405 5830
WARNING 2023-08-04 15:19:51,363 log Bad Request: /activate/MjA/bsey9r-278f83ab5ec3c87c08fbe866c362817b/
WARNING 2023-08-04 15:19:51,365 basehttp "POST /activate/MjA/bsey9r-278f83ab5ec3c87c08fbe866c362817b/ HTTP/1.1" 400 5811
WARNING 2023-08-04 15:19:56,932 log Bad Request: /activate/MjA/bsey9r-278f83ab5ec3c87c08fbe866c362817b/
WARNING 2023-08-04 15:19:56,933 basehttp "POST /activate/MjA/bsey9r-278f83ab5ec3c87c08fbe866c362817b/ HTTP/1.1" 400 5811
WARNING 2023-08-04 15:21:30,994 log Method Not Allowed: /activate/MjE/bseyne-b461c62815823dec88f88cdf08dc8818/
WARNING 2023-08-04 15:21:30,995 basehttp "GET /activate/MjE/bseyne-b461c62815823dec88f88cdf08dc8818/ HTTP/1.1" 405 5830
WARNING 2023-08-04 15:21:33,519 log Bad Request: /activate/MjE/bseyne-b461c62815823dec88f88cdf08dc8818/
WARNING 2023-08-04 15:21:33,520 basehttp "POST /activate/MjE/bseyne-b461c62815823dec88f88cdf08dc8818/ HTTP/1.1" 400 5811
WARNING 2023-08-04 15:23:43,570 log Method Not Allowed: /activate/MjI/bseyr3-2fd1e4b7853aed4f18ef199abb92be21/
WARNING 2023-08-04 15:23:43,571 basehttp "GET /activate/MjI/bseyr3-2fd1e4b7853aed4f18ef199abb92be21/ HTTP/1.1" 405 5830
WARNING 2023-08-04 16:00:42,086 log Method Not Allowed: /activate/MjM/bsf0gh-2fef4e86ed1a45cb2143e402298bc0f1/
WARNING 2023-08-04 16:00:42,205 basehttp "GET /activate/MjM/bsf0gh-2fef4e86ed1a45cb2143e402298bc0f1/ HTTP/1.1" 405 5830
WARNING 2023-08-04 16:26:05,111 log Bad Request: /activate/MjM/bsf0gh-2fef4e86ed1a45cb2143e402298bc0f1/
WARNING 2023-08-04 16:26:05,112 basehttp "GET /activate/MjM/bsf0gh-2fef4e86ed1a45cb2143e402298bc0f1/ HTTP/1.1" 400 5578
WARNING 2023-08-04 22:09:06,908 log Unauthorized: /access/
WARNING 2023-08-04 22:09:06,939 basehttp "POST /access/ HTTP/1.1" 401 63
WARNING 2023-08-04 22:17:02,614 log Unauthorized: /access/
WARNING 2023-08-04 22:17:02,615 basehttp "POST /access/ HTTP/1.1" 401 63
WARNING 2023-08-05 11:04:41,347 log Not Found: /favicon.ico
WARNING 2023-08-05 11:04:41,380 basehttp "GET /favicon.ico HTTP/1.1" 404 2852
WARNING 2023-08-05 11:06:11,022 log Unauthorized: /access/
WARNING 2023-08-05 11:06:11,023 basehttp "POST /access/ HTTP/1.1" 401 63
WARNING 2023-08-05 11:39:01,074 log Unauthorized: /access/
WARNING 2023-08-05 11:39:01,076 basehttp "POST /access/ HTTP/1.1" 401 63
WARNING 2023-08-05 11:42:11,071 log Unauthorized: /access/
WARNING 2023-08-05 11:42:11,072 basehttp "POST /access/ HTTP/1.1" 401 63
WARNING 2023-08-05 11:43:56,139 log Unauthorized: /access/
WARNING 2023-08-05 11:43:56,139 basehttp "POST /access/ HTTP/1.1" 401 63
WARNING 2023-08-05 11:46:36,222 log Unauthorized: /access/
WARNING 2023-08-05 11:46:36,223 basehttp "POST /access/ HTTP/1.1" 401 63
WARNING 2023-08-05 11:59:37,103 log Unauthorized: /access/
WARNING 2023-08-05 11:59:37,104 basehttp "POST /access/ HTTP/1.1" 401 63
WARNING 2023-08-05 12:00:16,934 log Unauthorized: /access/
WARNING 2023-08-05 12:00:16,935 basehttp "POST /access/ HTTP/1.1" 401 63
WARNING 2023-08-05 12:01:29,333 log Unauthorized: /access/
WARNING 2023-08-05 12:01:29,334 basehttp "POST /access/ HTTP/1.1" 401 63
WARNING 2023-08-05 12:18:51,761 log Unauthorized: /access/
WARNING 2023-08-05 12:18:51,762 basehttp "POST /access/ HTTP/1.1" 401 63
WARNING 2023-08-05 12:24:04,620 log Unauthorized: /access/
WARNING 2023-08-05 12:24:04,621 basehttp "POST /access/ HTTP/1.1" 401 63
WARNING 2023-08-05 12:25:35,343 log Unauthorized: /access/
WARNING 2023-08-05 12:25:35,344 basehttp "POST /access/ HTTP/1.1" 401 63
WARNING 2023-08-05 12:27:21,606 log Unauthorized: /access/
WARNING 2023-08-05 12:27:21,607 basehttp "POST /access/ HTTP/1.1" 401 63
WARNING 2023-08-05 13:10:11,421 log Unauthorized: /access/
WARNING 2023-08-05 13:10:11,452 basehttp "POST /access/ HTTP/1.1" 401 63
WARNING 2023-08-05 13:17:48,710 log Unauthorized: /access/
WARNING 2023-08-05 13:17:48,711 basehttp "POST /access/ HTTP/1.1" 401 63
WARNING 2023-08-05 13:19:47,754 log Unauthorized: /access/
WARNING 2023-08-05 13:19:47,756 basehttp "POST /access/ HTTP/1.1" 401 63
WARNING 2023-08-05 13:21:04,083 log Unauthorized: /access/
WARNING 2023-08-05 13:21:04,084 basehttp "POST /access/ HTTP/1.1" 401 63
WARNING 2023-08-05 13:22:03,753 log Unauthorized: /access/
WARNING 2023-08-05 13:22:03,754 basehttp "POST /access/ HTTP/1.1" 401 63
WARNING 2023-08-05 13:22:29,414 log Unauthorized: /access/
WARNING 2023-08-05 13:22:29,415 basehttp "POST /access/ HTTP/1.1" 401 63
WARNING 2023-08-05 13:23:26,673 log Unauthorized: /access/
WARNING 2023-08-05 13:23:26,674 basehttp "POST /access/ HTTP/1.1" 401 63
WARNING 2023-08-05 13:29:07,488 log Unauthorized: /access/
WARNING 2023-08-05 13:29:07,489 basehttp "POST /access/ HTTP/1.1" 401 63
WARNING 2023-08-05 13:34:37,107 log Unauthorized: /access/
WARNING 2023-08-05 13:34:37,108 basehttp "POST /access/ HTTP/1.1" 401 63
WARNING 2023-08-05 13:35:22,727 log Unauthorized: /access/
WARNING 2023-08-05 13:35:22,728 basehttp "POST /access/ HTTP/1.1" 401 63
WARNING 2023-08-05 13:36:34,960 log Unauthorized: /access/
WARNING 2023-08-05 13:36:34,961 basehttp "POST /access/ HTTP/1.1" 401 63
WARNING 2023-08-05 13:38:12,310 log Unauthorized: /access/
WARNING 2023-08-05 13:38:12,312 basehttp "POST /access/ HTTP/1.1" 401 63
WARNING 2023-08-05 13:38:45,658 log Unauthorized: /access/
WARNING 2023-08-05 13:38:45,659 basehttp "POST /access/ HTTP/1.1" 401 63
WARNING 2023-08-05 13:39:25,647 log Unauthorized: /access/
WARNING 2023-08-05 13:39:25,647 basehttp "POST /access/ HTTP/1.1" 401 63
WARNING 2023-08-05 13:48:44,169 log Unauthorized: /access/
WARNING 2023-08-05 13:48:44,170 basehttp "POST /access/ HTTP/1.1" 401 63
WARNING 2023-08-05 13:49:53,172 log Unauthorized: /access/
WARNING 2023-08-05 13:49:53,173 basehttp "POST /access/ HTTP/1.1" 401 63
WARNING 2023-08-05 13:53:37,421 log Unauthorized: /access/
WARNING 2023-08-05 13:53:37,422 basehttp "POST /access/ HTTP/1.1" 401 63
WARNING 2023-08-05 13:54:05,628 log Unauthorized: /access/
WARNING 2023-08-05 13:54:05,630 basehttp "POST /access/ HTTP/1.1" 401 63
WARNING 2023-08-05 13:55:07,535 log Unauthorized: /access/
WARNING 2023-08-05 13:55:07,536 basehttp "POST /access/ HTTP/1.1" 401 63
WARNING 2023-08-05 15:44:39,470 log Unauthorized: /access/
WARNING 2023-08-05 15:44:39,509 basehttp "POST /access/ HTTP/1.1" 401 63
WARNING 2023-08-05 16:33:40,611 log Unauthorized: /access/
WARNING 2023-08-05 16:33:40,661 basehttp "POST /access/ HTTP/1.1" 401 63
WARNING 2023-08-05 16:33:45,737 log Unauthorized: /access/
WARNING 2023-08-05 16:33:45,738 basehttp "POST /access/ HTTP/1.1" 401 63
WARNING 2023-08-05 16:34:36,773 log Unauthorized: /access/
WARNING 2023-08-05 16:34:36,774 basehttp "POST /access/ HTTP/1.1" 401 63
WARNING 2023-08-05 16:35:40,262 log Unauthorized: /access/
WARNING 2023-08-05 16:35:40,263 basehttp "POST /access/ HTTP/1.1" 401 63
WARNING 2023-08-05 16:35:41,623 log Unauthorized: /access/
WARNING 2023-08-05 16:35:41,624 basehttp "POST /access/ HTTP/1.1" 401 63
WARNING 2023-08-05 16:44:53,145 log Unauthorized: /access/
WARNING 2023-08-05 16:44:53,146 basehttp "POST /access/ HTTP/1.1" 401 63
WARNING 2023-08-05 16:46:23,345 log Unauthorized: /access/
WARNING 2023-08-05 16:46:23,346 basehttp "POST /access/ HTTP/1.1" 401 63
WARNING 2023-08-05 16:47:24,291 log Unauthorized: /access/
WARNING 2023-08-05 16:47:24,292 basehttp "POST /access/ HTTP/1.1" 401 63
WARNING 2023-08-05 16:49:39,186 log Unauthorized: /access/
WARNING 2023-08-05 16:49:39,187 basehttp "POST /access/ HTTP/1.1" 401 63
WARNING 2023-08-05 16:50:08,641 log Unauthorized: /access/
WARNING 2023-08-05 16:50:08,642 basehttp "POST /access/ HTTP/1.1" 401 63
WARNING 2023-08-05 16:53:04,383 log Bad Request: /activate/MjY/bsghhe-6a89f2723592b4fe6c9e06d552b51947/
WARNING 2023-08-05 16:53:04,384 basehttp "GET /activate/MjY/bsghhe-6a89f2723592b4fe6c9e06d552b51947/ HTTP/1.1" 400 5633
ERROR 2023-08-05 17:07:58,889 log Internal Server Error: /activate/<str:uid>/<str:token>/
Traceback (most recent call last):
  File "D:\python files\Project tasks\customizeUserModel\venv\lib\site-packages\django\utils\http.py", line 206, in urlsafe_base64_decode
    return base64.urlsafe_b64decode(s.ljust(len(s) + len(s) % 4, b"="))
  File "C:\Users\Admin\AppData\Local\Programs\Python\Python310\lib\base64.py", line 133, in urlsafe_b64decode
    return b64decode(s)
  File "C:\Users\Admin\AppData\Local\Programs\Python\Python310\lib\base64.py", line 87, in b64decode
    return binascii.a2b_base64(s)
binascii.Error: Incorrect padding

During handling of the above exception, another exception occurred:

Traceback (most recent call last):
  File "D:\python files\Project tasks\customizeUserModel\venv\lib\site-packages\django\core\handlers\exception.py", line 55, in inner
    response = get_response(request)
  File "D:\python files\Project tasks\customizeUserModel\venv\lib\site-packages\django\core\handlers\base.py", line 197, in _get_response
    response = wrapped_callback(request, *callback_args, **callback_kwargs)
  File "D:\python files\Project tasks\customizeUserModel\venv\lib\site-packages\django\views\decorators\csrf.py", line 56, in wrapper_view
    return view_func(*args, **kwargs)
  File "D:\python files\Project tasks\customizeUserModel\venv\lib\site-packages\django\views\generic\base.py", line 104, in view
    return self.dispatch(request, *args, **kwargs)
  File "D:\python files\Project tasks\customizeUserModel\venv\lib\site-packages\rest_framework\views.py", line 509, in dispatch
    response = self.handle_exception(exc)
  File "D:\python files\Project tasks\customizeUserModel\venv\lib\site-packages\rest_framework\views.py", line 469, in handle_exception
    self.raise_uncaught_exception(exc)
  File "D:\python files\Project tasks\customizeUserModel\venv\lib\site-packages\rest_framework\views.py", line 480, in raise_uncaught_exception
    raise exc
  File "D:\python files\Project tasks\customizeUserModel\venv\lib\site-packages\rest_framework\views.py", line 506, in dispatch
    response = handler(request, *args, **kwargs)
  File "D:\python files\Project tasks\customizeUserModel\projectDept\accounts\views.py", line 39, in get
    uid = force_bytes(urlsafe_base64_decode(uid))
  File "D:\python files\Project tasks\customizeUserModel\venv\lib\site-packages\django\utils\http.py", line 208, in urlsafe_base64_decode
    raise ValueError(e)
ValueError: Incorrect padding
ERROR 2023-08-05 17:07:58,926 basehttp "GET /activate/%3Cstr:uid%3E/%3Cstr:token%3E/ HTTP/1.1" 500 116683
ERROR 2023-08-05 17:07:58,953 log Internal Server Error: /activate/<str:uid>/<str:token>/
Traceback (most recent call last):
  File "D:\python files\Project tasks\customizeUserModel\venv\lib\site-packages\django\utils\http.py", line 206, in urlsafe_base64_decode
    return base64.urlsafe_b64decode(s.ljust(len(s) + len(s) % 4, b"="))
  File "C:\Users\Admin\AppData\Local\Programs\Python\Python310\lib\base64.py", line 133, in urlsafe_b64decode
    return b64decode(s)
  File "C:\Users\Admin\AppData\Local\Programs\Python\Python310\lib\base64.py", line 87, in b64decode
    return binascii.a2b_base64(s)
binascii.Error: Incorrect padding

During handling of the above exception, another exception occurred:

Traceback (most recent call last):
  File "D:\python files\Project tasks\customizeUserModel\venv\lib\site-packages\django\core\handlers\exception.py", line 55, in inner
    response = get_response(request)
  File "D:\python files\Project tasks\customizeUserModel\venv\lib\site-packages\django\core\handlers\base.py", line 197, in _get_response
    response = wrapped_callback(request, *callback_args, **callback_kwargs)
  File "D:\python files\Project tasks\customizeUserModel\venv\lib\site-packages\django\views\decorators\csrf.py", line 56, in wrapper_view
    return view_func(*args, **kwargs)
  File "D:\python files\Project tasks\customizeUserModel\venv\lib\site-packages\django\views\generic\base.py", line 104, in view
    return self.dispatch(request, *args, **kwargs)
  File "D:\python files\Project tasks\customizeUserModel\venv\lib\site-packages\rest_framework\views.py", line 509, in dispatch
    response = self.handle_exception(exc)
  File "D:\python files\Project tasks\customizeUserModel\venv\lib\site-packages\rest_framework\views.py", line 469, in handle_exception
    self.raise_uncaught_exception(exc)
  File "D:\python files\Project tasks\customizeUserModel\venv\lib\site-packages\rest_framework\views.py", line 480, in raise_uncaught_exception
    raise exc
  File "D:\python files\Project tasks\customizeUserModel\venv\lib\site-packages\rest_framework\views.py", line 506, in dispatch
    response = handler(request, *args, **kwargs)
  File "D:\python files\Project tasks\customizeUserModel\projectDept\accounts\views.py", line 39, in get
    uid = force_bytes(urlsafe_base64_decode(uid))
  File "D:\python files\Project tasks\customizeUserModel\venv\lib\site-packages\django\utils\http.py", line 208, in urlsafe_base64_decode
    raise ValueError(e)
ValueError: Incorrect padding
ERROR 2023-08-05 17:07:58,958 basehttp "GET /activate/%3Cstr:uid%3E/%3Cstr:token%3E/ HTTP/1.1" 500 116683
ERROR 2023-08-05 17:07:58,986 log Internal Server Error: /activate/<str:uid>/<str:token>/
Traceback (most recent call last):
  File "D:\python files\Project tasks\customizeUserModel\venv\lib\site-packages\django\utils\http.py", line 206, in urlsafe_base64_decode
    return base64.urlsafe_b64decode(s.ljust(len(s) + len(s) % 4, b"="))
  File "C:\Users\Admin\AppData\Local\Programs\Python\Python310\lib\base64.py", line 133, in urlsafe_b64decode
    return b64decode(s)
  File "C:\Users\Admin\AppData\Local\Programs\Python\Python310\lib\base64.py", line 87, in b64decode
    return binascii.a2b_base64(s)
binascii.Error: Incorrect padding

During handling of the above exception, another exception occurred:

Traceback (most recent call last):
  File "D:\python files\Project tasks\customizeUserModel\venv\lib\site-packages\django\core\handlers\exception.py", line 55, in inner
    response = get_response(request)
  File "D:\python files\Project tasks\customizeUserModel\venv\lib\site-packages\django\core\handlers\base.py", line 197, in _get_response
    response = wrapped_callback(request, *callback_args, **callback_kwargs)
  File "D:\python files\Project tasks\customizeUserModel\venv\lib\site-packages\django\views\decorators\csrf.py", line 56, in wrapper_view
    return view_func(*args, **kwargs)
  File "D:\python files\Project tasks\customizeUserModel\venv\lib\site-packages\django\views\generic\base.py", line 104, in view
    return self.dispatch(request, *args, **kwargs)
  File "D:\python files\Project tasks\customizeUserModel\venv\lib\site-packages\rest_framework\views.py", line 509, in dispatch
    response = self.handle_exception(exc)
  File "D:\python files\Project tasks\customizeUserModel\venv\lib\site-packages\rest_framework\views.py", line 469, in handle_exception
    self.raise_uncaught_exception(exc)
  File "D:\python files\Project tasks\customizeUserModel\venv\lib\site-packages\rest_framework\views.py", line 480, in raise_uncaught_exception
    raise exc
  File "D:\python files\Project tasks\customizeUserModel\venv\lib\site-packages\rest_framework\views.py", line 506, in dispatch
    response = handler(request, *args, **kwargs)
  File "D:\python files\Project tasks\customizeUserModel\projectDept\accounts\views.py", line 39, in get
    uid = force_bytes(urlsafe_base64_decode(uid))
  File "D:\python files\Project tasks\customizeUserModel\venv\lib\site-packages\django\utils\http.py", line 208, in urlsafe_base64_decode
    raise ValueError(e)
ValueError: Incorrect padding
ERROR 2023-08-05 17:07:58,990 basehttp "GET /activate/%3Cstr:uid%3E/%3Cstr:token%3E/ HTTP/1.1" 500 116683
ERROR 2023-08-05 17:08:13,498 log Internal Server Error: /activate/<str:uid>/<str:token>/
Traceback (most recent call last):
  File "D:\python files\Project tasks\customizeUserModel\venv\lib\site-packages\django\utils\http.py", line 206, in urlsafe_base64_decode
    return base64.urlsafe_b64decode(s.ljust(len(s) + len(s) % 4, b"="))
  File "C:\Users\Admin\AppData\Local\Programs\Python\Python310\lib\base64.py", line 133, in urlsafe_b64decode
    return b64decode(s)
  File "C:\Users\Admin\AppData\Local\Programs\Python\Python310\lib\base64.py", line 87, in b64decode
    return binascii.a2b_base64(s)
binascii.Error: Incorrect padding

During handling of the above exception, another exception occurred:

Traceback (most recent call last):
  File "D:\python files\Project tasks\customizeUserModel\venv\lib\site-packages\django\core\handlers\exception.py", line 55, in inner
    response = get_response(request)
  File "D:\python files\Project tasks\customizeUserModel\venv\lib\site-packages\django\core\handlers\base.py", line 197, in _get_response
    response = wrapped_callback(request, *callback_args, **callback_kwargs)
  File "D:\python files\Project tasks\customizeUserModel\venv\lib\site-packages\django\views\decorators\csrf.py", line 56, in wrapper_view
    return view_func(*args, **kwargs)
  File "D:\python files\Project tasks\customizeUserModel\venv\lib\site-packages\django\views\generic\base.py", line 104, in view
    return self.dispatch(request, *args, **kwargs)
  File "D:\python files\Project tasks\customizeUserModel\venv\lib\site-packages\rest_framework\views.py", line 509, in dispatch
    response = self.handle_exception(exc)
  File "D:\python files\Project tasks\customizeUserModel\venv\lib\site-packages\rest_framework\views.py", line 469, in handle_exception
    self.raise_uncaught_exception(exc)
  File "D:\python files\Project tasks\customizeUserModel\venv\lib\site-packages\rest_framework\views.py", line 480, in raise_uncaught_exception
    raise exc
  File "D:\python files\Project tasks\customizeUserModel\venv\lib\site-packages\rest_framework\views.py", line 506, in dispatch
    response = handler(request, *args, **kwargs)
  File "D:\python files\Project tasks\customizeUserModel\projectDept\accounts\views.py", line 39, in get
    uid = force_bytes(urlsafe_base64_decode(uid))
  File "D:\python files\Project tasks\customizeUserModel\venv\lib\site-packages\django\utils\http.py", line 208, in urlsafe_base64_decode
    raise ValueError(e)
ValueError: Incorrect padding
ERROR 2023-08-05 17:08:13,505 basehttp "GET /activate/%3Cstr:uid%3E/%3Cstr:token%3E/ HTTP/1.1" 500 116683
ERROR 2023-08-05 17:10:30,527 log Internal Server Error: /activate/<str:uid>/<str:token>/
Traceback (most recent call last):
  File "D:\python files\Project tasks\customizeUserModel\venv\lib\site-packages\django\utils\http.py", line 206, in urlsafe_base64_decode
    return base64.urlsafe_b64decode(s.ljust(len(s) + len(s) % 4, b"="))
  File "C:\Users\Admin\AppData\Local\Programs\Python\Python310\lib\base64.py", line 133, in urlsafe_b64decode
    return b64decode(s)
  File "C:\Users\Admin\AppData\Local\Programs\Python\Python310\lib\base64.py", line 87, in b64decode
    return binascii.a2b_base64(s)
binascii.Error: Incorrect padding

During handling of the above exception, another exception occurred:

Traceback (most recent call last):
  File "D:\python files\Project tasks\customizeUserModel\venv\lib\site-packages\django\core\handlers\exception.py", line 55, in inner
    response = get_response(request)
  File "D:\python files\Project tasks\customizeUserModel\venv\lib\site-packages\django\core\handlers\base.py", line 197, in _get_response
    response = wrapped_callback(request, *callback_args, **callback_kwargs)
  File "D:\python files\Project tasks\customizeUserModel\venv\lib\site-packages\django\views\decorators\csrf.py", line 56, in wrapper_view
    return view_func(*args, **kwargs)
  File "D:\python files\Project tasks\customizeUserModel\venv\lib\site-packages\django\views\generic\base.py", line 104, in view
    return self.dispatch(request, *args, **kwargs)
  File "D:\python files\Project tasks\customizeUserModel\venv\lib\site-packages\rest_framework\views.py", line 509, in dispatch
    response = self.handle_exception(exc)
  File "D:\python files\Project tasks\customizeUserModel\venv\lib\site-packages\rest_framework\views.py", line 469, in handle_exception
    self.raise_uncaught_exception(exc)
  File "D:\python files\Project tasks\customizeUserModel\venv\lib\site-packages\rest_framework\views.py", line 480, in raise_uncaught_exception
    raise exc
  File "D:\python files\Project tasks\customizeUserModel\venv\lib\site-packages\rest_framework\views.py", line 506, in dispatch
    response = handler(request, *args, **kwargs)
  File "D:\python files\Project tasks\customizeUserModel\projectDept\accounts\views.py", line 39, in get
    uid = force_bytes(urlsafe_base64_decode(uid))
  File "D:\python files\Project tasks\customizeUserModel\venv\lib\site-packages\django\utils\http.py", line 208, in urlsafe_base64_decode
    raise ValueError(e)
ValueError: Incorrect padding
ERROR 2023-08-05 17:10:30,535 basehttp "GET /activate/%3Cstr:uid%3E/%3Cstr:token%3E/ HTTP/1.1" 500 116683
ERROR 2023-08-05 17:13:06,518 log Internal Server Error: /activate/<str:uid>/<str:token>/
Traceback (most recent call last):
  File "D:\python files\Project tasks\customizeUserModel\venv\lib\site-packages\django\utils\http.py", line 206, in urlsafe_base64_decode
    return base64.urlsafe_b64decode(s.ljust(len(s) + len(s) % 4, b"="))
  File "C:\Users\Admin\AppData\Local\Programs\Python\Python310\lib\base64.py", line 133, in urlsafe_b64decode
    return b64decode(s)
  File "C:\Users\Admin\AppData\Local\Programs\Python\Python310\lib\base64.py", line 87, in b64decode
    return binascii.a2b_base64(s)
binascii.Error: Incorrect padding

During handling of the above exception, another exception occurred:

Traceback (most recent call last):
  File "D:\python files\Project tasks\customizeUserModel\venv\lib\site-packages\django\core\handlers\exception.py", line 55, in inner
    response = get_response(request)
  File "D:\python files\Project tasks\customizeUserModel\venv\lib\site-packages\django\core\handlers\base.py", line 197, in _get_response
    response = wrapped_callback(request, *callback_args, **callback_kwargs)
  File "D:\python files\Project tasks\customizeUserModel\venv\lib\site-packages\django\views\decorators\csrf.py", line 56, in wrapper_view
    return view_func(*args, **kwargs)
  File "D:\python files\Project tasks\customizeUserModel\venv\lib\site-packages\django\views\generic\base.py", line 104, in view
    return self.dispatch(request, *args, **kwargs)
  File "D:\python files\Project tasks\customizeUserModel\venv\lib\site-packages\rest_framework\views.py", line 509, in dispatch
    response = self.handle_exception(exc)
  File "D:\python files\Project tasks\customizeUserModel\venv\lib\site-packages\rest_framework\views.py", line 469, in handle_exception
    self.raise_uncaught_exception(exc)
  File "D:\python files\Project tasks\customizeUserModel\venv\lib\site-packages\rest_framework\views.py", line 480, in raise_uncaught_exception
    raise exc
  File "D:\python files\Project tasks\customizeUserModel\venv\lib\site-packages\rest_framework\views.py", line 506, in dispatch
    response = handler(request, *args, **kwargs)
  File "D:\python files\Project tasks\customizeUserModel\projectDept\accounts\views.py", line 39, in get
    uid = force_bytes(urlsafe_base64_decode(uid))
  File "D:\python files\Project tasks\customizeUserModel\venv\lib\site-packages\django\utils\http.py", line 208, in urlsafe_base64_decode
    raise ValueError(e)
ValueError: Incorrect padding
ERROR 2023-08-05 17:13:06,529 basehttp "GET /activate/%3Cstr:uid%3E/%3Cstr:token%3E/ HTTP/1.1" 500 116709
ERROR 2023-08-05 17:13:07,210 log Internal Server Error: /activate/<str:uid>/<str:token>/
Traceback (most recent call last):
  File "D:\python files\Project tasks\customizeUserModel\venv\lib\site-packages\django\utils\http.py", line 206, in urlsafe_base64_decode
    return base64.urlsafe_b64decode(s.ljust(len(s) + len(s) % 4, b"="))
  File "C:\Users\Admin\AppData\Local\Programs\Python\Python310\lib\base64.py", line 133, in urlsafe_b64decode
    return b64decode(s)
  File "C:\Users\Admin\AppData\Local\Programs\Python\Python310\lib\base64.py", line 87, in b64decode
    return binascii.a2b_base64(s)
binascii.Error: Incorrect padding

During handling of the above exception, another exception occurred:

Traceback (most recent call last):
  File "D:\python files\Project tasks\customizeUserModel\venv\lib\site-packages\django\core\handlers\exception.py", line 55, in inner
    response = get_response(request)
  File "D:\python files\Project tasks\customizeUserModel\venv\lib\site-packages\django\core\handlers\base.py", line 197, in _get_response
    response = wrapped_callback(request, *callback_args, **callback_kwargs)
  File "D:\python files\Project tasks\customizeUserModel\venv\lib\site-packages\django\views\decorators\csrf.py", line 56, in wrapper_view
    return view_func(*args, **kwargs)
  File "D:\python files\Project tasks\customizeUserModel\venv\lib\site-packages\django\views\generic\base.py", line 104, in view
    return self.dispatch(request, *args, **kwargs)
  File "D:\python files\Project tasks\customizeUserModel\venv\lib\site-packages\rest_framework\views.py", line 509, in dispatch
    response = self.handle_exception(exc)
  File "D:\python files\Project tasks\customizeUserModel\venv\lib\site-packages\rest_framework\views.py", line 469, in handle_exception
    self.raise_uncaught_exception(exc)
  File "D:\python files\Project tasks\customizeUserModel\venv\lib\site-packages\rest_framework\views.py", line 480, in raise_uncaught_exception
    raise exc
  File "D:\python files\Project tasks\customizeUserModel\venv\lib\site-packages\rest_framework\views.py", line 506, in dispatch
    response = handler(request, *args, **kwargs)
  File "D:\python files\Project tasks\customizeUserModel\projectDept\accounts\views.py", line 39, in get
    uid = force_bytes(urlsafe_base64_decode(uid))
  File "D:\python files\Project tasks\customizeUserModel\venv\lib\site-packages\django\utils\http.py", line 208, in urlsafe_base64_decode
    raise ValueError(e)
ValueError: Incorrect padding
ERROR 2023-08-05 17:13:07,214 basehttp "GET /activate/%3Cstr:uid%3E/%3Cstr:token%3E/ HTTP/1.1" 500 116709
ERROR 2023-08-05 17:13:11,200 log Internal Server Error: /activate/<str:uid>/<str:token>/
Traceback (most recent call last):
  File "D:\python files\Project tasks\customizeUserModel\venv\lib\site-packages\django\utils\http.py", line 206, in urlsafe_base64_decode
    return base64.urlsafe_b64decode(s.ljust(len(s) + len(s) % 4, b"="))
  File "C:\Users\Admin\AppData\Local\Programs\Python\Python310\lib\base64.py", line 133, in urlsafe_b64decode
    return b64decode(s)
  File "C:\Users\Admin\AppData\Local\Programs\Python\Python310\lib\base64.py", line 87, in b64decode
    return binascii.a2b_base64(s)
binascii.Error: Incorrect padding

During handling of the above exception, another exception occurred:

Traceback (most recent call last):
  File "D:\python files\Project tasks\customizeUserModel\venv\lib\site-packages\django\core\handlers\exception.py", line 55, in inner
    response = get_response(request)
  File "D:\python files\Project tasks\customizeUserModel\venv\lib\site-packages\django\core\handlers\base.py", line 197, in _get_response
    response = wrapped_callback(request, *callback_args, **callback_kwargs)
  File "D:\python files\Project tasks\customizeUserModel\venv\lib\site-packages\django\views\decorators\csrf.py", line 56, in wrapper_view
    return view_func(*args, **kwargs)
  File "D:\python files\Project tasks\customizeUserModel\venv\lib\site-packages\django\views\generic\base.py", line 104, in view
    return self.dispatch(request, *args, **kwargs)
  File "D:\python files\Project tasks\customizeUserModel\venv\lib\site-packages\rest_framework\views.py", line 509, in dispatch
    response = self.handle_exception(exc)
  File "D:\python files\Project tasks\customizeUserModel\venv\lib\site-packages\rest_framework\views.py", line 469, in handle_exception
    self.raise_uncaught_exception(exc)
  File "D:\python files\Project tasks\customizeUserModel\venv\lib\site-packages\rest_framework\views.py", line 480, in raise_uncaught_exception
    raise exc
  File "D:\python files\Project tasks\customizeUserModel\venv\lib\site-packages\rest_framework\views.py", line 506, in dispatch
    response = handler(request, *args, **kwargs)
  File "D:\python files\Project tasks\customizeUserModel\projectDept\accounts\views.py", line 39, in get
    uid = force_bytes(urlsafe_base64_decode(uid))
  File "D:\python files\Project tasks\customizeUserModel\venv\lib\site-packages\django\utils\http.py", line 208, in urlsafe_base64_decode
    raise ValueError(e)
ValueError: Incorrect padding
ERROR 2023-08-05 17:13:11,205 basehttp "GET /activate/%3Cstr:uid%3E/%3Cstr:token%3E/ HTTP/1.1" 500 116709
ERROR 2023-08-05 17:13:15,196 log Internal Server Error: /activate/<str:uid>/<str:token>/
Traceback (most recent call last):
  File "D:\python files\Project tasks\customizeUserModel\venv\lib\site-packages\django\utils\http.py", line 206, in urlsafe_base64_decode
    return base64.urlsafe_b64decode(s.ljust(len(s) + len(s) % 4, b"="))
  File "C:\Users\Admin\AppData\Local\Programs\Python\Python310\lib\base64.py", line 133, in urlsafe_b64decode
    return b64decode(s)
  File "C:\Users\Admin\AppData\Local\Programs\Python\Python310\lib\base64.py", line 87, in b64decode
    return binascii.a2b_base64(s)
binascii.Error: Incorrect padding

During handling of the above exception, another exception occurred:

Traceback (most recent call last):
  File "D:\python files\Project tasks\customizeUserModel\venv\lib\site-packages\django\core\handlers\exception.py", line 55, in inner
    response = get_response(request)
  File "D:\python files\Project tasks\customizeUserModel\venv\lib\site-packages\django\core\handlers\base.py", line 197, in _get_response
    response = wrapped_callback(request, *callback_args, **callback_kwargs)
  File "D:\python files\Project tasks\customizeUserModel\venv\lib\site-packages\django\views\decorators\csrf.py", line 56, in wrapper_view
    return view_func(*args, **kwargs)
  File "D:\python files\Project tasks\customizeUserModel\venv\lib\site-packages\django\views\generic\base.py", line 104, in view
    return self.dispatch(request, *args, **kwargs)
  File "D:\python files\Project tasks\customizeUserModel\venv\lib\site-packages\rest_framework\views.py", line 509, in dispatch
    response = self.handle_exception(exc)
  File "D:\python files\Project tasks\customizeUserModel\venv\lib\site-packages\rest_framework\views.py", line 469, in handle_exception
    self.raise_uncaught_exception(exc)
  File "D:\python files\Project tasks\customizeUserModel\venv\lib\site-packages\rest_framework\views.py", line 480, in raise_uncaught_exception
    raise exc
  File "D:\python files\Project tasks\customizeUserModel\venv\lib\site-packages\rest_framework\views.py", line 506, in dispatch
    response = handler(request, *args, **kwargs)
  File "D:\python files\Project tasks\customizeUserModel\projectDept\accounts\views.py", line 39, in get
    uid = force_bytes(urlsafe_base64_decode(uid))
  File "D:\python files\Project tasks\customizeUserModel\venv\lib\site-packages\django\utils\http.py", line 208, in urlsafe_base64_decode
    raise ValueError(e)
ValueError: Incorrect padding
ERROR 2023-08-05 17:13:15,200 basehttp "GET /activate/%3Cstr:uid%3E/%3Cstr:token%3E/ HTTP/1.1" 500 116709
ERROR 2023-08-05 17:13:26,585 log Internal Server Error: /activate/<str:uid>/<str:token>/
Traceback (most recent call last):
  File "D:\python files\Project tasks\customizeUserModel\venv\lib\site-packages\django\utils\http.py", line 206, in urlsafe_base64_decode
    return base64.urlsafe_b64decode(s.ljust(len(s) + len(s) % 4, b"="))
  File "C:\Users\Admin\AppData\Local\Programs\Python\Python310\lib\base64.py", line 133, in urlsafe_b64decode
    return b64decode(s)
  File "C:\Users\Admin\AppData\Local\Programs\Python\Python310\lib\base64.py", line 87, in b64decode
    return binascii.a2b_base64(s)
binascii.Error: Incorrect padding

During handling of the above exception, another exception occurred:

Traceback (most recent call last):
  File "D:\python files\Project tasks\customizeUserModel\venv\lib\site-packages\django\core\handlers\exception.py", line 55, in inner
    response = get_response(request)
  File "D:\python files\Project tasks\customizeUserModel\venv\lib\site-packages\django\core\handlers\base.py", line 197, in _get_response
    response = wrapped_callback(request, *callback_args, **callback_kwargs)
  File "D:\python files\Project tasks\customizeUserModel\venv\lib\site-packages\django\views\decorators\csrf.py", line 56, in wrapper_view
    return view_func(*args, **kwargs)
  File "D:\python files\Project tasks\customizeUserModel\venv\lib\site-packages\django\views\generic\base.py", line 104, in view
    return self.dispatch(request, *args, **kwargs)
  File "D:\python files\Project tasks\customizeUserModel\venv\lib\site-packages\rest_framework\views.py", line 509, in dispatch
    response = self.handle_exception(exc)
  File "D:\python files\Project tasks\customizeUserModel\venv\lib\site-packages\rest_framework\views.py", line 469, in handle_exception
    self.raise_uncaught_exception(exc)
  File "D:\python files\Project tasks\customizeUserModel\venv\lib\site-packages\rest_framework\views.py", line 480, in raise_uncaught_exception
    raise exc
  File "D:\python files\Project tasks\customizeUserModel\venv\lib\site-packages\rest_framework\views.py", line 506, in dispatch
    response = handler(request, *args, **kwargs)
  File "D:\python files\Project tasks\customizeUserModel\projectDept\accounts\views.py", line 39, in get
    uid = force_bytes(urlsafe_base64_decode(uid))
  File "D:\python files\Project tasks\customizeUserModel\venv\lib\site-packages\django\utils\http.py", line 208, in urlsafe_base64_decode
    raise ValueError(e)
ValueError: Incorrect padding
ERROR 2023-08-05 17:13:26,598 basehttp "GET /activate/%3Cstr:uid%3E/%3Cstr:token%3E/ HTTP/1.1" 500 116709
ERROR 2023-08-05 17:13:49,519 log Internal Server Error: /activate/<str:uid>/<str:token>/
Traceback (most recent call last):
  File "D:\python files\Project tasks\customizeUserModel\venv\lib\site-packages\django\utils\http.py", line 206, in urlsafe_base64_decode
    return base64.urlsafe_b64decode(s.ljust(len(s) + len(s) % 4, b"="))
  File "C:\Users\Admin\AppData\Local\Programs\Python\Python310\lib\base64.py", line 133, in urlsafe_b64decode
    return b64decode(s)
  File "C:\Users\Admin\AppData\Local\Programs\Python\Python310\lib\base64.py", line 87, in b64decode
    return binascii.a2b_base64(s)
binascii.Error: Incorrect padding

During handling of the above exception, another exception occurred:

Traceback (most recent call last):
  File "D:\python files\Project tasks\customizeUserModel\venv\lib\site-packages\django\core\handlers\exception.py", line 55, in inner
    response = get_response(request)
  File "D:\python files\Project tasks\customizeUserModel\venv\lib\site-packages\django\core\handlers\base.py", line 197, in _get_response
    response = wrapped_callback(request, *callback_args, **callback_kwargs)
  File "D:\python files\Project tasks\customizeUserModel\venv\lib\site-packages\django\views\decorators\csrf.py", line 56, in wrapper_view
    return view_func(*args, **kwargs)
  File "D:\python files\Project tasks\customizeUserModel\venv\lib\site-packages\django\views\generic\base.py", line 104, in view
    return self.dispatch(request, *args, **kwargs)
  File "D:\python files\Project tasks\customizeUserModel\venv\lib\site-packages\rest_framework\views.py", line 509, in dispatch
    response = self.handle_exception(exc)
  File "D:\python files\Project tasks\customizeUserModel\venv\lib\site-packages\rest_framework\views.py", line 469, in handle_exception
    self.raise_uncaught_exception(exc)
  File "D:\python files\Project tasks\customizeUserModel\venv\lib\site-packages\rest_framework\views.py", line 480, in raise_uncaught_exception
    raise exc
  File "D:\python files\Project tasks\customizeUserModel\venv\lib\site-packages\rest_framework\views.py", line 506, in dispatch
    response = handler(request, *args, **kwargs)
  File "D:\python files\Project tasks\customizeUserModel\projectDept\accounts\views.py", line 39, in get
    uid = force_bytes(urlsafe_base64_decode(uid))
  File "D:\python files\Project tasks\customizeUserModel\venv\lib\site-packages\django\utils\http.py", line 208, in urlsafe_base64_decode
    raise ValueError(e)
ValueError: Incorrect padding
ERROR 2023-08-05 17:13:49,523 basehttp "GET /activate/%3Cstr:uid%3E/%3Cstr:token%3E/ HTTP/1.1" 500 116709
ERROR 2023-08-05 17:13:51,510 log Internal Server Error: /activate/<str:uid>/<str:token>/
Traceback (most recent call last):
  File "D:\python files\Project tasks\customizeUserModel\venv\lib\site-packages\django\utils\http.py", line 206, in urlsafe_base64_decode
    return base64.urlsafe_b64decode(s.ljust(len(s) + len(s) % 4, b"="))
  File "C:\Users\Admin\AppData\Local\Programs\Python\Python310\lib\base64.py", line 133, in urlsafe_b64decode
    return b64decode(s)
  File "C:\Users\Admin\AppData\Local\Programs\Python\Python310\lib\base64.py", line 87, in b64decode
    return binascii.a2b_base64(s)
binascii.Error: Incorrect padding

During handling of the above exception, another exception occurred:

Traceback (most recent call last):
  File "D:\python files\Project tasks\customizeUserModel\venv\lib\site-packages\django\core\handlers\exception.py", line 55, in inner
    response = get_response(request)
  File "D:\python files\Project tasks\customizeUserModel\venv\lib\site-packages\django\core\handlers\base.py", line 197, in _get_response
    response = wrapped_callback(request, *callback_args, **callback_kwargs)
  File "D:\python files\Project tasks\customizeUserModel\venv\lib\site-packages\django\views\decorators\csrf.py", line 56, in wrapper_view
    return view_func(*args, **kwargs)
  File "D:\python files\Project tasks\customizeUserModel\venv\lib\site-packages\django\views\generic\base.py", line 104, in view
    return self.dispatch(request, *args, **kwargs)
  File "D:\python files\Project tasks\customizeUserModel\venv\lib\site-packages\rest_framework\views.py", line 509, in dispatch
    response = self.handle_exception(exc)
  File "D:\python files\Project tasks\customizeUserModel\venv\lib\site-packages\rest_framework\views.py", line 469, in handle_exception
    self.raise_uncaught_exception(exc)
  File "D:\python files\Project tasks\customizeUserModel\venv\lib\site-packages\rest_framework\views.py", line 480, in raise_uncaught_exception
    raise exc
  File "D:\python files\Project tasks\customizeUserModel\venv\lib\site-packages\rest_framework\views.py", line 506, in dispatch
    response = handler(request, *args, **kwargs)
  File "D:\python files\Project tasks\customizeUserModel\projectDept\accounts\views.py", line 39, in get
    uid = force_bytes(urlsafe_base64_decode(uid))
  File "D:\python files\Project tasks\customizeUserModel\venv\lib\site-packages\django\utils\http.py", line 208, in urlsafe_base64_decode
    raise ValueError(e)
ValueError: Incorrect padding
ERROR 2023-08-05 17:13:51,513 basehttp "GET /activate/%3Cstr:uid%3E/%3Cstr:token%3E/ HTTP/1.1" 500 116709
ERROR 2023-08-05 17:14:16,506 log Internal Server Error: /activate/<str:uid>/<str:token>/
Traceback (most recent call last):
  File "D:\python files\Project tasks\customizeUserModel\venv\lib\site-packages\django\utils\http.py", line 206, in urlsafe_base64_decode
    return base64.urlsafe_b64decode(s.ljust(len(s) + len(s) % 4, b"="))
  File "C:\Users\Admin\AppData\Local\Programs\Python\Python310\lib\base64.py", line 133, in urlsafe_b64decode
    return b64decode(s)
  File "C:\Users\Admin\AppData\Local\Programs\Python\Python310\lib\base64.py", line 87, in b64decode
    return binascii.a2b_base64(s)
binascii.Error: Incorrect padding

During handling of the above exception, another exception occurred:

Traceback (most recent call last):
  File "D:\python files\Project tasks\customizeUserModel\venv\lib\site-packages\django\core\handlers\exception.py", line 55, in inner
    response = get_response(request)
  File "D:\python files\Project tasks\customizeUserModel\venv\lib\site-packages\django\core\handlers\base.py", line 197, in _get_response
    response = wrapped_callback(request, *callback_args, **callback_kwargs)
  File "D:\python files\Project tasks\customizeUserModel\venv\lib\site-packages\django\views\decorators\csrf.py", line 56, in wrapper_view
    return view_func(*args, **kwargs)
  File "D:\python files\Project tasks\customizeUserModel\venv\lib\site-packages\django\views\generic\base.py", line 104, in view
    return self.dispatch(request, *args, **kwargs)
  File "D:\python files\Project tasks\customizeUserModel\venv\lib\site-packages\rest_framework\views.py", line 509, in dispatch
    response = self.handle_exception(exc)
  File "D:\python files\Project tasks\customizeUserModel\venv\lib\site-packages\rest_framework\views.py", line 469, in handle_exception
    self.raise_uncaught_exception(exc)
  File "D:\python files\Project tasks\customizeUserModel\venv\lib\site-packages\rest_framework\views.py", line 480, in raise_uncaught_exception
    raise exc
  File "D:\python files\Project tasks\customizeUserModel\venv\lib\site-packages\rest_framework\views.py", line 506, in dispatch
    response = handler(request, *args, **kwargs)
  File "D:\python files\Project tasks\customizeUserModel\projectDept\accounts\views.py", line 39, in get
    uid = force_bytes(urlsafe_base64_decode(uid))
  File "D:\python files\Project tasks\customizeUserModel\venv\lib\site-packages\django\utils\http.py", line 208, in urlsafe_base64_decode
    raise ValueError(e)
ValueError: Incorrect padding
ERROR 2023-08-05 17:14:16,509 basehttp "GET /activate/%3Cstr:uid%3E/%3Cstr:token%3E/ HTTP/1.1" 500 116709
ERROR 2023-08-05 17:14:19,195 log Internal Server Error: /activate/<str:uid>/<str:token>/
Traceback (most recent call last):
  File "D:\python files\Project tasks\customizeUserModel\venv\lib\site-packages\django\utils\http.py", line 206, in urlsafe_base64_decode
    return base64.urlsafe_b64decode(s.ljust(len(s) + len(s) % 4, b"="))
  File "C:\Users\Admin\AppData\Local\Programs\Python\Python310\lib\base64.py", line 133, in urlsafe_b64decode
    return b64decode(s)
  File "C:\Users\Admin\AppData\Local\Programs\Python\Python310\lib\base64.py", line 87, in b64decode
    return binascii.a2b_base64(s)
binascii.Error: Incorrect padding

During handling of the above exception, another exception occurred:

Traceback (most recent call last):
  File "D:\python files\Project tasks\customizeUserModel\venv\lib\site-packages\django\core\handlers\exception.py", line 55, in inner
    response = get_response(request)
  File "D:\python files\Project tasks\customizeUserModel\venv\lib\site-packages\django\core\handlers\base.py", line 197, in _get_response
    response = wrapped_callback(request, *callback_args, **callback_kwargs)
  File "D:\python files\Project tasks\customizeUserModel\venv\lib\site-packages\django\views\decorators\csrf.py", line 56, in wrapper_view
    return view_func(*args, **kwargs)
  File "D:\python files\Project tasks\customizeUserModel\venv\lib\site-packages\django\views\generic\base.py", line 104, in view
    return self.dispatch(request, *args, **kwargs)
  File "D:\python files\Project tasks\customizeUserModel\venv\lib\site-packages\rest_framework\views.py", line 509, in dispatch
    response = self.handle_exception(exc)
  File "D:\python files\Project tasks\customizeUserModel\venv\lib\site-packages\rest_framework\views.py", line 469, in handle_exception
    self.raise_uncaught_exception(exc)
  File "D:\python files\Project tasks\customizeUserModel\venv\lib\site-packages\rest_framework\views.py", line 480, in raise_uncaught_exception
    raise exc
  File "D:\python files\Project tasks\customizeUserModel\venv\lib\site-packages\rest_framework\views.py", line 506, in dispatch
    response = handler(request, *args, **kwargs)
  File "D:\python files\Project tasks\customizeUserModel\projectDept\accounts\views.py", line 39, in get
    uid = force_bytes(urlsafe_base64_decode(uid))
  File "D:\python files\Project tasks\customizeUserModel\venv\lib\site-packages\django\utils\http.py", line 208, in urlsafe_base64_decode
    raise ValueError(e)
ValueError: Incorrect padding
ERROR 2023-08-05 17:14:19,200 basehttp "GET /activate/%3Cstr:uid%3E/%3Cstr:token%3E/ HTTP/1.1" 500 116709
ERROR 2023-08-05 17:14:31,539 log Internal Server Error: /activate/<str:uid>/<str:token>/
Traceback (most recent call last):
  File "D:\python files\Project tasks\customizeUserModel\venv\lib\site-packages\django\utils\http.py", line 206, in urlsafe_base64_decode
    return base64.urlsafe_b64decode(s.ljust(len(s) + len(s) % 4, b"="))
  File "C:\Users\Admin\AppData\Local\Programs\Python\Python310\lib\base64.py", line 133, in urlsafe_b64decode
    return b64decode(s)
  File "C:\Users\Admin\AppData\Local\Programs\Python\Python310\lib\base64.py", line 87, in b64decode
    return binascii.a2b_base64(s)
binascii.Error: Incorrect padding

During handling of the above exception, another exception occurred:

Traceback (most recent call last):
  File "D:\python files\Project tasks\customizeUserModel\venv\lib\site-packages\django\core\handlers\exception.py", line 55, in inner
    response = get_response(request)
  File "D:\python files\Project tasks\customizeUserModel\venv\lib\site-packages\django\core\handlers\base.py", line 197, in _get_response
    response = wrapped_callback(request, *callback_args, **callback_kwargs)
  File "D:\python files\Project tasks\customizeUserModel\venv\lib\site-packages\django\views\decorators\csrf.py", line 56, in wrapper_view
    return view_func(*args, **kwargs)
  File "D:\python files\Project tasks\customizeUserModel\venv\lib\site-packages\django\views\generic\base.py", line 104, in view
    return self.dispatch(request, *args, **kwargs)
  File "D:\python files\Project tasks\customizeUserModel\venv\lib\site-packages\rest_framework\views.py", line 509, in dispatch
    response = self.handle_exception(exc)
  File "D:\python files\Project tasks\customizeUserModel\venv\lib\site-packages\rest_framework\views.py", line 469, in handle_exception
    self.raise_uncaught_exception(exc)
  File "D:\python files\Project tasks\customizeUserModel\venv\lib\site-packages\rest_framework\views.py", line 480, in raise_uncaught_exception
    raise exc
  File "D:\python files\Project tasks\customizeUserModel\venv\lib\site-packages\rest_framework\views.py", line 506, in dispatch
    response = handler(request, *args, **kwargs)
  File "D:\python files\Project tasks\customizeUserModel\projectDept\accounts\views.py", line 39, in get
    uid = force_bytes(urlsafe_base64_decode(uid))
  File "D:\python files\Project tasks\customizeUserModel\venv\lib\site-packages\django\utils\http.py", line 208, in urlsafe_base64_decode
    raise ValueError(e)
ValueError: Incorrect padding
ERROR 2023-08-05 17:14:31,544 basehttp "GET /activate/%3Cstr:uid%3E/%3Cstr:token%3E/ HTTP/1.1" 500 116709
ERROR 2023-08-05 17:14:36,195 log Internal Server Error: /activate/<str:uid>/<str:token>/
Traceback (most recent call last):
  File "D:\python files\Project tasks\customizeUserModel\venv\lib\site-packages\django\utils\http.py", line 206, in urlsafe_base64_decode
    return base64.urlsafe_b64decode(s.ljust(len(s) + len(s) % 4, b"="))
  File "C:\Users\Admin\AppData\Local\Programs\Python\Python310\lib\base64.py", line 133, in urlsafe_b64decode
    return b64decode(s)
  File "C:\Users\Admin\AppData\Local\Programs\Python\Python310\lib\base64.py", line 87, in b64decode
    return binascii.a2b_base64(s)
binascii.Error: Incorrect padding

During handling of the above exception, another exception occurred:

Traceback (most recent call last):
  File "D:\python files\Project tasks\customizeUserModel\venv\lib\site-packages\django\core\handlers\exception.py", line 55, in inner
    response = get_response(request)
  File "D:\python files\Project tasks\customizeUserModel\venv\lib\site-packages\django\core\handlers\base.py", line 197, in _get_response
    response = wrapped_callback(request, *callback_args, **callback_kwargs)
  File "D:\python files\Project tasks\customizeUserModel\venv\lib\site-packages\django\views\decorators\csrf.py", line 56, in wrapper_view
    return view_func(*args, **kwargs)
  File "D:\python files\Project tasks\customizeUserModel\venv\lib\site-packages\django\views\generic\base.py", line 104, in view
    return self.dispatch(request, *args, **kwargs)
  File "D:\python files\Project tasks\customizeUserModel\venv\lib\site-packages\rest_framework\views.py", line 509, in dispatch
    response = self.handle_exception(exc)
  File "D:\python files\Project tasks\customizeUserModel\venv\lib\site-packages\rest_framework\views.py", line 469, in handle_exception
    self.raise_uncaught_exception(exc)
  File "D:\python files\Project tasks\customizeUserModel\venv\lib\site-packages\rest_framework\views.py", line 480, in raise_uncaught_exception
    raise exc
  File "D:\python files\Project tasks\customizeUserModel\venv\lib\site-packages\rest_framework\views.py", line 506, in dispatch
    response = handler(request, *args, **kwargs)
  File "D:\python files\Project tasks\customizeUserModel\projectDept\accounts\views.py", line 39, in get
    uid = force_bytes(urlsafe_base64_decode(uid))
  File "D:\python files\Project tasks\customizeUserModel\venv\lib\site-packages\django\utils\http.py", line 208, in urlsafe_base64_decode
    raise ValueError(e)
ValueError: Incorrect padding
ERROR 2023-08-05 17:14:36,198 basehttp "GET /activate/%3Cstr:uid%3E/%3Cstr:token%3E/ HTTP/1.1" 500 116709
ERROR 2023-08-05 17:14:51,936 log Internal Server Error: /activate/<str:uid>/<str:token>/
Traceback (most recent call last):
  File "D:\python files\Project tasks\customizeUserModel\venv\lib\site-packages\django\utils\http.py", line 206, in urlsafe_base64_decode
    return base64.urlsafe_b64decode(s.ljust(len(s) + len(s) % 4, b"="))
  File "C:\Users\Admin\AppData\Local\Programs\Python\Python310\lib\base64.py", line 133, in urlsafe_b64decode
    return b64decode(s)
  File "C:\Users\Admin\AppData\Local\Programs\Python\Python310\lib\base64.py", line 87, in b64decode
    return binascii.a2b_base64(s)
binascii.Error: Incorrect padding

During handling of the above exception, another exception occurred:

Traceback (most recent call last):
  File "D:\python files\Project tasks\customizeUserModel\venv\lib\site-packages\django\core\handlers\exception.py", line 55, in inner
    response = get_response(request)
  File "D:\python files\Project tasks\customizeUserModel\venv\lib\site-packages\django\core\handlers\base.py", line 197, in _get_response
    response = wrapped_callback(request, *callback_args, **callback_kwargs)
  File "D:\python files\Project tasks\customizeUserModel\venv\lib\site-packages\django\views\decorators\csrf.py", line 56, in wrapper_view
    return view_func(*args, **kwargs)
  File "D:\python files\Project tasks\customizeUserModel\venv\lib\site-packages\django\views\generic\base.py", line 104, in view
    return self.dispatch(request, *args, **kwargs)
  File "D:\python files\Project tasks\customizeUserModel\venv\lib\site-packages\rest_framework\views.py", line 509, in dispatch
    response = self.handle_exception(exc)
  File "D:\python files\Project tasks\customizeUserModel\venv\lib\site-packages\rest_framework\views.py", line 469, in handle_exception
    self.raise_uncaught_exception(exc)
  File "D:\python files\Project tasks\customizeUserModel\venv\lib\site-packages\rest_framework\views.py", line 480, in raise_uncaught_exception
    raise exc
  File "D:\python files\Project tasks\customizeUserModel\venv\lib\site-packages\rest_framework\views.py", line 506, in dispatch
    response = handler(request, *args, **kwargs)
  File "D:\python files\Project tasks\customizeUserModel\projectDept\accounts\views.py", line 39, in get
    uid = force_bytes(urlsafe_base64_decode(uid))
  File "D:\python files\Project tasks\customizeUserModel\venv\lib\site-packages\django\utils\http.py", line 208, in urlsafe_base64_decode
    raise ValueError(e)
ValueError: Incorrect padding
ERROR 2023-08-05 17:14:51,940 basehttp "GET /activate/%3Cstr:uid%3E/%3Cstr:token%3E/ HTTP/1.1" 500 116709
ERROR 2023-08-05 17:14:51,979 log Internal Server Error: /activate/<str:uid>/<str:token>/
Traceback (most recent call last):
  File "D:\python files\Project tasks\customizeUserModel\venv\lib\site-packages\django\utils\http.py", line 206, in urlsafe_base64_decode
    return base64.urlsafe_b64decode(s.ljust(len(s) + len(s) % 4, b"="))
  File "C:\Users\Admin\AppData\Local\Programs\Python\Python310\lib\base64.py", line 133, in urlsafe_b64decode
    return b64decode(s)
  File "C:\Users\Admin\AppData\Local\Programs\Python\Python310\lib\base64.py", line 87, in b64decode
    return binascii.a2b_base64(s)
binascii.Error: Incorrect padding

During handling of the above exception, another exception occurred:

Traceback (most recent call last):
  File "D:\python files\Project tasks\customizeUserModel\venv\lib\site-packages\django\core\handlers\exception.py", line 55, in inner
    response = get_response(request)
  File "D:\python files\Project tasks\customizeUserModel\venv\lib\site-packages\django\core\handlers\base.py", line 197, in _get_response
    response = wrapped_callback(request, *callback_args, **callback_kwargs)
  File "D:\python files\Project tasks\customizeUserModel\venv\lib\site-packages\django\views\decorators\csrf.py", line 56, in wrapper_view
    return view_func(*args, **kwargs)
  File "D:\python files\Project tasks\customizeUserModel\venv\lib\site-packages\django\views\generic\base.py", line 104, in view
    return self.dispatch(request, *args, **kwargs)
  File "D:\python files\Project tasks\customizeUserModel\venv\lib\site-packages\rest_framework\views.py", line 509, in dispatch
    response = self.handle_exception(exc)
  File "D:\python files\Project tasks\customizeUserModel\venv\lib\site-packages\rest_framework\views.py", line 469, in handle_exception
    self.raise_uncaught_exception(exc)
  File "D:\python files\Project tasks\customizeUserModel\venv\lib\site-packages\rest_framework\views.py", line 480, in raise_uncaught_exception
    raise exc
  File "D:\python files\Project tasks\customizeUserModel\venv\lib\site-packages\rest_framework\views.py", line 506, in dispatch
    response = handler(request, *args, **kwargs)
  File "D:\python files\Project tasks\customizeUserModel\projectDept\accounts\views.py", line 39, in get
    uid = force_bytes(urlsafe_base64_decode(uid))
  File "D:\python files\Project tasks\customizeUserModel\venv\lib\site-packages\django\utils\http.py", line 208, in urlsafe_base64_decode
    raise ValueError(e)
ValueError: Incorrect padding
ERROR 2023-08-05 17:14:51,986 basehttp "GET /activate/%3Cstr:uid%3E/%3Cstr:token%3E/ HTTP/1.1" 500 116709
ERROR 2023-08-05 17:15:20,337 log Internal Server Error: /activate/<str:uid>/<str:token>/
Traceback (most recent call last):
  File "D:\python files\Project tasks\customizeUserModel\venv\lib\site-packages\django\utils\http.py", line 206, in urlsafe_base64_decode
    return base64.urlsafe_b64decode(s.ljust(len(s) + len(s) % 4, b"="))
  File "C:\Users\Admin\AppData\Local\Programs\Python\Python310\lib\base64.py", line 133, in urlsafe_b64decode
    return b64decode(s)
  File "C:\Users\Admin\AppData\Local\Programs\Python\Python310\lib\base64.py", line 87, in b64decode
    return binascii.a2b_base64(s)
binascii.Error: Incorrect padding

During handling of the above exception, another exception occurred:

Traceback (most recent call last):
  File "D:\python files\Project tasks\customizeUserModel\venv\lib\site-packages\django\core\handlers\exception.py", line 55, in inner
    response = get_response(request)
  File "D:\python files\Project tasks\customizeUserModel\venv\lib\site-packages\django\core\handlers\base.py", line 197, in _get_response
    response = wrapped_callback(request, *callback_args, **callback_kwargs)
  File "D:\python files\Project tasks\customizeUserModel\venv\lib\site-packages\django\views\decorators\csrf.py", line 56, in wrapper_view
    return view_func(*args, **kwargs)
  File "D:\python files\Project tasks\customizeUserModel\venv\lib\site-packages\django\views\generic\base.py", line 104, in view
    return self.dispatch(request, *args, **kwargs)
  File "D:\python files\Project tasks\customizeUserModel\venv\lib\site-packages\rest_framework\views.py", line 509, in dispatch
    response = self.handle_exception(exc)
  File "D:\python files\Project tasks\customizeUserModel\venv\lib\site-packages\rest_framework\views.py", line 469, in handle_exception
    self.raise_uncaught_exception(exc)
  File "D:\python files\Project tasks\customizeUserModel\venv\lib\site-packages\rest_framework\views.py", line 480, in raise_uncaught_exception
    raise exc
  File "D:\python files\Project tasks\customizeUserModel\venv\lib\site-packages\rest_framework\views.py", line 506, in dispatch
    response = handler(request, *args, **kwargs)
  File "D:\python files\Project tasks\customizeUserModel\projectDept\accounts\views.py", line 39, in get
    uid = force_bytes(urlsafe_base64_decode(uid))
  File "D:\python files\Project tasks\customizeUserModel\venv\lib\site-packages\django\utils\http.py", line 208, in urlsafe_base64_decode
    raise ValueError(e)
ValueError: Incorrect padding
ERROR 2023-08-05 17:15:20,351 basehttp "GET /activate/%3Cstr:uid%3E/%3Cstr:token%3E/ HTTP/1.1" 500 116709
ERROR 2023-08-05 17:15:20,447 log Internal Server Error: /activate/<str:uid>/<str:token>/
Traceback (most recent call last):
  File "D:\python files\Project tasks\customizeUserModel\venv\lib\site-packages\django\utils\http.py", line 206, in urlsafe_base64_decode
    return base64.urlsafe_b64decode(s.ljust(len(s) + len(s) % 4, b"="))
  File "C:\Users\Admin\AppData\Local\Programs\Python\Python310\lib\base64.py", line 133, in urlsafe_b64decode
    return b64decode(s)
  File "C:\Users\Admin\AppData\Local\Programs\Python\Python310\lib\base64.py", line 87, in b64decode
    return binascii.a2b_base64(s)
binascii.Error: Incorrect padding

During handling of the above exception, another exception occurred:

Traceback (most recent call last):
  File "D:\python files\Project tasks\customizeUserModel\venv\lib\site-packages\django\core\handlers\exception.py", line 55, in inner
    response = get_response(request)
  File "D:\python files\Project tasks\customizeUserModel\venv\lib\site-packages\django\core\handlers\base.py", line 197, in _get_response
    response = wrapped_callback(request, *callback_args, **callback_kwargs)
  File "D:\python files\Project tasks\customizeUserModel\venv\lib\site-packages\django\views\decorators\csrf.py", line 56, in wrapper_view
    return view_func(*args, **kwargs)
  File "D:\python files\Project tasks\customizeUserModel\venv\lib\site-packages\django\views\generic\base.py", line 104, in view
    return self.dispatch(request, *args, **kwargs)
  File "D:\python files\Project tasks\customizeUserModel\venv\lib\site-packages\rest_framework\views.py", line 509, in dispatch
    response = self.handle_exception(exc)
  File "D:\python files\Project tasks\customizeUserModel\venv\lib\site-packages\rest_framework\views.py", line 469, in handle_exception
    self.raise_uncaught_exception(exc)
  File "D:\python files\Project tasks\customizeUserModel\venv\lib\site-packages\rest_framework\views.py", line 480, in raise_uncaught_exception
    raise exc
  File "D:\python files\Project tasks\customizeUserModel\venv\lib\site-packages\rest_framework\views.py", line 506, in dispatch
    response = handler(request, *args, **kwargs)
  File "D:\python files\Project tasks\customizeUserModel\projectDept\accounts\views.py", line 39, in get
    uid = force_bytes(urlsafe_base64_decode(uid))
  File "D:\python files\Project tasks\customizeUserModel\venv\lib\site-packages\django\utils\http.py", line 208, in urlsafe_base64_decode
    raise ValueError(e)
ValueError: Incorrect padding
ERROR 2023-08-05 17:15:20,452 basehttp "GET /activate/%3Cstr:uid%3E/%3Cstr:token%3E/ HTTP/1.1" 500 116709
ERROR 2023-08-05 17:15:27,270 log Internal Server Error: /activate/<str:uid>/<str:token>/
Traceback (most recent call last):
  File "D:\python files\Project tasks\customizeUserModel\venv\lib\site-packages\django\utils\http.py", line 206, in urlsafe_base64_decode
    return base64.urlsafe_b64decode(s.ljust(len(s) + len(s) % 4, b"="))
  File "C:\Users\Admin\AppData\Local\Programs\Python\Python310\lib\base64.py", line 133, in urlsafe_b64decode
    return b64decode(s)
  File "C:\Users\Admin\AppData\Local\Programs\Python\Python310\lib\base64.py", line 87, in b64decode
    return binascii.a2b_base64(s)
binascii.Error: Incorrect padding

During handling of the above exception, another exception occurred:

Traceback (most recent call last):
  File "D:\python files\Project tasks\customizeUserModel\venv\lib\site-packages\django\core\handlers\exception.py", line 55, in inner
    response = get_response(request)
  File "D:\python files\Project tasks\customizeUserModel\venv\lib\site-packages\django\core\handlers\base.py", line 197, in _get_response
    response = wrapped_callback(request, *callback_args, **callback_kwargs)
  File "D:\python files\Project tasks\customizeUserModel\venv\lib\site-packages\django\views\decorators\csrf.py", line 56, in wrapper_view
    return view_func(*args, **kwargs)
  File "D:\python files\Project tasks\customizeUserModel\venv\lib\site-packages\django\views\generic\base.py", line 104, in view
    return self.dispatch(request, *args, **kwargs)
  File "D:\python files\Project tasks\customizeUserModel\venv\lib\site-packages\rest_framework\views.py", line 509, in dispatch
    response = self.handle_exception(exc)
  File "D:\python files\Project tasks\customizeUserModel\venv\lib\site-packages\rest_framework\views.py", line 469, in handle_exception
    self.raise_uncaught_exception(exc)
  File "D:\python files\Project tasks\customizeUserModel\venv\lib\site-packages\rest_framework\views.py", line 480, in raise_uncaught_exception
    raise exc
  File "D:\python files\Project tasks\customizeUserModel\venv\lib\site-packages\rest_framework\views.py", line 506, in dispatch
    response = handler(request, *args, **kwargs)
  File "D:\python files\Project tasks\customizeUserModel\projectDept\accounts\views.py", line 39, in get
    uid = force_bytes(urlsafe_base64_decode(uid))
  File "D:\python files\Project tasks\customizeUserModel\venv\lib\site-packages\django\utils\http.py", line 208, in urlsafe_base64_decode
    raise ValueError(e)
ValueError: Incorrect padding
ERROR 2023-08-05 17:15:27,274 basehttp "GET /activate/%3Cstr:uid%3E/%3Cstr:token%3E/ HTTP/1.1" 500 116709
ERROR 2023-08-05 17:15:27,330 log Internal Server Error: /activate/<str:uid>/<str:token>/
Traceback (most recent call last):
  File "D:\python files\Project tasks\customizeUserModel\venv\lib\site-packages\django\utils\http.py", line 206, in urlsafe_base64_decode
    return base64.urlsafe_b64decode(s.ljust(len(s) + len(s) % 4, b"="))
  File "C:\Users\Admin\AppData\Local\Programs\Python\Python310\lib\base64.py", line 133, in urlsafe_b64decode
    return b64decode(s)
  File "C:\Users\Admin\AppData\Local\Programs\Python\Python310\lib\base64.py", line 87, in b64decode
    return binascii.a2b_base64(s)
binascii.Error: Incorrect padding

During handling of the above exception, another exception occurred:

Traceback (most recent call last):
  File "D:\python files\Project tasks\customizeUserModel\venv\lib\site-packages\django\core\handlers\exception.py", line 55, in inner
    response = get_response(request)
  File "D:\python files\Project tasks\customizeUserModel\venv\lib\site-packages\django\core\handlers\base.py", line 197, in _get_response
    response = wrapped_callback(request, *callback_args, **callback_kwargs)
  File "D:\python files\Project tasks\customizeUserModel\venv\lib\site-packages\django\views\decorators\csrf.py", line 56, in wrapper_view
    return view_func(*args, **kwargs)
  File "D:\python files\Project tasks\customizeUserModel\venv\lib\site-packages\django\views\generic\base.py", line 104, in view
    return self.dispatch(request, *args, **kwargs)
  File "D:\python files\Project tasks\customizeUserModel\venv\lib\site-packages\rest_framework\views.py", line 509, in dispatch
    response = self.handle_exception(exc)
  File "D:\python files\Project tasks\customizeUserModel\venv\lib\site-packages\rest_framework\views.py", line 469, in handle_exception
    self.raise_uncaught_exception(exc)
  File "D:\python files\Project tasks\customizeUserModel\venv\lib\site-packages\rest_framework\views.py", line 480, in raise_uncaught_exception
    raise exc
  File "D:\python files\Project tasks\customizeUserModel\venv\lib\site-packages\rest_framework\views.py", line 506, in dispatch
    response = handler(request, *args, **kwargs)
  File "D:\python files\Project tasks\customizeUserModel\projectDept\accounts\views.py", line 39, in get
    uid = force_bytes(urlsafe_base64_decode(uid))
  File "D:\python files\Project tasks\customizeUserModel\venv\lib\site-packages\django\utils\http.py", line 208, in urlsafe_base64_decode
    raise ValueError(e)
ValueError: Incorrect padding
ERROR 2023-08-05 17:15:27,335 basehttp "GET /activate/%3Cstr:uid%3E/%3Cstr:token%3E/ HTTP/1.1" 500 116709
ERROR 2023-08-05 17:15:45,547 log Internal Server Error: /activate/<str:uid>/<str:token>/
Traceback (most recent call last):
  File "D:\python files\Project tasks\customizeUserModel\venv\lib\site-packages\django\utils\http.py", line 206, in urlsafe_base64_decode
    return base64.urlsafe_b64decode(s.ljust(len(s) + len(s) % 4, b"="))
  File "C:\Users\Admin\AppData\Local\Programs\Python\Python310\lib\base64.py", line 133, in urlsafe_b64decode
    return b64decode(s)
  File "C:\Users\Admin\AppData\Local\Programs\Python\Python310\lib\base64.py", line 87, in b64decode
    return binascii.a2b_base64(s)
binascii.Error: Incorrect padding

During handling of the above exception, another exception occurred:

Traceback (most recent call last):
  File "D:\python files\Project tasks\customizeUserModel\venv\lib\site-packages\django\core\handlers\exception.py", line 55, in inner
    response = get_response(request)
  File "D:\python files\Project tasks\customizeUserModel\venv\lib\site-packages\django\core\handlers\base.py", line 197, in _get_response
    response = wrapped_callback(request, *callback_args, **callback_kwargs)
  File "D:\python files\Project tasks\customizeUserModel\venv\lib\site-packages\django\views\decorators\csrf.py", line 56, in wrapper_view
    return view_func(*args, **kwargs)
  File "D:\python files\Project tasks\customizeUserModel\venv\lib\site-packages\django\views\generic\base.py", line 104, in view
    return self.dispatch(request, *args, **kwargs)
  File "D:\python files\Project tasks\customizeUserModel\venv\lib\site-packages\rest_framework\views.py", line 509, in dispatch
    response = self.handle_exception(exc)
  File "D:\python files\Project tasks\customizeUserModel\venv\lib\site-packages\rest_framework\views.py", line 469, in handle_exception
    self.raise_uncaught_exception(exc)
  File "D:\python files\Project tasks\customizeUserModel\venv\lib\site-packages\rest_framework\views.py", line 480, in raise_uncaught_exception
    raise exc
  File "D:\python files\Project tasks\customizeUserModel\venv\lib\site-packages\rest_framework\views.py", line 506, in dispatch
    response = handler(request, *args, **kwargs)
  File "D:\python files\Project tasks\customizeUserModel\projectDept\accounts\views.py", line 39, in get
    uid = force_bytes(urlsafe_base64_decode(uid))
  File "D:\python files\Project tasks\customizeUserModel\venv\lib\site-packages\django\utils\http.py", line 208, in urlsafe_base64_decode
    raise ValueError(e)
ValueError: Incorrect padding
ERROR 2023-08-05 17:15:45,551 basehttp "GET /activate/%3Cstr:uid%3E/%3Cstr:token%3E/ HTTP/1.1" 500 116709
ERROR 2023-08-05 17:15:46,202 log Internal Server Error: /activate/<str:uid>/<str:token>/
Traceback (most recent call last):
  File "D:\python files\Project tasks\customizeUserModel\venv\lib\site-packages\django\utils\http.py", line 206, in urlsafe_base64_decode
    return base64.urlsafe_b64decode(s.ljust(len(s) + len(s) % 4, b"="))
  File "C:\Users\Admin\AppData\Local\Programs\Python\Python310\lib\base64.py", line 133, in urlsafe_b64decode
    return b64decode(s)
  File "C:\Users\Admin\AppData\Local\Programs\Python\Python310\lib\base64.py", line 87, in b64decode
    return binascii.a2b_base64(s)
binascii.Error: Incorrect padding

During handling of the above exception, another exception occurred:

Traceback (most recent call last):
  File "D:\python files\Project tasks\customizeUserModel\venv\lib\site-packages\django\core\handlers\exception.py", line 55, in inner
    response = get_response(request)
  File "D:\python files\Project tasks\customizeUserModel\venv\lib\site-packages\django\core\handlers\base.py", line 197, in _get_response
    response = wrapped_callback(request, *callback_args, **callback_kwargs)
  File "D:\python files\Project tasks\customizeUserModel\venv\lib\site-packages\django\views\decorators\csrf.py", line 56, in wrapper_view
    return view_func(*args, **kwargs)
  File "D:\python files\Project tasks\customizeUserModel\venv\lib\site-packages\django\views\generic\base.py", line 104, in view
    return self.dispatch(request, *args, **kwargs)
  File "D:\python files\Project tasks\customizeUserModel\venv\lib\site-packages\rest_framework\views.py", line 509, in dispatch
    response = self.handle_exception(exc)
  File "D:\python files\Project tasks\customizeUserModel\venv\lib\site-packages\rest_framework\views.py", line 469, in handle_exception
    self.raise_uncaught_exception(exc)
  File "D:\python files\Project tasks\customizeUserModel\venv\lib\site-packages\rest_framework\views.py", line 480, in raise_uncaught_exception
    raise exc
  File "D:\python files\Project tasks\customizeUserModel\venv\lib\site-packages\rest_framework\views.py", line 506, in dispatch
    response = handler(request, *args, **kwargs)
  File "D:\python files\Project tasks\customizeUserModel\projectDept\accounts\views.py", line 39, in get
    uid = force_bytes(urlsafe_base64_decode(uid))
  File "D:\python files\Project tasks\customizeUserModel\venv\lib\site-packages\django\utils\http.py", line 208, in urlsafe_base64_decode
    raise ValueError(e)
ValueError: Incorrect padding
ERROR 2023-08-05 17:15:46,207 basehttp "GET /activate/%3Cstr:uid%3E/%3Cstr:token%3E/ HTTP/1.1" 500 116709
ERROR 2023-08-05 17:15:52,906 log Internal Server Error: /activate/<str:uid>/<str:token>/
Traceback (most recent call last):
  File "D:\python files\Project tasks\customizeUserModel\venv\lib\site-packages\django\utils\http.py", line 206, in urlsafe_base64_decode
    return base64.urlsafe_b64decode(s.ljust(len(s) + len(s) % 4, b"="))
  File "C:\Users\Admin\AppData\Local\Programs\Python\Python310\lib\base64.py", line 133, in urlsafe_b64decode
    return b64decode(s)
  File "C:\Users\Admin\AppData\Local\Programs\Python\Python310\lib\base64.py", line 87, in b64decode
    return binascii.a2b_base64(s)
binascii.Error: Incorrect padding

During handling of the above exception, another exception occurred:

Traceback (most recent call last):
  File "D:\python files\Project tasks\customizeUserModel\venv\lib\site-packages\django\core\handlers\exception.py", line 55, in inner
    response = get_response(request)
  File "D:\python files\Project tasks\customizeUserModel\venv\lib\site-packages\django\core\handlers\base.py", line 197, in _get_response
    response = wrapped_callback(request, *callback_args, **callback_kwargs)
  File "D:\python files\Project tasks\customizeUserModel\venv\lib\site-packages\django\views\decorators\csrf.py", line 56, in wrapper_view
    return view_func(*args, **kwargs)
  File "D:\python files\Project tasks\customizeUserModel\venv\lib\site-packages\django\views\generic\base.py", line 104, in view
    return self.dispatch(request, *args, **kwargs)
  File "D:\python files\Project tasks\customizeUserModel\venv\lib\site-packages\rest_framework\views.py", line 509, in dispatch
    response = self.handle_exception(exc)
  File "D:\python files\Project tasks\customizeUserModel\venv\lib\site-packages\rest_framework\views.py", line 469, in handle_exception
    self.raise_uncaught_exception(exc)
  File "D:\python files\Project tasks\customizeUserModel\venv\lib\site-packages\rest_framework\views.py", line 480, in raise_uncaught_exception
    raise exc
  File "D:\python files\Project tasks\customizeUserModel\venv\lib\site-packages\rest_framework\views.py", line 506, in dispatch
    response = handler(request, *args, **kwargs)
  File "D:\python files\Project tasks\customizeUserModel\projectDept\accounts\views.py", line 39, in get
    uid = force_bytes(urlsafe_base64_decode(uid))
  File "D:\python files\Project tasks\customizeUserModel\venv\lib\site-packages\django\utils\http.py", line 208, in urlsafe_base64_decode
    raise ValueError(e)
ValueError: Incorrect padding
ERROR 2023-08-05 17:15:52,911 basehttp "GET /activate/%3Cstr:uid%3E/%3Cstr:token%3E/ HTTP/1.1" 500 116709
ERROR 2023-08-05 17:15:52,976 log Internal Server Error: /activate/<str:uid>/<str:token>/
Traceback (most recent call last):
  File "D:\python files\Project tasks\customizeUserModel\venv\lib\site-packages\django\utils\http.py", line 206, in urlsafe_base64_decode
    return base64.urlsafe_b64decode(s.ljust(len(s) + len(s) % 4, b"="))
  File "C:\Users\Admin\AppData\Local\Programs\Python\Python310\lib\base64.py", line 133, in urlsafe_b64decode
    return b64decode(s)
  File "C:\Users\Admin\AppData\Local\Programs\Python\Python310\lib\base64.py", line 87, in b64decode
    return binascii.a2b_base64(s)
binascii.Error: Incorrect padding

During handling of the above exception, another exception occurred:

Traceback (most recent call last):
  File "D:\python files\Project tasks\customizeUserModel\venv\lib\site-packages\django\core\handlers\exception.py", line 55, in inner
    response = get_response(request)
  File "D:\python files\Project tasks\customizeUserModel\venv\lib\site-packages\django\core\handlers\base.py", line 197, in _get_response
    response = wrapped_callback(request, *callback_args, **callback_kwargs)
  File "D:\python files\Project tasks\customizeUserModel\venv\lib\site-packages\django\views\decorators\csrf.py", line 56, in wrapper_view
    return view_func(*args, **kwargs)
  File "D:\python files\Project tasks\customizeUserModel\venv\lib\site-packages\django\views\generic\base.py", line 104, in view
    return self.dispatch(request, *args, **kwargs)
  File "D:\python files\Project tasks\customizeUserModel\venv\lib\site-packages\rest_framework\views.py", line 509, in dispatch
    response = self.handle_exception(exc)
  File "D:\python files\Project tasks\customizeUserModel\venv\lib\site-packages\rest_framework\views.py", line 469, in handle_exception
    self.raise_uncaught_exception(exc)
  File "D:\python files\Project tasks\customizeUserModel\venv\lib\site-packages\rest_framework\views.py", line 480, in raise_uncaught_exception
    raise exc
  File "D:\python files\Project tasks\customizeUserModel\venv\lib\site-packages\rest_framework\views.py", line 506, in dispatch
    response = handler(request, *args, **kwargs)
  File "D:\python files\Project tasks\customizeUserModel\projectDept\accounts\views.py", line 39, in get
    uid = force_bytes(urlsafe_base64_decode(uid))
  File "D:\python files\Project tasks\customizeUserModel\venv\lib\site-packages\django\utils\http.py", line 208, in urlsafe_base64_decode
    raise ValueError(e)
ValueError: Incorrect padding
ERROR 2023-08-05 17:15:52,981 basehttp "GET /activate/%3Cstr:uid%3E/%3Cstr:token%3E/ HTTP/1.1" 500 116709
ERROR 2023-08-05 17:16:22,840 log Internal Server Error: /activate/<str:uid>/<str:token>/
Traceback (most recent call last):
  File "D:\python files\Project tasks\customizeUserModel\venv\lib\site-packages\django\utils\http.py", line 206, in urlsafe_base64_decode
    return base64.urlsafe_b64decode(s.ljust(len(s) + len(s) % 4, b"="))
  File "C:\Users\Admin\AppData\Local\Programs\Python\Python310\lib\base64.py", line 133, in urlsafe_b64decode
    return b64decode(s)
  File "C:\Users\Admin\AppData\Local\Programs\Python\Python310\lib\base64.py", line 87, in b64decode
    return binascii.a2b_base64(s)
binascii.Error: Incorrect padding

During handling of the above exception, another exception occurred:

Traceback (most recent call last):
  File "D:\python files\Project tasks\customizeUserModel\venv\lib\site-packages\django\core\handlers\exception.py", line 55, in inner
    response = get_response(request)
  File "D:\python files\Project tasks\customizeUserModel\venv\lib\site-packages\django\core\handlers\base.py", line 197, in _get_response
    response = wrapped_callback(request, *callback_args, **callback_kwargs)
  File "D:\python files\Project tasks\customizeUserModel\venv\lib\site-packages\django\views\decorators\csrf.py", line 56, in wrapper_view
    return view_func(*args, **kwargs)
  File "D:\python files\Project tasks\customizeUserModel\venv\lib\site-packages\django\views\generic\base.py", line 104, in view
    return self.dispatch(request, *args, **kwargs)
  File "D:\python files\Project tasks\customizeUserModel\venv\lib\site-packages\rest_framework\views.py", line 509, in dispatch
    response = self.handle_exception(exc)
  File "D:\python files\Project tasks\customizeUserModel\venv\lib\site-packages\rest_framework\views.py", line 469, in handle_exception
    self.raise_uncaught_exception(exc)
  File "D:\python files\Project tasks\customizeUserModel\venv\lib\site-packages\rest_framework\views.py", line 480, in raise_uncaught_exception
    raise exc
  File "D:\python files\Project tasks\customizeUserModel\venv\lib\site-packages\rest_framework\views.py", line 506, in dispatch
    response = handler(request, *args, **kwargs)
  File "D:\python files\Project tasks\customizeUserModel\projectDept\accounts\views.py", line 39, in get
    uid = force_bytes(urlsafe_base64_decode(uid))
  File "D:\python files\Project tasks\customizeUserModel\venv\lib\site-packages\django\utils\http.py", line 208, in urlsafe_base64_decode
    raise ValueError(e)
ValueError: Incorrect padding
ERROR 2023-08-05 17:16:22,842 basehttp "GET /activate/%3Cstr:uid%3E/%3Cstr:token%3E/ HTTP/1.1" 500 116709
ERROR 2023-08-05 17:16:22,904 log Internal Server Error: /activate/<str:uid>/<str:token>/
Traceback (most recent call last):
  File "D:\python files\Project tasks\customizeUserModel\venv\lib\site-packages\django\utils\http.py", line 206, in urlsafe_base64_decode
    return base64.urlsafe_b64decode(s.ljust(len(s) + len(s) % 4, b"="))
  File "C:\Users\Admin\AppData\Local\Programs\Python\Python310\lib\base64.py", line 133, in urlsafe_b64decode
    return b64decode(s)
  File "C:\Users\Admin\AppData\Local\Programs\Python\Python310\lib\base64.py", line 87, in b64decode
    return binascii.a2b_base64(s)
binascii.Error: Incorrect padding

During handling of the above exception, another exception occurred:

Traceback (most recent call last):
  File "D:\python files\Project tasks\customizeUserModel\venv\lib\site-packages\django\core\handlers\exception.py", line 55, in inner
    response = get_response(request)
  File "D:\python files\Project tasks\customizeUserModel\venv\lib\site-packages\django\core\handlers\base.py", line 197, in _get_response
    response = wrapped_callback(request, *callback_args, **callback_kwargs)
  File "D:\python files\Project tasks\customizeUserModel\venv\lib\site-packages\django\views\decorators\csrf.py", line 56, in wrapper_view
    return view_func(*args, **kwargs)
  File "D:\python files\Project tasks\customizeUserModel\venv\lib\site-packages\django\views\generic\base.py", line 104, in view
    return self.dispatch(request, *args, **kwargs)
  File "D:\python files\Project tasks\customizeUserModel\venv\lib\site-packages\rest_framework\views.py", line 509, in dispatch
    response = self.handle_exception(exc)
  File "D:\python files\Project tasks\customizeUserModel\venv\lib\site-packages\rest_framework\views.py", line 469, in handle_exception
    self.raise_uncaught_exception(exc)
  File "D:\python files\Project tasks\customizeUserModel\venv\lib\site-packages\rest_framework\views.py", line 480, in raise_uncaught_exception
    raise exc
  File "D:\python files\Project tasks\customizeUserModel\venv\lib\site-packages\rest_framework\views.py", line 506, in dispatch
    response = handler(request, *args, **kwargs)
  File "D:\python files\Project tasks\customizeUserModel\projectDept\accounts\views.py", line 39, in get
    uid = force_bytes(urlsafe_base64_decode(uid))
  File "D:\python files\Project tasks\customizeUserModel\venv\lib\site-packages\django\utils\http.py", line 208, in urlsafe_base64_decode
    raise ValueError(e)
ValueError: Incorrect padding
ERROR 2023-08-05 17:16:22,908 basehttp "GET /activate/%3Cstr:uid%3E/%3Cstr:token%3E/ HTTP/1.1" 500 116709
ERROR 2023-08-05 17:16:23,206 log Internal Server Error: /activate/<str:uid>/<str:token>/
Traceback (most recent call last):
  File "D:\python files\Project tasks\customizeUserModel\venv\lib\site-packages\django\utils\http.py", line 206, in urlsafe_base64_decode
    return base64.urlsafe_b64decode(s.ljust(len(s) + len(s) % 4, b"="))
  File "C:\Users\Admin\AppData\Local\Programs\Python\Python310\lib\base64.py", line 133, in urlsafe_b64decode
    return b64decode(s)
  File "C:\Users\Admin\AppData\Local\Programs\Python\Python310\lib\base64.py", line 87, in b64decode
    return binascii.a2b_base64(s)
binascii.Error: Incorrect padding

During handling of the above exception, another exception occurred:

Traceback (most recent call last):
  File "D:\python files\Project tasks\customizeUserModel\venv\lib\site-packages\django\core\handlers\exception.py", line 55, in inner
    response = get_response(request)
  File "D:\python files\Project tasks\customizeUserModel\venv\lib\site-packages\django\core\handlers\base.py", line 197, in _get_response
    response = wrapped_callback(request, *callback_args, **callback_kwargs)
  File "D:\python files\Project tasks\customizeUserModel\venv\lib\site-packages\django\views\decorators\csrf.py", line 56, in wrapper_view
    return view_func(*args, **kwargs)
  File "D:\python files\Project tasks\customizeUserModel\venv\lib\site-packages\django\views\generic\base.py", line 104, in view
    return self.dispatch(request, *args, **kwargs)
  File "D:\python files\Project tasks\customizeUserModel\venv\lib\site-packages\rest_framework\views.py", line 509, in dispatch
    response = self.handle_exception(exc)
  File "D:\python files\Project tasks\customizeUserModel\venv\lib\site-packages\rest_framework\views.py", line 469, in handle_exception
    self.raise_uncaught_exception(exc)
  File "D:\python files\Project tasks\customizeUserModel\venv\lib\site-packages\rest_framework\views.py", line 480, in raise_uncaught_exception
    raise exc
  File "D:\python files\Project tasks\customizeUserModel\venv\lib\site-packages\rest_framework\views.py", line 506, in dispatch
    response = handler(request, *args, **kwargs)
  File "D:\python files\Project tasks\customizeUserModel\projectDept\accounts\views.py", line 39, in get
    uid = force_bytes(urlsafe_base64_decode(uid))
  File "D:\python files\Project tasks\customizeUserModel\venv\lib\site-packages\django\utils\http.py", line 208, in urlsafe_base64_decode
    raise ValueError(e)
ValueError: Incorrect padding
ERROR 2023-08-05 17:16:23,208 basehttp "GET /activate/%3Cstr:uid%3E/%3Cstr:token%3E/ HTTP/1.1" 500 116709
ERROR 2023-08-05 17:16:23,244 log Internal Server Error: /activate/<str:uid>/<str:token>/
Traceback (most recent call last):
  File "D:\python files\Project tasks\customizeUserModel\venv\lib\site-packages\django\utils\http.py", line 206, in urlsafe_base64_decode
    return base64.urlsafe_b64decode(s.ljust(len(s) + len(s) % 4, b"="))
  File "C:\Users\Admin\AppData\Local\Programs\Python\Python310\lib\base64.py", line 133, in urlsafe_b64decode
    return b64decode(s)
  File "C:\Users\Admin\AppData\Local\Programs\Python\Python310\lib\base64.py", line 87, in b64decode
    return binascii.a2b_base64(s)
binascii.Error: Incorrect padding

During handling of the above exception, another exception occurred:

Traceback (most recent call last):
  File "D:\python files\Project tasks\customizeUserModel\venv\lib\site-packages\django\core\handlers\exception.py", line 55, in inner
    response = get_response(request)
  File "D:\python files\Project tasks\customizeUserModel\venv\lib\site-packages\django\core\handlers\base.py", line 197, in _get_response
    response = wrapped_callback(request, *callback_args, **callback_kwargs)
  File "D:\python files\Project tasks\customizeUserModel\venv\lib\site-packages\django\views\decorators\csrf.py", line 56, in wrapper_view
    return view_func(*args, **kwargs)
  File "D:\python files\Project tasks\customizeUserModel\venv\lib\site-packages\django\views\generic\base.py", line 104, in view
    return self.dispatch(request, *args, **kwargs)
  File "D:\python files\Project tasks\customizeUserModel\venv\lib\site-packages\rest_framework\views.py", line 509, in dispatch
    response = self.handle_exception(exc)
  File "D:\python files\Project tasks\customizeUserModel\venv\lib\site-packages\rest_framework\views.py", line 469, in handle_exception
    self.raise_uncaught_exception(exc)
  File "D:\python files\Project tasks\customizeUserModel\venv\lib\site-packages\rest_framework\views.py", line 480, in raise_uncaught_exception
    raise exc
  File "D:\python files\Project tasks\customizeUserModel\venv\lib\site-packages\rest_framework\views.py", line 506, in dispatch
    response = handler(request, *args, **kwargs)
  File "D:\python files\Project tasks\customizeUserModel\projectDept\accounts\views.py", line 39, in get
    uid = force_bytes(urlsafe_base64_decode(uid))
  File "D:\python files\Project tasks\customizeUserModel\venv\lib\site-packages\django\utils\http.py", line 208, in urlsafe_base64_decode
    raise ValueError(e)
ValueError: Incorrect padding
ERROR 2023-08-05 17:16:23,248 basehttp "GET /activate/%3Cstr:uid%3E/%3Cstr:token%3E/ HTTP/1.1" 500 116709
ERROR 2023-08-05 17:16:34,346 log Internal Server Error: /activate/<str:uid>/<str:token>/
Traceback (most recent call last):
  File "D:\python files\Project tasks\customizeUserModel\venv\lib\site-packages\django\utils\http.py", line 206, in urlsafe_base64_decode
    return base64.urlsafe_b64decode(s.ljust(len(s) + len(s) % 4, b"="))
  File "C:\Users\Admin\AppData\Local\Programs\Python\Python310\lib\base64.py", line 133, in urlsafe_b64decode
    return b64decode(s)
  File "C:\Users\Admin\AppData\Local\Programs\Python\Python310\lib\base64.py", line 87, in b64decode
    return binascii.a2b_base64(s)
binascii.Error: Incorrect padding

During handling of the above exception, another exception occurred:

Traceback (most recent call last):
  File "D:\python files\Project tasks\customizeUserModel\venv\lib\site-packages\django\core\handlers\exception.py", line 55, in inner
    response = get_response(request)
  File "D:\python files\Project tasks\customizeUserModel\venv\lib\site-packages\django\core\handlers\base.py", line 197, in _get_response
    response = wrapped_callback(request, *callback_args, **callback_kwargs)
  File "D:\python files\Project tasks\customizeUserModel\venv\lib\site-packages\django\views\decorators\csrf.py", line 56, in wrapper_view
    return view_func(*args, **kwargs)
  File "D:\python files\Project tasks\customizeUserModel\venv\lib\site-packages\django\views\generic\base.py", line 104, in view
    return self.dispatch(request, *args, **kwargs)
  File "D:\python files\Project tasks\customizeUserModel\venv\lib\site-packages\rest_framework\views.py", line 509, in dispatch
    response = self.handle_exception(exc)
  File "D:\python files\Project tasks\customizeUserModel\venv\lib\site-packages\rest_framework\views.py", line 469, in handle_exception
    self.raise_uncaught_exception(exc)
  File "D:\python files\Project tasks\customizeUserModel\venv\lib\site-packages\rest_framework\views.py", line 480, in raise_uncaught_exception
    raise exc
  File "D:\python files\Project tasks\customizeUserModel\venv\lib\site-packages\rest_framework\views.py", line 506, in dispatch
    response = handler(request, *args, **kwargs)
  File "D:\python files\Project tasks\customizeUserModel\projectDept\accounts\views.py", line 39, in get
    uid = force_bytes(urlsafe_base64_decode(uid))
  File "D:\python files\Project tasks\customizeUserModel\venv\lib\site-packages\django\utils\http.py", line 208, in urlsafe_base64_decode
    raise ValueError(e)
ValueError: Incorrect padding
ERROR 2023-08-05 17:16:34,351 basehttp "GET /activate/%3Cstr:uid%3E/%3Cstr:token%3E/ HTTP/1.1" 500 116709
ERROR 2023-08-05 17:16:34,410 log Internal Server Error: /activate/<str:uid>/<str:token>/
Traceback (most recent call last):
  File "D:\python files\Project tasks\customizeUserModel\venv\lib\site-packages\django\utils\http.py", line 206, in urlsafe_base64_decode
    return base64.urlsafe_b64decode(s.ljust(len(s) + len(s) % 4, b"="))
  File "C:\Users\Admin\AppData\Local\Programs\Python\Python310\lib\base64.py", line 133, in urlsafe_b64decode
    return b64decode(s)
  File "C:\Users\Admin\AppData\Local\Programs\Python\Python310\lib\base64.py", line 87, in b64decode
    return binascii.a2b_base64(s)
binascii.Error: Incorrect padding

During handling of the above exception, another exception occurred:

Traceback (most recent call last):
  File "D:\python files\Project tasks\customizeUserModel\venv\lib\site-packages\django\core\handlers\exception.py", line 55, in inner
    response = get_response(request)
  File "D:\python files\Project tasks\customizeUserModel\venv\lib\site-packages\django\core\handlers\base.py", line 197, in _get_response
    response = wrapped_callback(request, *callback_args, **callback_kwargs)
  File "D:\python files\Project tasks\customizeUserModel\venv\lib\site-packages\django\views\decorators\csrf.py", line 56, in wrapper_view
    return view_func(*args, **kwargs)
  File "D:\python files\Project tasks\customizeUserModel\venv\lib\site-packages\django\views\generic\base.py", line 104, in view
    return self.dispatch(request, *args, **kwargs)
  File "D:\python files\Project tasks\customizeUserModel\venv\lib\site-packages\rest_framework\views.py", line 509, in dispatch
    response = self.handle_exception(exc)
  File "D:\python files\Project tasks\customizeUserModel\venv\lib\site-packages\rest_framework\views.py", line 469, in handle_exception
    self.raise_uncaught_exception(exc)
  File "D:\python files\Project tasks\customizeUserModel\venv\lib\site-packages\rest_framework\views.py", line 480, in raise_uncaught_exception
    raise exc
  File "D:\python files\Project tasks\customizeUserModel\venv\lib\site-packages\rest_framework\views.py", line 506, in dispatch
    response = handler(request, *args, **kwargs)
  File "D:\python files\Project tasks\customizeUserModel\projectDept\accounts\views.py", line 39, in get
    uid = force_bytes(urlsafe_base64_decode(uid))
  File "D:\python files\Project tasks\customizeUserModel\venv\lib\site-packages\django\utils\http.py", line 208, in urlsafe_base64_decode
    raise ValueError(e)
ValueError: Incorrect padding
ERROR 2023-08-05 17:16:34,416 basehttp "GET /activate/%3Cstr:uid%3E/%3Cstr:token%3E/ HTTP/1.1" 500 116709
WARNING 2023-08-05 17:31:47,948 log Bad Request: /activate/MjY/bsghhe-6a89f2723592b4fe6c9e06d552b51947/
WARNING 2023-08-05 17:31:47,949 basehttp "GET /activate/MjY/bsghhe-6a89f2723592b4fe6c9e06d552b51947/ HTTP/1.1" 400 5665
WARNING 2023-08-05 17:35:16,726 log Bad Request: /activate/MjY/bsghhe-6a89f2723592b4fe6c9e06d552b51947/
WARNING 2023-08-05 17:35:16,727 basehttp "GET /activate/MjY/bsghhe-6a89f2723592b4fe6c9e06d552b51947/ HTTP/1.1" 400 5665
ERROR 2023-08-05 17:40:18,521 log Internal Server Error: /activate/<str:uid>/<str:token>/
Traceback (most recent call last):
  File "D:\python files\Project tasks\customizeUserModel\venv\lib\site-packages\django\utils\http.py", line 206, in urlsafe_base64_decode
    return base64.urlsafe_b64decode(s.ljust(len(s) + len(s) % 4, b"="))
  File "C:\Users\Admin\AppData\Local\Programs\Python\Python310\lib\base64.py", line 133, in urlsafe_b64decode
    return b64decode(s)
  File "C:\Users\Admin\AppData\Local\Programs\Python\Python310\lib\base64.py", line 87, in b64decode
    return binascii.a2b_base64(s)
binascii.Error: Incorrect padding

During handling of the above exception, another exception occurred:

Traceback (most recent call last):
  File "D:\python files\Project tasks\customizeUserModel\venv\lib\site-packages\django\core\handlers\exception.py", line 55, in inner
    response = get_response(request)
  File "D:\python files\Project tasks\customizeUserModel\venv\lib\site-packages\django\core\handlers\base.py", line 197, in _get_response
    response = wrapped_callback(request, *callback_args, **callback_kwargs)
  File "D:\python files\Project tasks\customizeUserModel\venv\lib\site-packages\django\views\decorators\csrf.py", line 56, in wrapper_view
    return view_func(*args, **kwargs)
  File "D:\python files\Project tasks\customizeUserModel\venv\lib\site-packages\django\views\generic\base.py", line 104, in view
    return self.dispatch(request, *args, **kwargs)
  File "D:\python files\Project tasks\customizeUserModel\venv\lib\site-packages\rest_framework\views.py", line 509, in dispatch
    response = self.handle_exception(exc)
  File "D:\python files\Project tasks\customizeUserModel\venv\lib\site-packages\rest_framework\views.py", line 469, in handle_exception
    self.raise_uncaught_exception(exc)
  File "D:\python files\Project tasks\customizeUserModel\venv\lib\site-packages\rest_framework\views.py", line 480, in raise_uncaught_exception
    raise exc
  File "D:\python files\Project tasks\customizeUserModel\venv\lib\site-packages\rest_framework\views.py", line 506, in dispatch
    response = handler(request, *args, **kwargs)
  File "D:\python files\Project tasks\customizeUserModel\projectDept\accounts\views.py", line 39, in get
    uid = force_bytes(urlsafe_base64_decode(uid))
  File "D:\python files\Project tasks\customizeUserModel\venv\lib\site-packages\django\utils\http.py", line 208, in urlsafe_base64_decode
    raise ValueError(e)
ValueError: Incorrect padding
ERROR 2023-08-05 17:40:18,525 basehttp "GET /activate/%3Cstr:uid%3E/%3Cstr:token%3E/ HTTP/1.1" 500 116619
ERROR 2023-08-05 17:40:18,557 log Internal Server Error: /activate/<str:uid>/<str:token>/
Traceback (most recent call last):
  File "D:\python files\Project tasks\customizeUserModel\venv\lib\site-packages\django\utils\http.py", line 206, in urlsafe_base64_decode
    return base64.urlsafe_b64decode(s.ljust(len(s) + len(s) % 4, b"="))
  File "C:\Users\Admin\AppData\Local\Programs\Python\Python310\lib\base64.py", line 133, in urlsafe_b64decode
    return b64decode(s)
  File "C:\Users\Admin\AppData\Local\Programs\Python\Python310\lib\base64.py", line 87, in b64decode
    return binascii.a2b_base64(s)
binascii.Error: Incorrect padding

During handling of the above exception, another exception occurred:

Traceback (most recent call last):
  File "D:\python files\Project tasks\customizeUserModel\venv\lib\site-packages\django\core\handlers\exception.py", line 55, in inner
    response = get_response(request)
  File "D:\python files\Project tasks\customizeUserModel\venv\lib\site-packages\django\core\handlers\base.py", line 197, in _get_response
    response = wrapped_callback(request, *callback_args, **callback_kwargs)
  File "D:\python files\Project tasks\customizeUserModel\venv\lib\site-packages\django\views\decorators\csrf.py", line 56, in wrapper_view
    return view_func(*args, **kwargs)
  File "D:\python files\Project tasks\customizeUserModel\venv\lib\site-packages\django\views\generic\base.py", line 104, in view
    return self.dispatch(request, *args, **kwargs)
  File "D:\python files\Project tasks\customizeUserModel\venv\lib\site-packages\rest_framework\views.py", line 509, in dispatch
    response = self.handle_exception(exc)
  File "D:\python files\Project tasks\customizeUserModel\venv\lib\site-packages\rest_framework\views.py", line 469, in handle_exception
    self.raise_uncaught_exception(exc)
  File "D:\python files\Project tasks\customizeUserModel\venv\lib\site-packages\rest_framework\views.py", line 480, in raise_uncaught_exception
    raise exc
  File "D:\python files\Project tasks\customizeUserModel\venv\lib\site-packages\rest_framework\views.py", line 506, in dispatch
    response = handler(request, *args, **kwargs)
  File "D:\python files\Project tasks\customizeUserModel\projectDept\accounts\views.py", line 39, in get
    uid = force_bytes(urlsafe_base64_decode(uid))
  File "D:\python files\Project tasks\customizeUserModel\venv\lib\site-packages\django\utils\http.py", line 208, in urlsafe_base64_decode
    raise ValueError(e)
ValueError: Incorrect padding
ERROR 2023-08-05 17:40:18,560 basehttp "GET /activate/%3Cstr:uid%3E/%3Cstr:token%3E/ HTTP/1.1" 500 116619
WARNING 2023-08-05 17:43:21,601 log Bad Request: /accounts/register/
WARNING 2023-08-05 17:43:21,601 basehttp "POST /accounts/register/ HTTP/1.1" 400 58
WARNING 2023-08-05 17:45:04,680 log Unauthorized: /access/
WARNING 2023-08-05 17:45:04,681 basehttp "POST /access/ HTTP/1.1" 401 63
ERROR 2023-08-05 17:46:29,805 log Internal Server Error: /activate/<str:uid>/<str:token>/
Traceback (most recent call last):
  File "D:\python files\Project tasks\customizeUserModel\venv\lib\site-packages\django\utils\http.py", line 206, in urlsafe_base64_decode
    return base64.urlsafe_b64decode(s.ljust(len(s) + len(s) % 4, b"="))
  File "C:\Users\Admin\AppData\Local\Programs\Python\Python310\lib\base64.py", line 133, in urlsafe_b64decode
    return b64decode(s)
  File "C:\Users\Admin\AppData\Local\Programs\Python\Python310\lib\base64.py", line 87, in b64decode
    return binascii.a2b_base64(s)
binascii.Error: Incorrect padding

During handling of the above exception, another exception occurred:

Traceback (most recent call last):
  File "D:\python files\Project tasks\customizeUserModel\venv\lib\site-packages\django\core\handlers\exception.py", line 55, in inner
    response = get_response(request)
  File "D:\python files\Project tasks\customizeUserModel\venv\lib\site-packages\django\core\handlers\base.py", line 197, in _get_response
    response = wrapped_callback(request, *callback_args, **callback_kwargs)
  File "D:\python files\Project tasks\customizeUserModel\venv\lib\site-packages\django\views\decorators\csrf.py", line 56, in wrapper_view
    return view_func(*args, **kwargs)
  File "D:\python files\Project tasks\customizeUserModel\venv\lib\site-packages\django\views\generic\base.py", line 104, in view
    return self.dispatch(request, *args, **kwargs)
  File "D:\python files\Project tasks\customizeUserModel\venv\lib\site-packages\rest_framework\views.py", line 509, in dispatch
    response = self.handle_exception(exc)
  File "D:\python files\Project tasks\customizeUserModel\venv\lib\site-packages\rest_framework\views.py", line 469, in handle_exception
    self.raise_uncaught_exception(exc)
  File "D:\python files\Project tasks\customizeUserModel\venv\lib\site-packages\rest_framework\views.py", line 480, in raise_uncaught_exception
    raise exc
  File "D:\python files\Project tasks\customizeUserModel\venv\lib\site-packages\rest_framework\views.py", line 506, in dispatch
    response = handler(request, *args, **kwargs)
  File "D:\python files\Project tasks\customizeUserModel\projectDept\accounts\views.py", line 39, in get
    uid = force_bytes(urlsafe_base64_decode(uid))
  File "D:\python files\Project tasks\customizeUserModel\venv\lib\site-packages\django\utils\http.py", line 208, in urlsafe_base64_decode
    raise ValueError(e)
ValueError: Incorrect padding
ERROR 2023-08-05 17:46:29,809 basehttp "GET /activate/%3Cstr:uid%3E/%3Cstr:token%3E/ HTTP/1.1" 500 116619
ERROR 2023-08-05 17:46:29,840 log Internal Server Error: /activate/<str:uid>/<str:token>/
Traceback (most recent call last):
  File "D:\python files\Project tasks\customizeUserModel\venv\lib\site-packages\django\utils\http.py", line 206, in urlsafe_base64_decode
    return base64.urlsafe_b64decode(s.ljust(len(s) + len(s) % 4, b"="))
  File "C:\Users\Admin\AppData\Local\Programs\Python\Python310\lib\base64.py", line 133, in urlsafe_b64decode
    return b64decode(s)
  File "C:\Users\Admin\AppData\Local\Programs\Python\Python310\lib\base64.py", line 87, in b64decode
    return binascii.a2b_base64(s)
binascii.Error: Incorrect padding

During handling of the above exception, another exception occurred:

Traceback (most recent call last):
  File "D:\python files\Project tasks\customizeUserModel\venv\lib\site-packages\django\core\handlers\exception.py", line 55, in inner
    response = get_response(request)
  File "D:\python files\Project tasks\customizeUserModel\venv\lib\site-packages\django\core\handlers\base.py", line 197, in _get_response
    response = wrapped_callback(request, *callback_args, **callback_kwargs)
  File "D:\python files\Project tasks\customizeUserModel\venv\lib\site-packages\django\views\decorators\csrf.py", line 56, in wrapper_view
    return view_func(*args, **kwargs)
  File "D:\python files\Project tasks\customizeUserModel\venv\lib\site-packages\django\views\generic\base.py", line 104, in view
    return self.dispatch(request, *args, **kwargs)
  File "D:\python files\Project tasks\customizeUserModel\venv\lib\site-packages\rest_framework\views.py", line 509, in dispatch
    response = self.handle_exception(exc)
  File "D:\python files\Project tasks\customizeUserModel\venv\lib\site-packages\rest_framework\views.py", line 469, in handle_exception
    self.raise_uncaught_exception(exc)
  File "D:\python files\Project tasks\customizeUserModel\venv\lib\site-packages\rest_framework\views.py", line 480, in raise_uncaught_exception
    raise exc
  File "D:\python files\Project tasks\customizeUserModel\venv\lib\site-packages\rest_framework\views.py", line 506, in dispatch
    response = handler(request, *args, **kwargs)
  File "D:\python files\Project tasks\customizeUserModel\projectDept\accounts\views.py", line 39, in get
    uid = force_bytes(urlsafe_base64_decode(uid))
  File "D:\python files\Project tasks\customizeUserModel\venv\lib\site-packages\django\utils\http.py", line 208, in urlsafe_base64_decode
    raise ValueError(e)
ValueError: Incorrect padding
ERROR 2023-08-05 17:46:29,843 basehttp "GET /activate/%3Cstr:uid%3E/%3Cstr:token%3E/ HTTP/1.1" 500 116619
ERROR 2023-08-05 17:58:24,630 log Internal Server Error: /activate/<str:uid>/<str:token>/
Traceback (most recent call last):
  File "D:\python files\Project tasks\customizeUserModel\venv\lib\site-packages\django\utils\http.py", line 206, in urlsafe_base64_decode
    return base64.urlsafe_b64decode(s.ljust(len(s) + len(s) % 4, b"="))
  File "C:\Users\Admin\AppData\Local\Programs\Python\Python310\lib\base64.py", line 133, in urlsafe_b64decode
    return b64decode(s)
  File "C:\Users\Admin\AppData\Local\Programs\Python\Python310\lib\base64.py", line 87, in b64decode
    return binascii.a2b_base64(s)
binascii.Error: Incorrect padding

During handling of the above exception, another exception occurred:

Traceback (most recent call last):
  File "D:\python files\Project tasks\customizeUserModel\venv\lib\site-packages\django\core\handlers\exception.py", line 55, in inner
    response = get_response(request)
  File "D:\python files\Project tasks\customizeUserModel\venv\lib\site-packages\django\core\handlers\base.py", line 197, in _get_response
    response = wrapped_callback(request, *callback_args, **callback_kwargs)
  File "D:\python files\Project tasks\customizeUserModel\venv\lib\site-packages\django\views\decorators\csrf.py", line 56, in wrapper_view
    return view_func(*args, **kwargs)
  File "D:\python files\Project tasks\customizeUserModel\venv\lib\site-packages\django\views\generic\base.py", line 104, in view
    return self.dispatch(request, *args, **kwargs)
  File "D:\python files\Project tasks\customizeUserModel\venv\lib\site-packages\rest_framework\views.py", line 509, in dispatch
    response = self.handle_exception(exc)
  File "D:\python files\Project tasks\customizeUserModel\venv\lib\site-packages\rest_framework\views.py", line 469, in handle_exception
    self.raise_uncaught_exception(exc)
  File "D:\python files\Project tasks\customizeUserModel\venv\lib\site-packages\rest_framework\views.py", line 480, in raise_uncaught_exception
    raise exc
  File "D:\python files\Project tasks\customizeUserModel\venv\lib\site-packages\rest_framework\views.py", line 506, in dispatch
    response = handler(request, *args, **kwargs)
  File "D:\python files\Project tasks\customizeUserModel\projectDept\accounts\views.py", line 39, in get
    uid = force_bytes(urlsafe_base64_decode(uid))
  File "D:\python files\Project tasks\customizeUserModel\venv\lib\site-packages\django\utils\http.py", line 208, in urlsafe_base64_decode
    raise ValueError(e)
ValueError: Incorrect padding
ERROR 2023-08-05 17:58:24,634 basehttp "GET /activate/%3Cstr:uid%3E/%3Cstr:token%3E/ HTTP/1.1" 500 116619
ERROR 2023-08-05 17:58:24,666 log Internal Server Error: /activate/<str:uid>/<str:token>/
Traceback (most recent call last):
  File "D:\python files\Project tasks\customizeUserModel\venv\lib\site-packages\django\utils\http.py", line 206, in urlsafe_base64_decode
    return base64.urlsafe_b64decode(s.ljust(len(s) + len(s) % 4, b"="))
  File "C:\Users\Admin\AppData\Local\Programs\Python\Python310\lib\base64.py", line 133, in urlsafe_b64decode
    return b64decode(s)
  File "C:\Users\Admin\AppData\Local\Programs\Python\Python310\lib\base64.py", line 87, in b64decode
    return binascii.a2b_base64(s)
binascii.Error: Incorrect padding

During handling of the above exception, another exception occurred:

Traceback (most recent call last):
  File "D:\python files\Project tasks\customizeUserModel\venv\lib\site-packages\django\core\handlers\exception.py", line 55, in inner
    response = get_response(request)
  File "D:\python files\Project tasks\customizeUserModel\venv\lib\site-packages\django\core\handlers\base.py", line 197, in _get_response
    response = wrapped_callback(request, *callback_args, **callback_kwargs)
  File "D:\python files\Project tasks\customizeUserModel\venv\lib\site-packages\django\views\decorators\csrf.py", line 56, in wrapper_view
    return view_func(*args, **kwargs)
  File "D:\python files\Project tasks\customizeUserModel\venv\lib\site-packages\django\views\generic\base.py", line 104, in view
    return self.dispatch(request, *args, **kwargs)
  File "D:\python files\Project tasks\customizeUserModel\venv\lib\site-packages\rest_framework\views.py", line 509, in dispatch
    response = self.handle_exception(exc)
  File "D:\python files\Project tasks\customizeUserModel\venv\lib\site-packages\rest_framework\views.py", line 469, in handle_exception
    self.raise_uncaught_exception(exc)
  File "D:\python files\Project tasks\customizeUserModel\venv\lib\site-packages\rest_framework\views.py", line 480, in raise_uncaught_exception
    raise exc
  File "D:\python files\Project tasks\customizeUserModel\venv\lib\site-packages\rest_framework\views.py", line 506, in dispatch
    response = handler(request, *args, **kwargs)
  File "D:\python files\Project tasks\customizeUserModel\projectDept\accounts\views.py", line 39, in get
    uid = force_bytes(urlsafe_base64_decode(uid))
  File "D:\python files\Project tasks\customizeUserModel\venv\lib\site-packages\django\utils\http.py", line 208, in urlsafe_base64_decode
    raise ValueError(e)
ValueError: Incorrect padding
ERROR 2023-08-05 17:58:24,669 basehttp "GET /activate/%3Cstr:uid%3E/%3Cstr:token%3E/ HTTP/1.1" 500 116619
WARNING 2023-08-05 18:21:21,400 log Bad Request: /activate/Mjc/bsgzxe-27da9ced0c85978f12fbd394b98e7270/
WARNING 2023-08-05 18:21:21,412 basehttp "GET /activate/Mjc/bsgzxe-27da9ced0c85978f12fbd394b98e7270/ HTTP/1.1" 400 5679
WARNING 2023-08-05 21:41:46,725 log Bad Request: /activate/Mjg/bsh1oq-cab95abc059e7eaf9e6f9b6d41baec51/
WARNING 2023-08-05 21:41:46,784 basehttp "GET /activate/Mjg/bsh1oq-cab95abc059e7eaf9e6f9b6d41baec51/ HTTP/1.1" 400 67
WARNING 2023-08-05 21:45:21,265 log Bad Request: /activate/Mjg/bsh1oq-cab95abc059e7eaf9e6f9b6d41baec51/
WARNING 2023-08-05 21:45:21,266 basehttp "GET /activate/Mjg/bsh1oq-cab95abc059e7eaf9e6f9b6d41baec51/ HTTP/1.1" 400 67
WARNING 2023-08-05 21:45:21,355 log Bad Request: /activate/Mjg/bsh1oq-cab95abc059e7eaf9e6f9b6d41baec51/
WARNING 2023-08-05 21:45:21,356 basehttp "GET /activate/Mjg/bsh1oq-cab95abc059e7eaf9e6f9b6d41baec51/ HTTP/1.1" 400 67
WARNING 2023-08-05 21:56:55,737 log Bad Request: /activate/Mjg/bsh1oq-cab95abc059e7eaf9e6f9b6d41baec51/
WARNING 2023-08-05 21:56:55,739 basehttp "GET /activate/Mjg/bsh1oq-cab95abc059e7eaf9e6f9b6d41baec51/ HTTP/1.1" 400 67
WARNING 2023-08-05 21:56:55,783 log Bad Request: /activate/Mjg/bsh1oq-cab95abc059e7eaf9e6f9b6d41baec51/
WARNING 2023-08-05 21:56:55,784 basehttp "GET /activate/Mjg/bsh1oq-cab95abc059e7eaf9e6f9b6d41baec51/ HTTP/1.1" 400 67
WARNING 2023-08-05 21:58:39,013 log Bad Request: /activate/Mjg/bsh1oq-cab95abc059e7eaf9e6f9b6d41baec51/
WARNING 2023-08-05 21:58:39,014 basehttp "GET /activate/Mjg/bsh1oq-cab95abc059e7eaf9e6f9b6d41baec51/ HTTP/1.1" 400 67
WARNING 2023-08-05 21:58:39,059 log Bad Request: /activate/Mjg/bsh1oq-cab95abc059e7eaf9e6f9b6d41baec51/
WARNING 2023-08-05 21:58:39,060 basehttp "GET /activate/Mjg/bsh1oq-cab95abc059e7eaf9e6f9b6d41baec51/ HTTP/1.1" 400 67
WARNING 2023-08-05 22:19:15,037 log Bad Request: /activate/Mjk/bshcj9-6b24584879eb48eeb8972c5bcf85db43/
WARNING 2023-08-05 22:19:15,038 basehttp "GET /activate/Mjk/bshcj9-6b24584879eb48eeb8972c5bcf85db43/ HTTP/1.1" 400 53
WARNING 2023-08-05 22:19:15,047 log Bad Request: /activate/Mjk/bshcj9-6b24584879eb48eeb8972c5bcf85db43/
WARNING 2023-08-05 22:19:15,048 basehttp "GET /activate/Mjk/bshcj9-6b24584879eb48eeb8972c5bcf85db43/ HTTP/1.1" 400 53
WARNING 2023-08-05 22:43:17,634 log Bad Request: /accounts/register/
WARNING 2023-08-05 22:43:17,635 basehttp "POST /accounts/register/ HTTP/1.1" 400 107
WARNING 2023-08-05 22:56:31,924 log Bad Request: /accounts/register/
WARNING 2023-08-05 22:56:31,925 basehttp "POST /accounts/register/ HTTP/1.1" 400 107
WARNING 2023-08-05 22:58:02,543 log Bad Request: /accounts/register/
WARNING 2023-08-05 22:58:02,543 basehttp "POST /accounts/register/ HTTP/1.1" 400 107
WARNING 2023-08-05 23:00:31,247 log Bad Request: /accounts/register/
WARNING 2023-08-05 23:00:31,248 basehttp "POST /accounts/register/ HTTP/1.1" 400 107
WARNING 2023-08-05 23:05:07,193 log Bad Request: /accounts/register/
WARNING 2023-08-05 23:05:07,194 basehttp "POST /accounts/register/ HTTP/1.1" 400 107
WARNING 2023-08-05 23:05:27,797 log Bad Request: /accounts/register/
WARNING 2023-08-05 23:05:27,798 basehttp "POST /accounts/register/ HTTP/1.1" 400 107
WARNING 2023-08-05 23:06:43,615 log Bad Request: /accounts/register/
WARNING 2023-08-05 23:06:43,616 basehttp "POST /accounts/register/ HTTP/1.1" 400 107
WARNING 2023-08-05 23:09:07,349 log Bad Request: /accounts/register/
WARNING 2023-08-05 23:09:07,349 basehttp "POST /accounts/register/ HTTP/1.1" 400 107
WARNING 2023-08-05 23:13:36,018 log Bad Request: /accounts/register/
WARNING 2023-08-05 23:13:36,019 basehttp "POST /accounts/register/ HTTP/1.1" 400 107
WARNING 2023-08-05 23:18:59,757 log Bad Request: /accounts/register/
WARNING 2023-08-05 23:18:59,758 basehttp "POST /accounts/register/ HTTP/1.1" 400 107
WARNING 2023-08-05 23:21:08,206 log Bad Request: /accounts/register/
WARNING 2023-08-05 23:21:08,207 basehttp "POST /accounts/register/ HTTP/1.1" 400 107
WARNING 2023-08-05 23:34:32,077 log Bad Request: /activate/MzM/bshg0k-27dde1118cc4f566bda67ec681f213f3/
WARNING 2023-08-05 23:34:32,078 basehttp "GET /activate/MzM/bshg0k-27dde1118cc4f566bda67ec681f213f3/ HTTP/1.1" 400 53
WARNING 2023-08-05 23:34:32,086 log Bad Request: /activate/MzM/bshg0k-27dde1118cc4f566bda67ec681f213f3/
WARNING 2023-08-05 23:34:32,087 basehttp "GET /activate/MzM/bshg0k-27dde1118cc4f566bda67ec681f213f3/ HTTP/1.1" 400 53
WARNING 2023-08-05 23:34:54,588 log Unauthorized: /access/
WARNING 2023-08-05 23:34:54,589 basehttp "POST /access/ HTTP/1.1" 401 63
WARNING 2023-08-05 23:36:47,700 log Unauthorized: /access/
WARNING 2023-08-05 23:36:47,701 basehttp "POST /access/ HTTP/1.1" 401 63
WARNING 2023-08-05 23:38:14,178 log Bad Request: /accounts/register/
WARNING 2023-08-05 23:38:14,179 basehttp "POST /accounts/register/ HTTP/1.1" 400 107
WARNING 2023-08-05 23:38:57,335 log Bad Request: /accounts/register/
WARNING 2023-08-05 23:38:57,336 basehttp "POST /accounts/register/ HTTP/1.1" 400 107
WARNING 2023-08-05 23:52:06,741 log Unauthorized: /access/
WARNING 2023-08-05 23:52:06,742 basehttp "POST /access/ HTTP/1.1" 401 63
WARNING 2023-08-07 10:08:29,200 log Unauthorized: /department/projectdetails/
WARNING 2023-08-07 10:08:29,215 basehttp "POST /department/projectdetails/ HTTP/1.1" 401 176
WARNING 2023-08-07 10:11:52,042 log Unauthorized: /department/projectdetails/
WARNING 2023-08-07 10:11:52,043 basehttp "POST /department/projectdetails/ HTTP/1.1" 401 176
WARNING 2023-08-07 10:18:16,949 log Unauthorized: /department/projectdetails/
WARNING 2023-08-07 10:18:16,950 basehttp "POST /department/projectdetails/ HTTP/1.1" 401 176
WARNING 2023-08-07 10:39:05,666 log Unauthorized: /department/projectdetails/
WARNING 2023-08-07 10:39:05,667 basehttp "POST /department/projectdetails/ HTTP/1.1" 401 176
